Workbook

Sheet Infos Mensuelles
A1: Salary Slip January 2026 | E1: 46053
A3: Administration
A4: Informations Employee | H4: Earnings | AW4: Deductions | AX4: Total Earning | AY4: WPS Law | BB4: Comments
A5: N° | B5: Last Name | C5: First Name | D5: Date of arrival | E5: Release date | F5: Employee ID | G5: Job name | H5: Basic salary | I5: Housing Allowances | J5: Transportation Allowance | K5: School Allowances | L5: Monthly bonus | M5: Total on Contract | N5: Working days | T5: Absence Days Unpaid | AC5: TOTAL of Days during the month | AD5: Paid | AG5: OT Hours | AN5: OT Days | AQ5: Other Allowance | AR5: Adjustment for previous month | AS5: Air plane Ticket | AT5: Total Earning | AU5: GPSSA (Pension) | AV5: Adjustement for Previous month | AW5: Advance payment/ Deduction Advance | AX5: Total Salary | AY5: Need to be send by the law for WPS | AZ5: Missing on salary | BA5: Adjustment to send
N6: No. working days | O6: Off days | P6: Public Holydays | Q6: No. leave days PAID | R6: Sick Leave PAID | S6: Total Working days payable | T6: No. leave days UNPAID | U6: Emergancy Leave UNPAID | V6: Sick leave UNPAID | W6: Absent days (not allowed) | X6: UNPAID Leave Amount | Y6: Emergancy Leave Amount | Z6: Sick leave UNPAID | AA6: Absent days (not allowed) | AB6: Total Working days unpayable | AD6: Leave PAID Amount | AE6: Sick Leave Amount | AF6: Salary | AG6: Hours | AH6: Amount Normal OT | AI6: Total | AJ6: Public Holydays | AK6: Amont Public Holydays | AL6: Total | AM6: Total | AN6: Days | AO6: Amount | AP6: Total
A7: S001 | B7: EUZET | C7: Laurent | D7: 44573 | F7: 50209057840806 | G7: General Manager | H7: 31500 | I7: 14000 | J7: 2000 | K7: 4000 | L7: 4350 | M7: =SUM(H7:L7) -> 55850 | N7: 21 | O7: 9 | P7: 1 | Q7: 0 | R7: 0 | S7: =N7+O7+P7+Q7+R7 -> 31 | T7: 0 | U7: 0 | V7: 0 | W7: 0 | X7: =M7/31*T7 -> 0 | Y7: =M7/31*U7 -> 0 | Z7: =M7/31*V7 -> 0 | AA7: =M7/31*W7 -> 0 | AB7: =T7+U7+V7+W7 -> 0 | AC7: =S7+AB7 -> 31 | AD7: =M7/31*Q7 -> 0 | AE7: =M7/31*R7 -> 0 | AF7: =M7/31*S7 -> 55850 | AG7: 0 | AH7: 173 | AI7: =AG7*AH7 -> 0 | AJ7: 0 | AK7: 173 | AL7: =AJ7*AK7 -> 0 | AM7: =AL7+AI7 -> 0 | AN7: 0 | AO7: 1693 | AP7: =AN7*AO7 -> 0 | AQ7: 0 | AR7: 0 | AS7: 0 | AT7: =SUM(AF7+AM7+AP7+AQ7+AR7+AS7) -> 55850 | AU7: 0 | AV7: 0 | AW7: 0 | AX7: =AT7-AU7-AV7-AW7 -> 55850 | AY7: =SUM(M7*80%) -> 44680 | AZ7: =AX7-AY7 -> 11170 | BA7: 0
A8: S002 | B8: ELKASIER | C8: Mohamed | D8: 45182 | F8: _00102049605328 | G8: Public relations Officer "Corporate Service Manager" | H8: 8800 | I8: 3600 | J8: 3600 | K8: 0 | L8: 0 | M8: =SUM(H8:L8) -> 16000 | N8: 20 | O8: 7 | P8: 0 | Q8: 4 | R8: 0 | S8: =N8+O8+P8+Q8+R8 -> 31 | T8: 0 | U8: 0 | V8: 0 | W8: 0 | X8: =M8/31*T8 -> 0 | Y8: =M8/31*U8 -> 0 | Z8: =M8/31*V8 -> 0 | AA8: =M8/31*W8 -> 0 | AB8: =T8+U8+V8+W8 -> 0 | AC8: =S8+AB8 -> 31 | AD8: =M8/31*Q8 -> 2064.5161 | AE8: =M8/31*R8 -> 0 | AF8: =M8/31*S8 -> 16000 | AG8: 0 | AH8: 40 | AI8: =AG8*AH8 -> 0 | AJ8: 0 | AK8: 48 | AL8: =AJ8*AK8 -> 0 | AM8: =AL8+AI8 -> 0 | AN8: 0 | AO8: 526 | AP8: =AN8*AO8 -> 0 | AQ8: 0 | AR8: 0 | AS8: 0 | AT8: =SUM(AF8+AM8+AP8+AQ8+AR8+AS8) -> 16000 | AU8: 0 | AV8: 0 | AW8: 0 | AX8: =AT8-AU8-AV8-AW8 -> 16000 | AY8: =SUM(M8*80%) -> 12800 | AZ8: =AX8-AY8 -> 3200 | BA8: 0
A9: S003 | B9: LAIJO FRANCIS | C9: Fancy | D9: 44942 | F9: 10013018976198 | G9: Accountant | H9: =M9*60% -> 3600 | I9: =M9*20% -> 1200 | J9: =M9*20% -> 1200 | K9: 0 | L9: 0 | M9: 6000 | N9: 7 | O9: 3 | P9: 1 | Q9: 20 | R9: 0 | S9: =N9+O9+P9+Q9+R9 -> 31 | T9: 0 | U9: 0 | V9: 0 | W9: 0 | X9: =M9/31*T9 -> 0 | Y9: =M9/31*U9 -> 0 | Z9: =M9/31*V9 -> 0 | AA9: =M9/31*W9 -> 0 | AB9: =T9+U9+V9+W9 -> 0 | AC9: =S9+AB9 -> 31 | AD9: =M9/31*Q9 -> 3870.9677 | AE9: =M9/31*R9 -> 0 | AF9: =M9/31*S9 -> 6000 | AG9: 0 | AH9: 16 | AI9: =AG9*AH9 -> 0 | AJ9: 0 | AK9: 20 | AL9: =AJ9*AK9 -> 0 | AM9: =AL9+AI9 -> 0 | AN9: 0 | AO9: 197 | AP9: =AN9*AO9 -> 0 | AQ9: 0 | AR9: 0 | AS9: 0 | AT9: =SUM(AF9+AM9+AP9+AQ9+AR9+AS9) -> 6000 | AU9: 0 | AV9: 0 | AW9: 0 | AX9: =AT9-AU9-AV9-AW9 -> 6000 | AY9: =SUM(M9*80%) -> 4800 | AZ9: =AX9-AY9 -> 1200 | BA9: 0
A10: S004 | B10: VATTAMKANDATHIL JOSEPH AUGUSTIN | C10: Binumon | D10: 41768 | F10: 10020057573094 | G10: Operation Manager | H10: =M10*60% -> 5100 | I10: =M10*20% -> 1700 | J10: =M10*20% -> 1700 | K10: 0 | L10: 0 | M10: 8500 | N10: 25 | O10: 5 | P10: 1 | Q10: 0 | R10: 0 | S10: =N10+O10+P10+Q10+R10 -> 31 | T10: 0 | U10: 0 | V10: 0 | W10: 0 | X10: =M10/31*T10 -> 0 | Y10: =M10/31*U10 -> 0 | Z10: =M10/31*V10 -> 0 | AA10: =M10/31*W10 -> 0 | AB10: =T10+U10+V10+W10 -> 0 | AC10: =S10+AB10 -> 31 | AD10: =M10/31*Q10 -> 0 | AE10: =M10/31*R10 -> 0 | AF10: =M10/31*S10 -> 8500 | AG10: 0 | AH10: 23 | AI10: =AG10*AH10 -> 0 | AJ10: 0 | AK10: 28 | AL10: =AJ10*AK10 -> 0 | AM10: =AL10+AI10 -> 0 | AN10: 1 | AO10: 279 | AP10: =AN10*AO10 -> 279 | AQ10: 0 | AR10: 0 | AS10: 0 | AT10: =SUM(AF10+AM10+AP10+AQ10+AR10+AS10) -> 8779 | AU10: 0 | AV10: 0 | AW10: 0 | AX10: =AT10-AU10-AV10-AW10 -> 8779 | AY10: =SUM(M10*80%) -> 6800 | AZ10: =AX10-AY10 -> 1979 | BA10: 0
A11: S005 | B11: SASIDHARAN PUTHENAYATHIL RAGHAVAN | C11: Anoop | D11: 43002 | F11: 10012127956935 | G11: Archiev clerk | H11: =M11*60% -> 3900 | I11: =M11*20% -> 1300 | J11: =M11*20% -> 1300 | K11: 0 | L11: 0 | M11: 6500 | N11: 26 | O11: 4 | P11: 1 | Q11: 0 | R11: 0 | S11: =N11+O11+P11+Q11+R11 -> 31 | T11: 0 | U11: 0 | V11: 0 | W11: 0 | X11: =M11/31*T11 -> 0 | Y11: =M11/31*U11 -> 0 | Z11: =M11/31*V11 -> 0 | AA11: =M11/31*W11 -> 0 | AB11: =T11+U11+V11+W11 -> 0 | AC11: =S11+AB11 -> 31 | AD11: =M11/31*Q11 -> 0 | AE11: =M11/31*R11 -> 0 | AF11: =M11/31*S11 -> 6500 | AG11: 0 | AH11: 18 | AI11: =AG11*AH11 -> 0 | AJ11: 0 | AK11: 21 | AL11: =AJ11*AK11 -> 0 | AM11: =AL11+AI11 -> 0 | AN11: 1 | AO11: 214 | AP11: =AN11*AO11 -> 214 | AQ11: 0 | AR11: 0 | AS11: 0 | AT11: =SUM(AF11+AM11+AP11+AQ11+AR11+AS11) -> 6714 | AU11: 0 | AV11: 0 | AW11: 0 | AX11: =AT11-AU11-AV11-AW11 -> 6714 | AY11: =SUM(M11*80%) -> 5200 | AZ11: =AX11-AY11 -> 1514 | BA11: 0
A12: S006 | B12: SHAREEQ MOHAMMED YUSUF ISMAIL | C12: Azeem | D12: 44243 | F12: 10027039033676 | G12: Filing clerk | H12: =M12*60% -> 3600 | I12: =M12*20% -> 1200 | J12: =M12*20% -> 1200 | K12: 0 | L12: 0 | M12: 6000 | N12: 25 | O12: 5 | P12: 1 | Q12: 0 | R12: 0 | S12: =N12+O12+P12+Q12+R12 -> 31 | T12: 0 | U12: 0 | V12: 0 | W12: 0 | X12: =M12/31*T12 -> 0 | Y12: =M12/31*U12 -> 0 | Z12: =M12/31*V12 -> 0 | AA12: =M12/31*W12 -> 0 | AB12: =T12+U12+V12+W12 -> 0 | AC12: =S12+AB12 -> 31 | AD12: =M12/31*Q12 -> 0 | AE12: =M12/31*R12 -> 0 | AF12: =M12/31*S12 -> 6000 | AG12: 8 | AH12: 16 | AI12: =AG12*AH12 -> 128 | AJ12: 0 | AK12: 20 | AL12: =AJ12*AK12 -> 0 | AM12: =AL12+AI12 -> 128 | AN12: 1 | AO12: 197 | AP12: =AN12*AO12 -> 197 | AQ12: 0 | AR12: 0 | AS12: 0 | AT12: =SUM(AF12+AM12+AP12+AQ12+AR12+AS12) -> 6325 | AU12: 0 | AV12: 0 | AW12: 0 | AX12: =AT12-AU12-AV12-AW12 -> 6325 | AY12: =SUM(M12*80%) -> 4800 | AZ12: =AX12-AY12 -> 1525 | BA12: 0
A13: S007 | B13: MOHAMED KASSIM | C13: Maideen | D13: 45231 | F13: 10025128665320 | G13: Messenger | H13: 3000 | I13: 1000 | J13: 1000 | K13: 0 | L13: 0 | M13: 5250 | N13: 24 | O13: 5 | P13: 0 | Q13: 2 | R13: 0 | S13: =N13+O13+P13+Q13+R13 -> 31 | T13: 0 | U13: 0 | V13: 0 | W13: 0 | X13: =M13/31*T13 -> 0 | Y13: =M13/31*U13 -> 0 | Z13: =M13/31*V13 -> 0 | AA13: =M13/31*W13 -> 0 | AB13: =T13+U13+V13+W13 -> 0 | AC13: =S13+AB13 -> 31 | AD13: =M13/31*Q13 -> 338.70968 | AE13: =M13/31*R13 -> 0 | AF13: =M13/31*S13 -> 5250 | AG13: 0 | AH13: 14 | AI13: =AG13*AH13 -> 0 | AJ13: 0 | AK13: 17 | AL13: =AJ13*AK13 -> 0 | AM13: =AL13+AI13 -> 0 | AN13: 0 | AO13: 173 | AP13: =AN13*AO13 -> 0 | AQ13: 0 | AR13: 0 | AS13: 0 | AT13: =SUM(AF13+AM13+AP13+AQ13+AR13+AS13) -> 5250 | AU13: 0 | AV13: 0 | AW13: 1925.7 | AX13: =AT13-AU13-AV13-AW13 -> 3324.3 | AY13: =SUM(M13*80%) -> 4200 | AZ13: =AX13-AY13 -> -875.7 | BA13: 0
A14: S008 | B14: SIVARAMAN GOPINATH | C14: Prince | D14: 44606 | F14: 10021048238840 | G14: Archiev clerk | H14: =M14*60% -> 3600 | I14: =M14*20% -> 1200 | J14: =M14*20% -> 1200 | K14: 0 | L14: 0 | M14: 6000 | N14: 26 | O14: 4 | P14: 1 | Q14: 0 | R14: 0 | S14: =N14+O14+P14+Q14+R14 -> 31 | T14: 0 | U14: 0 | V14: 0 | W14: 0 | X14: =M14/31*T14 -> 0 | Y14: =M14/31*U14 -> 0 | Z14: =M14/31*V14 -> 0 | AA14: =M14/31*W14 -> 0 | AB14: =T14+U14+V14+W14 -> 0 | AC14: =S14+AB14 -> 31 | AD14: =M14/31*Q14 -> 0 | AE14: =M14/31*R14 -> 0 | AF14: =M14/31*S14 -> 6000 | AG14: 0 | AH14: 16 | AI14: =AG14*AH14 -> 0 | AJ14: 0 | AK14: 20 | AL14: =AJ14*AK14 -> 0 | AM14: =AL14+AI14 -> 0 | AN14: 1 | AO14: 197 | AP14: =AN14*AO14 -> 197 | AQ14: 0 | AR14: 0 | AS14: 0 | AT14: =SUM(AF14+AM14+AP14+AQ14+AR14+AS14) -> 6197 | AU14: 0 | AV14: 0 | AW14: 0 | AX14: =AT14-AU14-AV14-AW14 -> 6197 | AY14: =SUM(M14*80%) -> 4800 | AZ14: =AX14-AY14 -> 1397 | BA14: 0
A15: S009 | B15: RAHMAN PATTUVAM | C15: Sajub | D15: 45260 | F15: 10030039360020 | G15: Messenger | H15: 3300 | I15: 1100 | J15: 1100 | K15: 0 | L15: 0 | M15: 5500 | N15: 26 | O15: 4 | P15: 1 | Q15: 0 | R15: 0 | S15: =N15+O15+P15+Q15+R15 -> 31 | T15: 0 | U15: 0 | V15: 0 | W15: 0 | X15: =M15/31*T15 -> 0 | Y15: =M15/31*U15 -> 0 | Z15: =M15/31*V15 -> 0 | AA15: =M15/31*W15 -> 0 | AB15: =T15+U15+V15+W15 -> 0 | AC15: =S15+AB15 -> 31 | AD15: =M15/31*Q15 -> 0 | AE15: =M15/31*R15 -> 0 | AF15: =M15/31*S15 -> 5500 | AG15: 25 | AH15: 15 | AI15: =AG15*AH15 -> 375 | AJ15: 0 | AK15: 18 | AL15: =AJ15*AK15 -> 0 | AM15: =AL15+AI15 -> 375 | AN15: 1 | AO15: 181 | AP15: =AN15*AO15 -> 181 | AQ15: 0 | AR15: 0 | AS15: 0 | AT15: =SUM(AF15+AM15+AP15+AQ15+AR15+AS15) -> 6056 | AU15: 0 | AV15: 0 | AW15: 0 | AX15: =AT15-AU15-AV15-AW15 -> 6056 | AY15: =SUM(M15*80%) -> 4400 | AZ15: =AX15-AY15 -> 1656 | BA15: 0
A16: S010 | B16: VAYAMBATHODY KUNHIMOIDU | C16: Shanavas | D16: 41912 | F16: 10025047761962 | G16: Follow up clerk | H16: =M16*60% -> 5100 | I16: =M16*20% -> 1700 | J16: =M16*20% -> 1700 | K16: 0 | L16: 0 | M16: 8500 | N16: 21 | O16: 4 | P16: 1 | Q16: 5 | R16: 0 | S16: =N16+O16+P16+Q16+R16 -> 31 | T16: 0 | U16: 0 | V16: 0 | W16: 0 | X16: =M16/31*T16 -> 0 | Y16: =M16/31*U16 -> 0 | Z16: =M16/31*V16 -> 0 | AA16: =M16/31*W16 -> 0 | AB16: =T16+U16+V16+W16 -> 0 | AC16: =S16+AB16 -> 31 | AD16: =M16/31*Q16 -> 1370.9677 | AE16: =M16/31*R16 -> 0 | AF16: =M16/31*S16 -> 8500 | AG16: 0 | AH16: 23 | AI16: =AG16*AH16 -> 0 | AJ16: 0 | AK16: 28 | AL16: =AJ16*AK16 -> 0 | AM16: =AL16+AI16 -> 0 | AN16: 1 | AO16: 279 | AP16: =AN16*AO16 -> 279 | AQ16: 0 | AR16: 0 | AS16: 0 | AT16: =SUM(AF16+AM16+AP16+AQ16+AR16+AS16) -> 8779 | AU16: 0 | AV16: 0 | AW16: 0 | AX16: =AT16-AU16-AV16-AW16 -> 8779 | AY16: =SUM(M16*80%) -> 6800 | AZ16: =AX16-AY16 -> 1979 | BA16: 0
A17: S020 | B17: NIEVA | C17: Raiza | D17: 45985 | F17: 30404129679881 | G17: Back office officer | H17: =M17*60/100 -> 2400 | I17: =M17*20/100 -> 800 | J17: =M17*20/100 -> 800 | K17: 0 | L17: 0 | M17: 4000 | N17: 26 | O17: 4 | P17: 1 | Q17: 0 | R17: 0 | S17: =N17+O17+P17+Q17+R17 -> 31 | T17: 0 | U17: 0 | V17: 0 | W17: 0 | X17: =M17/31*T17 -> 0 | Y17: =M17/31*U17 -> 0 | Z17: =M17/31*V17 -> 0 | AA17: =M17/31*W17 -> 0 | AB17: =T17+U17+V17+W17 -> 0 | AC17: =S17+AB17 -> 31 | AD17: =M17/31*Q17 -> 0 | AE17: =M17/31*R17 -> 0 | AF17: =M17/31*S17 -> 4000 | AG17: 0 | AH17: 11 | AI17: =AG17*AH17 -> 0 | AJ17: 0 | AK17: 13 | AL17: =AJ17*AK17 -> 0 | AM17: =AL17+AI17 -> 0 | AN17: 0 | AO17: 132 | AP17: =AN17*AO17 -> 0 | AQ17: 0 | AS17: 0 | AT17: =SUM(AF17+AM17+AP17+AQ17+AR17+AS17) -> 4000 | AU17: 0 | AV17: 0 | AW17: 0 | AX17: =AT17-AU17-AV17-AW17 -> 4000 | AY17: =SUM(M17*80%) -> 3200 | AZ17: =AX17-AY17 -> 800 | BA17: 0
A18: S021 | B18: THAZHUTHARINTAVIDA | C18: Loshin | D18: 46012 | F18: 10005068743230 | H18: 3000 | I18: 1000 | J18: 1000 | K18: 0 | L18: 0 | M18: 5000 | N18: 26 | O18: 4 | P18: 1 | Q18: 0 | R18: 0 | S18: =N18+O18+P18+Q18+R18 -> 31 | T18: 0 | U18: 0 | V18: 0 | W18: 0 | X18: =M18/31*T18 -> 0 | Y18: =M18/31*U18 -> 0 | Z18: =M18/31*V18 -> 0 | AA18: =M18/31*W18 -> 0 | AB18: =T18+U18+V18+W18 -> 0 | AC18: =S18+AB18 -> 31 | AD18: =M18/31*Q18 -> 0 | AE18: =M18/31*R18 -> 0 | AF18: =M18/31*S18 -> 5000 | AG18: 26 | AH18: 14 | AI18: =AG18*AH18 -> 364 | AJ18: 0 | AK18: 16 | AL18: =AJ18*AK18 -> 0 | AM18: =AL18+AI18 -> 364 | AN18: 1 | AO18: 164 | AP18: =AN18*AO18 -> 164 | AQ18: 0 | AR18: 0 | AS18: 0 | AT18: =SUM(AF18+AM18+AP18+AQ18+AR18+AS18) -> 5528 | AU18: 0 | AV18: 0 | AW18: 0 | AX18: =AT18-AU18-AV18-AW18 -> 5528 | AY18: =SUM(M18*80%) -> 4000 | AZ18: =AX18-AY18 -> 1528 | BA18: 0
A19: S012 | B19: PADAMANATHAN | C19: Ramu | D19: 44095 | F19: 10022016768789 | G19: Cleaner | H19: =M19*60% -> 2160 | I19: =M19*20% -> 720 | J19: =M19*20% -> 720 | K19: 0 | L19: 0 | M19: 3600 | N19: 25 | O19: 5 | P19: 1 | Q19: 0 | R19: 0 | S19: =N19+O19+P19+Q19+R19 -> 31 | T19: 0 | U19: 0 | V19: 0 | W19: 0 | X19: =M19/31*T19 -> 0 | Y19: =M19/31*U19 -> 0 | Z19: =M19/31*V19 -> 0 | AA19: =M19/31*W19 -> 0 | AB19: =T19+U19+V19+W19 -> 0 | AC19: =S19+AB19 -> 31 | AD19: =M19/31*Q19 -> 0 | AE19: =M19/31*R19 -> 0 | AF19: =M19/31*S19 -> 3600 | AG19: 0 | AH19: 10 | AI19: =AG19*AH19 -> 0 | AJ19: 0 | AK19: 12 | AL19: =AJ19*AK19 -> 0 | AM19: =AL19+AI19 -> 0 | AN19: 1 | AO19: 115 | AP19: =AN19*AO19 -> 115 | AQ19: 0 | AR19: 0 | AS19: 0 | AT19: =SUM(AF19+AM19+AP19+AQ19+AR19+AS19) -> 3715 | AU19: 0 | AV19: 0 | AW19: 0 | AX19: =AT19-AU19-AV19-AW19 -> 3715 | AY19: =SUM(M19*80%) -> 2880 | AZ19: =AX19-AY19 -> 835 | BA19: 0
A20: S018 | B20: YAKKOOB | C20: Rather | D20: 45955 | F20: 10007018981824 | G20: Cleaner | H20: =M20*60% -> 1800 | I20: =M20*20% -> 600 | J20: =M20*20% -> 600 | K20: 0 | L20: 0 | M20: 3000 | N20: 25 | O20: 5 | P20: 1 | Q20: 0 | R20: 0 | S20: =N20+O20+P20+Q20+R20 -> 31 | T20: 0 | U20: 0 | V20: 0 | W20: 0 | X20: =M20/31*T20 -> 0 | Y20: =M20/31*U20 -> 0 | Z20: =M20/31*V20 -> 0 | AA20: =M20/31*W20 -> 0 | AB20: =T20+U20+V20+W20 -> 0 | AC20: =S20+AB20 -> 31 | AD20: =M20/31*Q20 -> 0 | AE20: =M20/31*R20 -> 0 | AF20: =M20/31*S20 -> 3000 | AG20: 0 | AH20: 8 | AI20: =AG20*AH20 -> 0 | AJ20: 0 | AK20: 10 | AL20: =AJ20*AK20 -> 0 | AM20: =AL20+AI20 -> 0 | AN20: 1 | AO20: 99 | AP20: =AN20*AO20 -> 99 | AQ20: 0 | AR20: 0 | AS20: 0 | AT20: =SUM(AF20+AM20+AP20+AQ20+AR20+AS20) -> 3099 | AU20: 0 | AV20: 0 | AW20: 0 | AX20: =AT20-AU20-AV20-AW20 -> 3099 | AY20: =SUM(M20*80%) -> 2400 | AZ20: =AX20-AY20 -> 699 | BA20: 0
A21: S016 | B21: ALZAABI | C21: Mariam | D21: 45600 | F21: _02120129566913 | G21: Operations Coordinator (Remote) | H21: 3000 | I21: 1000 | J21: 1000 | K21: 0 | L21: 0 | M21: 5000 | N21: 21 | O21: 9 | P21: 1 | Q21: 0 | R21: 0 | S21: =N21+O21+P21+Q21+R21 -> 31 | T21: 0 | U21: 0 | V21: 0 | W21: 0 | X21: =M21/31*T21 -> 0 | Y21: =M21/31*U21 -> 0 | Z21: =M21/31*V21 -> 0 | AA21: =M21/31*W21 -> 0 | AB21: =T21+U21+V21+W21 -> 0 | AC21: =S21+AB21 -> 31 | AD21: =M21/31*Q21 -> 0 | AE21: =M21/31*R21 -> 0 | AF21: =M21/31*S21 -> 5000 | AG21: 0 | AH21: 0 | AI21: =AG21*AH21 -> 0 | AJ21: 0 | AK21: 0 | AL21: =AJ21*AK21 -> 0 | AM21: =AL21+AI21 -> 0 | AN21: 0 | AO21: 0 | AP21: =AN21*AO21 -> 0 | AQ21: 0 | AR21: 0 | AS21: 0 | AT21: =SUM(AF21+AM21+AP21+AQ21+AR21+AS21) -> 5000 | AU21: 550 | AV21: 0 | AW21: 0 | AX21: =AT21-AU21-AV21-AW21 -> 4450 | AY21: =SUM(M21*80%) -> 4000 | AZ21: =AX21-AY21 -> 450 | BA21: 0 | BB21: Employee contribution (11%)
A22: S017 | B22: ALZAABI | C22: Fetoun | D22: 45600 | F22: _02124060158242 | G22: Inside Sales Assistant (Remote) | H22: 3000 | I22: 1000 | J22: 1000 | K22: 0 | L22: 0 | M22: 5000 | N22: 21 | O22: 9 | P22: 1 | Q22: 0 | R22: 0 | S22: =N22+O22+P22+Q22+R22 -> 31 | T22: 0 | U22: 0 | V22: 0 | W22: 0 | X22: =M22/31*T22 -> 0 | Y22: =M22/31*U22 -> 0 | Z22: =M22/31*V22 -> 0 | AA22: =M22/31*W22 -> 0 | AB22: =T22+U22+V22+W22 -> 0 | AC22: =S22+AB22 -> 31 | AD22: =M22/31*Q22 -> 0 | AE22: =M22/31*R22 -> 0 | AF22: =M22/31*S22 -> 5000 | AG22: 0 | AH22: 0 | AI22: =AG22*AH22 -> 0 | AJ22: 0 | AK22: 0 | AL22: =AJ22*AK22 -> 0 | AM22: =AL22+AI22 -> 0 | AN22: 0 | AO22: 0 | AP22: =AN22*AO22 -> 0 | AQ22: 0 | AR22: 0 | AS22: 0 | AT22: =SUM(AF22+AM22+AP22+AQ22+AR22+AS22) -> 5000 | AU22: 550 | AV22: 0 | AW22: 0 | AX22: =AT22-AU22-AV22-AW22 -> 4450 | AY22: =SUM(M22*80%) -> 4000 | AZ22: =AX22-AY22 -> 450 | BA22: 0 | BB22: Employee contribution (11%)
A23: S019 | B23: ALSHAMSI | C23: Shaikha | D23: 45985 | F23: _02129100723577 | G23: Office Clerk (Remote) | H23: 3000 | I23: 1000 | J23: 1000 | K23: 0 | L23: 0 | M23: 5000 | N23: 21 | O23: 9 | P23: 1 | Q23: 0 | R23: 0 | S23: =N23+O23+P23+Q23+R23 -> 31 | T23: 0 | U23: 0 | V23: 0 | W23: 0 | X23: =M23/31*T23 -> 0 | Y23: =M23/31*U23 -> 0 | Z23: =M23/31*V23 -> 0 | AA23: =M23/31*W23 -> 0 | AB23: =T23+U23+V23+W23 -> 0 | AC23: =S23+AB23 -> 31 | AD23: =M23/31*Q23 -> 0 | AE23: =M23/31*R23 -> 0 | AF23: =M23/31*S23 -> 5000 | AG23: 0 | AH23: 0 | AI23: =AG23*AH23 -> 0 | AJ23: 0 | AK23: 0 | AL23: =AJ23*AK23 -> 0 | AM23: =AL23+AI23 -> 0 | AN23: 0 | AO23: 0 | AP23: =AN23*AO23 -> 0 | AQ23: 0 | AR23: 0 | AS23: 0 | AT23: =SUM(AF23+AM23+AP23+AQ23+AR23+AS23) -> 5000 | AU23: 550 | AV23: 0 | AW23: 0 | AX23: =AT23-AU23-AV23-AW23 -> 4450 | AY23: =SUM(M23*80%) -> 4000 | AZ23: =AX23-AY23 -> 450 | BA23: 0 | BB23: Employee contribution (11%)
C24: Taqi | H24: =M24*0.6 -> 24000 | I24: =M24*0.2 -> 8000 | J24: =M24*0.2 -> 8000 | M24: 40000 | AQ24: =SUM(AQ7:AQ23) -> 0 | AR24: =SUM(AR7:AR23) -> 0 | AS24: =SUM(AS7:AS23) -> 0 | AT24: =SUM(AT7+AT8+AT9+AT10+AT11+AT12+AT13+AT14+AT15+AT16+AT17+AT18+AT19+AT20+AT21+AT22+AT23) -> 157292 | AU24: =SUM(AU7:AU23) -> 1650 | AV24: =SUM(AV7:AV23) -> 0 | AW24: =SUM(AW7:AW23) -> 1925.7 | AX24: =SUM(AX7:AX23) -> 153716.3
C25: Guillaume
AR26: Salaries Wages | AS26: =AS28-AS27 -> 157292 | AU26: Total Advance & deductions | AW26: =AU24+AV24+AW24 -> 3575.7
AR27: Air ticket | AS27: =AS24 -> 0 | AX27: =AX24-AX7 -> 97866.3
B28: Pension to be paid GPSSA | C28: Mariam | D28: 625 | AR28: Total Payable | AS28: =AT24 -> 157292
C29: Fetoun | D29: 625
C30: Shaikha | D30: 625 | AX30: Bank transfert | AY30: =AX24 -> 153716.3
AS33: Manager allowances | AT33: =AX7 -> 55850
AS34: Staff allowance | AT34: =SUM(AT8:AT23)-AS24 -> 101442

Sheet Laurent
A1: CHABE LUXURY TRANSPORT LLC
A2: 11B Street Warehouse 3b/27
A3: AL KHABAISI
A4: Dubai, UAE
A5: ='Infos Mensuelles'!A1 -> Salary Slip January 2026
A8: Employee last name: | D8: ='Infos Mensuelles'!B7 -> EUZET | H8: Employee ID: | J8: ='Infos Mensuelles'!F7 -> 50209057840806
H9: Arrival date: | J9: ='Infos Mensuelles'!D7 -> 44573
A11: Employee first name | D11: ='Infos Mensuelles'!C7 -> Laurent | H11: Employee Position: | J11: ='Infos Mensuelles'!G7 -> General Manager
A15: Employee Attendance
A16: Working days: | D16: ='Infos Mensuelles'!N7 -> 21 | E16: OT Hours Basic | H16: ='Infos Mensuelles'!AG7 -> 0 | I16: Absence day | L16: ='Infos Mensuelles'!W7 -> 0
A17: Working Public Holidays: | D17: ='Infos Mensuelles'!P7 -> 1 | E17: OT Hours Public holidays | H17: ='Infos Mensuelles'!AJ7 -> 0 | I17: Emergency Leave Unpaid : | L17: ='Infos Mensuelles'!U7 -> 0
A18: Off days: | D18: ='Infos Mensuelles'!O7 -> 9 | E18: OT Days | H18: ='Infos Mensuelles'!AJ7 -> 0 | I18: Leaves without pay: | L18: ='Infos Mensuelles'!T7 -> 0
A19: Sick Leave | D19: ='Infos Mensuelles'!R7 -> 0 | E19: Leave Payable: | H19: ='Infos Mensuelles'!Q7 -> 0
A20: Payable days: | D20: ='Infos Mensuelles'!S7 -> 31
A23: Earnings & Deductions
A24: Salary Head | G24: Amount Earnings (AED) | J24: Amount Deductions (AED)
A26: Earnings
A27: Basic Salary | G27: ='Infos Mensuelles'!H7 -> 31500
A28: Housing Allowances | G28: ='Infos Mensuelles'!I7 -> 14000
A29: Transport Allowances | G29: ='Infos Mensuelles'!J7 -> 2000
A30: School Allowances | G30: ='Infos Mensuelles'!K7 -> 4000
A31: Monthly Bonus | G31: ='Infos Mensuelles'!L7 -> 4350
A32: OT Hours Basic | G32: ='Infos Mensuelles'!AI7 -> 0
A33: OT Hours Public holidays | G33: ='Infos Mensuelles'!AL7 -> 0
A34: OT Days | G34: ='Infos Mensuelles'!AP7 -> 0
A35: Air Plane Ticket Refundable | G35: ='Infos Mensuelles'!AS7 -> 0
A37: Deductions
A38: Pension Locals Employees (Non eligible) | J38: ='Infos Mensuelles'!AU7 -> 0
A39: Adjustment form previous month(s) | J39: ='Infos Mensuelles'!AV7 -> 0
A40: Advance salary | J40: ='Infos Mensuelles'!AW7 -> 0
A41: Absences | J41: ='Infos Mensuelles'!AA7 -> 0
A42: Unpaid leaves | J42: ='Infos Mensuelles'!X7 -> 0
A43: Emergency leave | J43: ='Infos Mensuelles'!Y7 -> 0
A44: Sick Leave Unpaid | J44: ='Infos Mensuelles'!Z7 -> 0
A46: TOTAL EARNINGS & DEDUCTIONS | G46: =SUM(G27:I34) -> 55850 | J46: =SUM(J40:L45) -> 0
A49: TOTAL AMOUNT : | G49: =G46-J46 -> 55850
A53: Payment informations:
A54: Date of payment: | D54: ='Infos Mensuelles'!E1 -> 46053
A55: Methode of payment: | D55: WPS
A56: If you need any informations please contact us at hr-dubai@chabe.com

Sheet Mohamed
A1: CHABE LUXURY TRANSPORT LLC
A2: 11B Street Warehouse 3b/27
A3: AL KHABAISI
A4: Dubai, UAE
A5: ='Infos Mensuelles'!A1 -> Salary Slip January 2026
A8: Employee last name: | D8: ='Infos Mensuelles'!B8 -> ELKASIER | H8: Employee ID: | J8: ='Infos Mensuelles'!F8 -> _00102049605328
H9: Arrival date: | J9: ='Infos Mensuelles'!D8 -> 45182
A11: Employee first name | D11: ='Infos Mensuelles'!C8 -> Mohamed | H11: Employee Position: | J11: ='Infos Mensuelles'!G8 -> Public relations Officer "Corporate Service Manager"
A15: Employee Attendance
A16: Working days: | D16: ='Infos Mensuelles'!N8 -> 20 | E16: OT Hours Basic | H16: ='Infos Mensuelles'!AG8 -> 0 | I16: Absence day | L16: ='Infos Mensuelles'!W8 -> 0
A17: Working Public Holidays: | D17: ='Infos Mensuelles'!P8 -> 0 | E17: OT Hours Public holidays | H17: ='Infos Mensuelles'!AJ8 -> 0 | I17: Emergency Leave Unpaid : | L17: ='Infos Mensuelles'!U8 -> 0
A18: Off days: | D18: ='Infos Mensuelles'!O8 -> 7 | E18: OT Days | H18: ='Infos Mensuelles'!AJ8 -> 0 | I18: Leaves without pay: | L18: ='Infos Mensuelles'!T8 -> 0
A19: Sick Leave | D19: ='Infos Mensuelles'!R8 -> 0 | E19: Leave Payable: | H19: ='Infos Mensuelles'!Q8 -> 4
A20: Payable days: | D20: ='Infos Mensuelles'!S8 -> 31
A23: Earnings & Deductions
A24: Salary Head | G24: Amount Earnings (AED) | J24: Amount Deductions (AED)
A26: Earnings
A27: Basic Salary | G27: ='Infos Mensuelles'!H8 -> 8800
A28: Housing Allowances | G28: ='Infos Mensuelles'!I8 -> 3600
A29: Transport Allowances | G29: ='Infos Mensuelles'!J8 -> 3600
A30: School Allowances | G30: ='Infos Mensuelles'!K8 -> 0
A31: Monthly Bonus | G31: ='Infos Mensuelles'!L8 -> 0
A32: OT Hours Basic | G32: ='Infos Mensuelles'!AI8 -> 0
A33: OT Hours Public holidays | G33: ='Infos Mensuelles'!AL8 -> 0
A34: OT Days | G34: ='Infos Mensuelles'!AP8 -> 0
A35: Air Plane Ticket Refundable | G35: ='Infos Mensuelles'!AS8 -> 0
A37: Deductions
A38: Pension Locals Employees (Non eligible) | J38: ='Infos Mensuelles'!AU8 -> 0
A39: Adjustment form previous month(s) | J39: ='Infos Mensuelles'!AV8 -> 0
A40: Advance salary | J40: ='Infos Mensuelles'!AW8 -> 0
A41: Absences | J41: ='Infos Mensuelles'!AA8 -> 0
A42: Unpaid leaves | J42: ='Infos Mensuelles'!X8 -> 0
A43: Emergency leave | J43: ='Infos Mensuelles'!Y8 -> 0
A44: Sick Leave Unpaid | J44: ='Infos Mensuelles'!Z8 -> 0
A46: TOTAL EARNINGS & DEDUCTIONS | G46: =SUM(G27:I34) -> 16000 | J46: =SUM(J40:L45) -> 0
A49: TOTAL AMOUNT : | G49: =G46-J46 -> 16000
A53: Payment informations:
A54: Date of payment: | D54: ='Infos Mensuelles'!E1 -> 46053
A55: Methode of payment: | D55: WPS
A56: If you need any informations please contact us at hr-dubai@chabe.com

Sheet Fancy
A1: CHABE LUXURY TRANSPORT LLC
A2: 11B Street Warehouse 3b/27
A3: AL KHABAISI
A4: Dubai, UAE
A5: ='Infos Mensuelles'!A1 -> Salary Slip January 2026
A8: Employee last name: | D8: ='Infos Mensuelles'!B9 -> LAIJO FRANCIS | H8: Employee ID: | J8: ='Infos Mensuelles'!F9 -> 10013018976198
H9: Arrival date: | J9: ='Infos Mensuelles'!D9 -> 44942
A11: Employee first name | D11: ='Infos Mensuelles'!C9 -> Fancy | H11: Employee Position: | J11: ='Infos Mensuelles'!G9 -> Accountant
A15: Employee Attendance
A16: Working days: | D16: ='Infos Mensuelles'!N9 -> 7 | E16: OT Hours Basic | H16: ='Infos Mensuelles'!AG9 -> 0 | I16: Absence day | L16: ='Infos Mensuelles'!W9 -> 0
A17: Working Public Holidays: | D17: ='Infos Mensuelles'!P9 -> 1 | E17: OT Hours Public holidays | H17: ='Infos Mensuelles'!AJ9 -> 0 | I17: Emergency Leave Unpaid : | L17: ='Infos Mensuelles'!U9 -> 0
A18: Off days: | D18: ='Infos Mensuelles'!O9 -> 3 | E18: OT Days | H18: ='Infos Mensuelles'!AJ9 -> 0 | I18: Leaves without pay: | L18: ='Infos Mensuelles'!T9 -> 0
A19: Sick Leave | D19: ='Infos Mensuelles'!R9 -> 0 | E19: Leave Payable: | H19: ='Infos Mensuelles'!Q9 -> 20
A20: Payable days: | D20: ='Infos Mensuelles'!S9 -> 31
A23: Earnings & Deductions
A24: Salary Head | G24: Amount Earnings (AED) | J24: Amount Deductions (AED)
A26: Earnings
A27: Basic Salary | G27: ='Infos Mensuelles'!H9 -> 3600
A28: Housing Allowances | G28: ='Infos Mensuelles'!I9 -> 1200
A29: Transport Allowances | G29: ='Infos Mensuelles'!J9 -> 1200
A30: School Allowances | G30: ='Infos Mensuelles'!K9 -> 0
A31: Monthly Bonus | G31: ='Infos Mensuelles'!L9 -> 0
A32: OT Hours Basic | G32: ='Infos Mensuelles'!AI9 -> 0
A33: OT Hours Public holidays | G33: ='Infos Mensuelles'!AL9 -> 0
A34: OT Days | G34: ='Infos Mensuelles'!AP9 -> 0
A35: Air Plane Ticket Refundable | G35: ='Infos Mensuelles'!AS9 -> 0
A37: Deductions
A38: Pension Locals Employees (Non eligible) | J38: ='Infos Mensuelles'!AU9 -> 0
A39: Adjustment form previous month(s) | J39: ='Infos Mensuelles'!AV9 -> 0
A40: Advance salary | J40: ='Infos Mensuelles'!AW9 -> 0
A41: Absences | J41: ='Infos Mensuelles'!AA9 -> 0
A42: Unpaid leaves | J42: ='Infos Mensuelles'!X9 -> 0
A43: Emergency leave | J43: ='Infos Mensuelles'!Y9 -> 0
A44: Sick Leave Unpaid
A46: TOTAL EARNINGS & DEDUCTIONS | G46: =SUM(G27:I35) -> 6000 | J46: =SUM(J40:L45) -> 0
A49: TOTAL AMOUNT : | G49: =G46-J46 -> 6000
A53: Payment informations:
A54: Date of payment: | D54: ='Infos Mensuelles'!E1 -> 46053
A55: Methode of payment: | D55: WPS
A56: If you need any informations please contact us at hr-dubai@chabe.com

Sheet Binu
A1: CHABE LUXURY TRANSPORT LLC
A2: 11B Street Warehouse 3b/27
A3: AL KHABAISI
A4: Dubai, UAE
A5: ='Infos Mensuelles'!A1 -> Salary Slip January 2026
A8: Employee last name: | D8: ='Infos Mensuelles'!B10 -> VATTAMKANDATHIL JOSEPH AUGUSTIN | H8: Employee ID: | J8: ='Infos Mensuelles'!F10 -> 10020057573094
H9: Arrival date: | J9: ='Infos Mensuelles'!D10 -> 41768
A11: Employee first name | D11: ='Infos Mensuelles'!C10 -> Binumon | H11: Employee Position: | J11: ='Infos Mensuelles'!G10 -> Operation Manager
A15: Employee Attendance
A16: Working days: | D16: ='Infos Mensuelles'!N10 -> 25 | E16: OT Hours Basic | H16: ='Infos Mensuelles'!AG10 -> 0 | I16: Absence day | L16: ='Infos Mensuelles'!W10 -> 0
A17: Working Public Holidays: | D17: ='Infos Mensuelles'!P10 -> 1 | E17: OT Hours Public holidays | H17: ='Infos Mensuelles'!AJ10 -> 0 | I17: Emergency Leave Unpaid : | L17: ='Infos Mensuelles'!U10 -> 0
A18: Off days: | D18: ='Infos Mensuelles'!O10 -> 5 | E18: OT Days | H18: ='Infos Mensuelles'!AJ10 -> 0 | I18: Leaves without pay: | L18: ='Infos Mensuelles'!T10 -> 0
A19: Sick Leave | D19: ='Infos Mensuelles'!R10 -> 0 | E19: Leave Payable: | H19: ='Infos Mensuelles'!Q10 -> 0
A20: Payable days: | D20: ='Infos Mensuelles'!S10 -> 31
A23: Earnings & Deductions
A24: Salary Head | G24: Amount Earnings (AED) | J24: Amount Deductions (AED)
A26: Earnings
A27: Basic Salary | G27: ='Infos Mensuelles'!H10 -> 5100
A28: Housing Allowances | G28: ='Infos Mensuelles'!I10 -> 1700
A29: Transport Allowances | G29: ='Infos Mensuelles'!J10 -> 1700
A30: School Allowances | G30: ='Infos Mensuelles'!K10 -> 0
A31: Monthly Bonus | G31: ='Infos Mensuelles'!L10 -> 0
A32: OT Hours Basic | G32: ='Infos Mensuelles'!AI10 -> 0
A33: OT Hours Public holidays | G33: ='Infos Mensuelles'!AL10 -> 0
A34: OT Days | G34: ='Infos Mensuelles'!AP10 -> 279
A35: Air Plane Ticket Refundable | G35: ='Infos Mensuelles'!AS10 -> 0
A37: Deductions
A38: Pension Locals Employees (Non eligible) | J38: ='Infos Mensuelles'!AU10 -> 0
A39: Adjustment form previous month(s) | J39: ='Infos Mensuelles'!AV10 -> 0
A40: Advance salary | J40: ='Infos Mensuelles'!AW10 -> 0
A41: Absences | J41: ='Infos Mensuelles'!AA10 -> 0
A42: Unpaid leaves | J42: ='Infos Mensuelles'!X10 -> 0
A43: Emergency leave | J43: ='Infos Mensuelles'!Y10 -> 0
A44: Sick Leave Unpaid
A46: TOTAL EARNINGS & DEDUCTIONS | G46: =SUM(G27:I35) -> 8779 | J46: =SUM(J40:L45) -> 0
A49: TOTAL AMOUNT : | G49: =G46-J46 -> 8779
A53: Payment informations:
A54: Date of payment: | D54: ='Infos Mensuelles'!E1 -> 46053
A55: Methode of payment: | D55: WPS
A56: If you need any informations please contact us at hr-dubai@chabe.com

Sheet Anoop
A1: CHABE LUXURY TRANSPORT LLC
A2: 11B Street Warehouse 3b/27
A3: AL KHABAISI
A4: Dubai, UAE
A5: ='Infos Mensuelles'!A1 -> Salary Slip January 2026
A8: Employee last name: | D8: ='Infos Mensuelles'!B11 -> SASIDHARAN PUTHENAYATHIL RAGHAVAN | H8: Employee ID: | J8: ='Infos Mensuelles'!F11 -> 10012127956935
H9: Arrival date: | J9: ='Infos Mensuelles'!D11 -> 43002
A11: Employee first name | D11: ='Infos Mensuelles'!C11 -> Anoop | H11: Employee Position: | J11: ='Infos Mensuelles'!G11 -> Archiev clerk
A15: Employee Attendance
A16: Working days: | D16: ='Infos Mensuelles'!N11 -> 26 | E16: OT Hours Basic | H16: ='Infos Mensuelles'!AG11 -> 0 | I16: Absence day | L16: ='Infos Mensuelles'!W11 -> 0
A17: Working Public Holidays: | D17: ='Infos Mensuelles'!P11 -> 1 | E17: OT Hours Public holidays | H17: ='Infos Mensuelles'!AJ11 -> 0 | I17: Emergency Leave Unpaid : | L17: ='Infos Mensuelles'!U11 -> 0
A18: Off days: | D18: ='Infos Mensuelles'!O11 -> 4 | E18: OT Days | H18: ='Infos Mensuelles'!AJ11 -> 0 | I18: Leaves without pay: | L18: ='Infos Mensuelles'!T11 -> 0
A19: Sick Leave | D19: ='Infos Mensuelles'!R11 -> 0 | E19: Leave Payable: | H19: ='Infos Mensuelles'!Q11 -> 0
A20: Payable days: | D20: ='Infos Mensuelles'!S11 -> 31
A23: Earnings & Deductions
A24: Salary Head | G24: Amount Earnings (AED) | J24: Amount Deductions (AED)
A26: Earnings
A27: Basic Salary | G27: ='Infos Mensuelles'!H11 -> 3900
A28: Housing Allowances | G28: ='Infos Mensuelles'!I11 -> 1300
A29: Transport Allowances | G29: ='Infos Mensuelles'!J11 -> 1300
A30: School Allowances | G30: ='Infos Mensuelles'!K11 -> 0
A31: Monthly Bonus | G31: ='Infos Mensuelles'!L11 -> 0
A32: OT Hours Basic | G32: ='Infos Mensuelles'!AI11 -> 0
A33: OT Hours Public holidays | G33: ='Infos Mensuelles'!AL11 -> 0
A34: OT Days | G34: ='Infos Mensuelles'!AP11 -> 214
A35: Air Plane Ticket Refundable | G35: ='Infos Mensuelles'!AS11 -> 0
A37: Deductions
A38: Pension Locals Employees (Non eligible) | J38: ='Infos Mensuelles'!AU11 -> 0
A39: Adjustment form previous month(s) | J39: ='Infos Mensuelles'!AV11 -> 0
A40: Advance salary | J40: ='Infos Mensuelles'!AW11 -> 0
A41: Absences | J41: ='Infos Mensuelles'!AA11 -> 0
A42: Unpaid leaves | J42: ='Infos Mensuelles'!X11 -> 0
A43: Emergency leave | J43: ='Infos Mensuelles'!Y11 -> 0
A44: Sick Leave Unpaid
A46: TOTAL EARNINGS & DEDUCTIONS | G46: =SUM(G27:I35) -> 6714 | J46: =SUM(J40:L45) -> 0
A49: TOTAL AMOUNT : | G49: =G46-J46 -> 6714
A53: Payment informations:
A54: Date of payment: | D54: ='Infos Mensuelles'!E1 -> 46053
A55: Methode of payment: | D55: WPS
A56: If you need any informations please contact us at hr-dubai@chabe.com

Sheet Azeem
A1: CHABE LUXURY TRANSPORT LLC
A2: 11B Street Warehouse 3b/27
A3: AL KHABAISI
A4: Dubai, UAE
A5: ='Infos Mensuelles'!A1 -> Salary Slip January 2026
A8: Employee last name: | D8: ='Infos Mensuelles'!B12 -> SHAREEQ MOHAMMED YUSUF ISMAIL | H8: Employee ID: | J8: ='Infos Mensuelles'!F12 -> 10027039033676
H9: Arrival date: | J9: ='Infos Mensuelles'!D12 -> 44243
A11: Employee first name | D11: ='Infos Mensuelles'!C12 -> Azeem | H11: Employee Position: | J11: ='Infos Mensuelles'!G12 -> Filing clerk
A15: Employee Attendance
A16: Working days: | D16: ='Infos Mensuelles'!N12 -> 25 | E16: OT Hours Basic | H16: ='Infos Mensuelles'!AG12 -> 8 | I16: Absence day | L16: ='Infos Mensuelles'!W12 -> 0
A17: Working Public Holidays: | D17: ='Infos Mensuelles'!P12 -> 1 | E17: OT Hours Public holidays | H17: ='Infos Mensuelles'!AJ12 -> 0 | I17: Emergency Leave Unpaid : | L17: ='Infos Mensuelles'!U12 -> 0
A18: Off days: | D18: ='Infos Mensuelles'!O12 -> 5 | E18: OT Days | H18: ='Infos Mensuelles'!AJ12 -> 0 | I18: Leaves without pay: | L18: ='Infos Mensuelles'!T12 -> 0
A19: Sick Leave | D19: ='Infos Mensuelles'!R12 -> 0 | E19: Leave Payable: | H19: ='Infos Mensuelles'!Q12 -> 0
A20: Payable days: | D20: ='Infos Mensuelles'!S12 -> 31
A23: Earnings & Deductions
A24: Salary Head | G24: Amount Earnings (AED) | J24: Amount Deductions (AED)
A26: Earnings
A27: Basic Salary | G27: ='Infos Mensuelles'!H12 -> 3600
A28: Housing Allowances | G28: ='Infos Mensuelles'!I12 -> 1200
A29: Transport Allowances | G29: ='Infos Mensuelles'!J12 -> 1200
A30: School Allowances | G30: ='Infos Mensuelles'!K12 -> 0
A31: Monthly Bonus | G31: ='Infos Mensuelles'!L12 -> 0
A32: OT Hours Basic | G32: ='Infos Mensuelles'!AI12 -> 128
A33: OT Hours Public holidays | G33: ='Infos Mensuelles'!AL12 -> 0
A34: OT Days | G34: ='Infos Mensuelles'!AP12 -> 197
A35: Air Plane Ticket Refundable | G35: ='Infos Mensuelles'!AS12 -> 0
A37: Deductions
A38: Pension Locals Employees (Non eligible) | J38: ='Infos Mensuelles'!AU12 -> 0
A39: Adjustment form previous month(s) | J39: ='Infos Mensuelles'!AV12 -> 0
A40: Advance salary | J40: ='Infos Mensuelles'!AW12 -> 0
A41: Absences | J41: ='Infos Mensuelles'!AA12 -> 0
A42: Unpaid leaves | J42: ='Infos Mensuelles'!X12 -> 0
A43: Emergency leave | J43: ='Infos Mensuelles'!Y12 -> 0
A44: Sick Leave Unpaid
A46: TOTAL EARNINGS & DEDUCTIONS | G46: =SUM(G27:I35) -> 6325 | J46: =SUM(J40:L45) -> 0
A49: TOTAL AMOUNT : | G49: =G46-J46 -> 6325
A53: Payment informations:
A54: Date of payment: | D54: ='Infos Mensuelles'!E1 -> 46053
A55: Methode of payment: | D55: WPS
A56: If you need any informations please contact us at hr-dubai@chabe.com

Sheet Maideen
A1: CHABE LUXURY TRANSPORT LLC
A2: 11B Street Warehouse 3b/27
A3: AL KHABAISI
A4: Dubai, UAE
A5: ='Infos Mensuelles'!A1 -> Salary Slip January 2026
A8: Employee last name: | D8: ='Infos Mensuelles'!B13 -> MOHAMED KASSIM | H8: Employee ID: | J8: ='Infos Mensuelles'!F13 -> 10025128665320
H9: Arrival date: | J9: ='Infos Mensuelles'!D13 -> 45231
A11: Employee first name | D11: ='Infos Mensuelles'!C13 -> Maideen | H11: Employee Position: | J11: ='Infos Mensuelles'!G13 -> Messenger
A15: Employee Attendance
A16: Working days: | D16: ='Infos Mensuelles'!N13 -> 24 | E16: OT Hours Basic | H16: ='Infos Mensuelles'!AG13 -> 0 | I16: Absence day | L16: ='Infos Mensuelles'!W13 -> 0
A17: Working Public Holidays: | D17: ='Infos Mensuelles'!P13 -> 0 | E17: OT Hours Public holidays | H17: ='Infos Mensuelles'!AJ13 -> 0 | I17: Emergency Leave Unpaid : | L17: ='Infos Mensuelles'!U13 -> 0
A18: Off days: | D18: ='Infos Mensuelles'!O13 -> 5 | E18: OT Days | H18: ='Infos Mensuelles'!AJ13 -> 0 | I18: Leaves without pay: | L18: ='Infos Mensuelles'!T13 -> 0
A19: Sick Leave | D19: ='Infos Mensuelles'!R13 -> 0 | E19: Leave Payable: | H19: ='Infos Mensuelles'!Q13 -> 2
A20: Payable days: | D20: ='Infos Mensuelles'!S13 -> 31
A23: Earnings & Deductions
A24: Salary Head | G24: Amount Earnings (AED) | J24: Amount Deductions (AED)
A26: Earnings
A27: Basic Salary | G27: ='Infos Mensuelles'!H13 -> 3000
A28: Housing Allowances | G28: ='Infos Mensuelles'!I13 -> 1000
A29: Transport Allowances | G29: ='Infos Mensuelles'!J13 -> 1000
A30: School Allowances | G30: ='Infos Mensuelles'!K13 -> 0
A31: Monthly Bonus | G31: ='Infos Mensuelles'!L13 -> 0
A32: OT Hours Basic | G32: ='Infos Mensuelles'!AI13 -> 0
A33: OT Hours Public holidays | G33: ='Infos Mensuelles'!AL13 -> 0
A34: OT Days | G34: ='Infos Mensuelles'!AP13 -> 0
A35: Air Plane Ticket Refundable | G35: ='Infos Mensuelles'!AS13 -> 0
A37: Deductions
A38: Pension Locals Employees (Non eligible) | J38: ='Infos Mensuelles'!AU13 -> 0
A39: Adjustment form previous month(s) | J39: ='Infos Mensuelles'!AV13 -> 0
A40: Advance salary | J40: ='Infos Mensuelles'!AW13 -> 1925.7
A41: Absences | J41: ='Infos Mensuelles'!AA13 -> 0
A42: Unpaid leaves | J42: ='Infos Mensuelles'!X13 -> 0
A43: Emergency leave | J43: ='Infos Mensuelles'!Y13 -> 0
A44: Sick Leave Unpaid
A46: TOTAL EARNINGS & DEDUCTIONS | G46: =SUM(G27:I35) -> 5000 | J46: =SUM(J40:L45) -> 1925.7
A49: TOTAL AMOUNT : | G49: =G46-J46 -> 3074.3
A53: Payment informations:
A54: Date of payment: | D54: ='Infos Mensuelles'!E1 -> 46053
A55: Methode of payment: | D55: WPS
A56: If you need any informations please contact us at hr-dubai@chabe.com

Sheet Prince
A1: CHABE LUXURY TRANSPORT LLC
A2: 11B Street Warehouse 3b/27
A3: AL KHABAISI
A4: Dubai, UAE
A5: ='Infos Mensuelles'!A1 -> Salary Slip January 2026
A8: Employee last name: | D8: ='Infos Mensuelles'!B14 -> SIVARAMAN GOPINATH | H8: Employee ID: | J8: ='Infos Mensuelles'!F14 -> 10021048238840
H9: Arrival date: | J9: ='Infos Mensuelles'!D14 -> 44606
A11: Employee first name | D11: ='Infos Mensuelles'!C14 -> Prince | H11: Employee Position: | J11: ='Infos Mensuelles'!G14 -> Archiev clerk
A15: Employee Attendance
A16: Working days: | D16: ='Infos Mensuelles'!N14 -> 26 | E16: OT Hours Basic | H16: ='Infos Mensuelles'!AG14 -> 0 | I16: Absence day | L16: ='Infos Mensuelles'!W14 -> 0
A17: Working Public Holidays: | D17: ='Infos Mensuelles'!P14 -> 1 | E17: OT Hours Public holidays | H17: ='Infos Mensuelles'!AJ14 -> 0 | I17: Emergency Leave Unpaid : | L17: ='Infos Mensuelles'!U14 -> 0
A18: Off days: | D18: ='Infos Mensuelles'!O14 -> 4 | E18: OT Days | H18: ='Infos Mensuelles'!AJ14 -> 0 | I18: Leaves without pay: | L18: ='Infos Mensuelles'!T14 -> 0
A19: Sick Leave | D19: ='Infos Mensuelles'!R14 -> 0 | E19: Leave Payable: | H19: ='Infos Mensuelles'!Q14 -> 0
A20: Payable days: | D20: ='Infos Mensuelles'!S14 -> 31
A23: Earnings & Deductions
A24: Salary Head | G24: Amount Earnings (AED) | J24: Amount Deductions (AED)
A26: Earnings
A27: Basic Salary | G27: ='Infos Mensuelles'!H14 -> 3600
A28: Housing Allowances | G28: ='Infos Mensuelles'!I14 -> 1200
A29: Transport Allowances | G29: ='Infos Mensuelles'!J14 -> 1200
A30: School Allowances | G30: ='Infos Mensuelles'!K14 -> 0
A31: Monthly Bonus | G31: ='Infos Mensuelles'!L14 -> 0
A32: OT Hours Basic | G32: ='Infos Mensuelles'!AI14 -> 0
A33: OT Hours Public holidays | G33: ='Infos Mensuelles'!AL14 -> 0
A34: OT Days | G34: ='Infos Mensuelles'!AP14 -> 197
A35: Air Plane Ticket Refundable | G35: ='Infos Mensuelles'!AS14 -> 0
A37: Deductions
A38: Pension Locals Employees (Non eligible) | J38: ='Infos Mensuelles'!AU14 -> 0
A39: Adjustment form previous month(s) | J39: ='Infos Mensuelles'!AV14 -> 0
A40: Advance salary | J40: ='Infos Mensuelles'!AW14 -> 0
A41: Absences | J41: ='Infos Mensuelles'!AA14 -> 0
A42: Unpaid leaves | J42: ='Infos Mensuelles'!X14 -> 0
A43: Emergency leave | J43: ='Infos Mensuelles'!Y14 -> 0
A44: Sick Leave Unpaid
A46: TOTAL EARNINGS & DEDUCTIONS | G46: =SUM(G27:I35) -> 6197 | J46: =SUM(J40:L45) -> 0
A49: TOTAL AMOUNT : | G49: =G46-J46 -> 6197
A53: Payment informations:
A54: Date of payment: | D54: ='Infos Mensuelles'!E1 -> 46053
A55: Methode of payment: | D55: WPS
A56: If you need any informations please contact us at hr-dubai@chabe.com

Sheet Sajub
A1: CHABE LUXURY TRANSPORT LLC
A2: 11B Street Warehouse 3b/27
A3: AL KHABAISI
A4: Dubai, UAE
A5: ='Infos Mensuelles'!A1 -> Salary Slip January 2026
A8: Employee last name: | D8: ='Infos Mensuelles'!B15 -> RAHMAN PATTUVAM | H8: Employee ID: | J8: ='Infos Mensuelles'!F15 -> 10030039360020
H9: Arrival date: | J9: ='Infos Mensuelles'!D15 -> 45260
A11: Employee first name | D11: ='Infos Mensuelles'!C15 -> Sajub | H11: Employee Position: | J11: ='Infos Mensuelles'!G15 -> Messenger
A15: Employee Attendance
A16: Working days: | D16: ='Infos Mensuelles'!N15 -> 26 | E16: OT Hours Basic | H16: ='Infos Mensuelles'!AG15 -> 25 | I16: Absence day | L16: ='Infos Mensuelles'!W15 -> 0
A17: Working Public Holidays: | D17: ='Infos Mensuelles'!P15 -> 1 | E17: OT Hours Public holidays | H17: ='Infos Mensuelles'!AJ15 -> 0 | I17: Emergency Leave Unpaid : | L17: ='Infos Mensuelles'!U15 -> 0
A18: Off days: | D18: ='Infos Mensuelles'!O15 -> 4 | E18: OT Days | H18: ='Infos Mensuelles'!AJ15 -> 0 | I18: Leaves without pay: | L18: ='Infos Mensuelles'!T15 -> 0
A19: Sick Leave | D19: ='Infos Mensuelles'!R15 -> 0 | E19: Leave Payable: | H19: ='Infos Mensuelles'!Q15 -> 0
A20: Payable days: | D20: ='Infos Mensuelles'!S15 -> 31
A23: Earnings & Deductions
A24: Salary Head | G24: Amount Earnings (AED) | J24: Amount Deductions (AED)
A26: Earnings
A27: Basic Salary | G27: ='Infos Mensuelles'!H15 -> 3300
A28: Housing Allowances | G28: ='Infos Mensuelles'!I15 -> 1100
A29: Transport Allowances | G29: ='Infos Mensuelles'!J15 -> 1100
A30: School Allowances | G30: ='Infos Mensuelles'!K15 -> 0
A31: Monthly Bonus | G31: ='Infos Mensuelles'!L15 -> 0
A32: OT Hours Basic | G32: ='Infos Mensuelles'!AI15 -> 375
A33: OT Hours Public holidays | G33: ='Infos Mensuelles'!AL15 -> 0
A34: OT Days | G34: ='Infos Mensuelles'!AP15 -> 181
A35: Air Plane Ticket Refundable | G35: ='Infos Mensuelles'!AS15 -> 0
A37: Deductions
A38: Pension Locals Employees (Non eligible) | J38: ='Infos Mensuelles'!AU15 -> 0
A39: Adjustment form previous month(s) | J39: ='Infos Mensuelles'!AV15 -> 0
A40: Advance salary | J40: ='Infos Mensuelles'!AW15 -> 0
A41: Absences | J41: ='Infos Mensuelles'!AA15 -> 0
A42: Unpaid leaves | J42: ='Infos Mensuelles'!X15 -> 0
A43: Emergency leave | J43: ='Infos Mensuelles'!Y15 -> 0
A44: Sick Leave Unpaid
A46: TOTAL EARNINGS & DEDUCTIONS | G46: =SUM(G27:I35) -> 6056 | J46: =SUM(J40:L45) -> 0
A49: TOTAL AMOUNT : | G49: =G46-J46 -> 6056
A53: Payment informations:
A54: Date of payment: | D54: ='Infos Mensuelles'!E1 -> 46053
A55: Methode of payment: | D55: WPS
A56: If you need any informations please contact us at hr-dubai@chabe.com

Sheet Shanavas
A1: CHABE LUXURY TRANSPORT LLC
A2: 11B Street Warehouse 3b/27
A3: AL KHABAISI
A4: Dubai, UAE
A5: ='Infos Mensuelles'!A1 -> Salary Slip January 2026
A8: Employee last name: | D8: ='Infos Mensuelles'!B16 -> VAYAMBATHODY KUNHIMOIDU | H8: Employee ID: | J8: ='Infos Mensuelles'!F16 -> 10025047761962
H9: Arrival date: | J9: ='Infos Mensuelles'!D16 -> 41912
A11: Employee first name | D11: ='Infos Mensuelles'!C16 -> Shanavas | H11: Employee Position: | J11: ='Infos Mensuelles'!G16 -> Follow up clerk
A15: Employee Attendance
A16: Working days: | D16: ='Infos Mensuelles'!N16 -> 21 | E16: OT Hours Basic | H16: ='Infos Mensuelles'!AG16 -> 0 | I16: Absence day | L16: ='Infos Mensuelles'!W16 -> 0
A17: Working Public Holidays: | D17: ='Infos Mensuelles'!P16 -> 1 | E17: OT Hours Public holidays | H17: ='Infos Mensuelles'!AJ16 -> 0 | I17: Emergency Leave Unpaid : | L17: ='Infos Mensuelles'!U16 -> 0
A18: Off days: | D18: ='Infos Mensuelles'!O16 -> 4 | E18: OT Days | H18: ='Infos Mensuelles'!AJ16 -> 0 | I18: Leaves without pay: | L18: ='Infos Mensuelles'!T16 -> 0
A19: Sick Leave | D19: ='Infos Mensuelles'!R16 -> 0 | E19: Leave Payable: | H19: ='Infos Mensuelles'!Q16 -> 5
A20: Payable days: | D20: ='Infos Mensuelles'!S16 -> 31
A23: Earnings & Deductions
A24: Salary Head | G24: Amount Earnings (AED) | J24: Amount Deductions (AED)
A26: Earnings
A27: Basic Salary | G27: ='Infos Mensuelles'!H16 -> 5100
A28: Housing Allowances | G28: ='Infos Mensuelles'!I16 -> 1700
A29: Transport Allowances | G29: ='Infos Mensuelles'!J16 -> 1700
A30: School Allowances | G30: ='Infos Mensuelles'!K16 -> 0
A31: Monthly Bonus | G31: ='Infos Mensuelles'!L16 -> 0
A32: OT Hours Basic | G32: ='Infos Mensuelles'!AI16 -> 0
A33: OT Hours Public holidays | G33: ='Infos Mensuelles'!AL16 -> 0
A34: OT Days | G34: ='Infos Mensuelles'!AP16 -> 279
A35: Air Plane Ticket Refundable | G35: ='Infos Mensuelles'!AS16 -> 0
A37: Deductions
A38: Pension Locals Employees (Non eligible) | J38: ='Infos Mensuelles'!AU16 -> 0
A39: Adjustment form previous month(s) | J39: ='Infos Mensuelles'!AV16 -> 0
A40: Advance salary | J40: ='Infos Mensuelles'!AW16 -> 0
A41: Absences | J41: ='Infos Mensuelles'!AA16 -> 0
A42: Unpaid leaves | J42: ='Infos Mensuelles'!X16 -> 0
A43: Emergency leave | J43: ='Infos Mensuelles'!Y16 -> 0
A44: Sick Leave Unpaid
A46: TOTAL EARNINGS & DEDUCTIONS | G46: =SUM(G27:I35) -> 8779 | J46: =SUM(J40:L45) -> 0
A49: TOTAL AMOUNT : | G49: =G46-J46 -> 8779
A53: Payment informations:
A54: Date of payment: | D54: ='Infos Mensuelles'!E1 -> 46053
A55: Methode of payment: | D55: WPS
A56: If you need any informations please contact us at hr-dubai@chabe.com

Sheet Raiza
A1: CHABE LUXURY TRANSPORT LLC
A2: 11B Street Warehouse 3b/27
A3: AL KHABAISI
A4: Dubai, UAE
A5: ='Infos Mensuelles'!A1 -> Salary Slip January 2026
A8: Employee last name: | D8: ='Infos Mensuelles'!B17 -> NIEVA | H8: Employee ID: | J8: ='Infos Mensuelles'!F17 -> 30404129679881
H9: Arrival date: | J9: ='Infos Mensuelles'!D17 -> 45985
A11: Employee first name | D11: ='Infos Mensuelles'!C17 -> Raiza | H11: Employee Position: | J11: ='Infos Mensuelles'!G17 -> Back office officer
A15: Employee Attendance
A16: Working days: | D16: ='Infos Mensuelles'!N17 -> 26 | E16: OT Hours Basic | H16: ='Infos Mensuelles'!AG17 -> 0 | I16: Absence day | L16: ='Infos Mensuelles'!W17 -> 0
A17: Working Public Holidays: | D17: ='Infos Mensuelles'!P17 -> 1 | E17: OT Hours Public holidays | H17: ='Infos Mensuelles'!AJ17 -> 0 | I17: Emergency Leaves Unpaid : | L17: ='Infos Mensuelles'!U17 -> 0
A18: Off days: | D18: ='Infos Mensuelles'!O17 -> 4 | E18: OT Days | H18: ='Infos Mensuelles'!AN17 -> 0 | I18: Unpaid Leaves : | L18: ='Infos Mensuelles'!T17 -> 0
A19: Sick Leave | D19: ='Infos Mensuelles'!R17 -> 0 | E19: Leave Payable: | H19: ='Infos Mensuelles'!Q17 -> 0
A20: Payable days: | D20: ='Infos Mensuelles'!S17 -> 31
A23: Earnings & Deductions
A24: Salary Head | G24: Amount Earnings (AED) | J24: Amount Deductions (AED)
A26: Earnings
A27: Basic Salary | G27: ='Infos Mensuelles'!H17 -> 2400
A28: Housing Allowances | G28: ='Infos Mensuelles'!I17 -> 800
A29: Transport Allowances | G29: ='Infos Mensuelles'!J17 -> 800
A30: School Allowances | G30: ='Infos Mensuelles'!K17 -> 0
A31: Monthly Bonus | G31: ='Infos Mensuelles'!L17 -> 0
A32: OT Hours Basic | G32: ='Infos Mensuelles'!AI17 -> 0
A33: OT Hours Public holidays | G33: ='Infos Mensuelles'!AL17 -> 0
A34: OT Days | G34: ='Infos Mensuelles'!AP17 -> 0
A35: Air Plane Ticket Refundable | G35: ='Infos Mensuelles'!AS17 -> 0
A37: Deductions
A38: Pension Locals Employees (Non eligible) | J38: 0
A39: Adjustment form previous month(s) | J39: ='Infos Mensuelles'!AV17 -> 0
A40: Advance salary | J40: ='Infos Mensuelles'!AW17 -> 0
A41: Absences | J41: ='Infos Mensuelles'!AA17 -> 0
A42: Unpaid leaves | J42: ='Infos Mensuelles'!X17 -> 0
A43: Emergency leave | J43: ='Infos Mensuelles'!Y17 -> 0
A44: Sick Leave Unpaid | J44: ='Infos Mensuelles'!Z17 -> 0
A46: TOTAL EARNINGS & DEDUCTIONS | G46: =SUM(G27:I35) -> 4000 | J46: =SUM(J40:L45) -> 0
A49: TOTAL AMOUNT : | G49: =G46-J46 -> 4000
A53: Payment informations:
A54: Date of payment: | D54: ='Infos Mensuelles'!E1 -> 46053
A55: Methode of payment: | D55: WPS
A56: If you need any informations please contact us at hr-dubai@chabe.com

Sheet Loshin
A1: CHABE LUXURY TRANSPORT LLC
A2: 11B Street Warehouse 3b/27
A3: AL KHABAISI
A4: Dubai, UAE
A5: ='Infos Mensuelles'!A1 -> Salary Slip January 2026
A8: Employee last name: | D8: ='Infos Mensuelles'!B18 -> THAZHUTHARINTAVIDA | H8: Employee ID: | J8: ='Infos Mensuelles'!F18 -> 10005068743230
H9: Arrival date: | J9: ='Infos Mensuelles'!D18 -> 46012
A11: Employee first name | D11: ='Infos Mensuelles'!C18 -> Loshin | H11: Employee Position: | J11: ='Infos Mensuelles'!G18 -> 0
A15: Employee Attendance
A16: Working days: | D16: ='Infos Mensuelles'!N18 -> 26 | E16: OT Hours Basic | H16: ='Infos Mensuelles'!AG18 -> 26 | I16: Absence day | L16: ='Infos Mensuelles'!W18 -> 0
A17: Working Public Holidays: | D17: ='Infos Mensuelles'!P18 -> 1 | E17: OT Hours Public holidays | H17: ='Infos Mensuelles'!AJ18 -> 0 | I17: Emergency Leaves Unpaid : | L17: ='Infos Mensuelles'!U18 -> 0
A18: Off days: | D18: ='Infos Mensuelles'!O18 -> 4 | E18: OT Days | H18: ='Infos Mensuelles'!AN18 -> 1 | I18: Unpaid Leaves : | L18: ='Infos Mensuelles'!T18 -> 0
A19: Sick Leave | D19: ='Infos Mensuelles'!R18 -> 0 | E19: Leave Payable: | H19: ='Infos Mensuelles'!Q18 -> 0
A20: Payable days: | D20: ='Infos Mensuelles'!S18 -> 31
A23: Earnings & Deductions
A24: Salary Head | G24: Amount Earnings (AED) | J24: Amount Deductions (AED)
A26: Earnings
A27: Basic Salary | G27: ='Infos Mensuelles'!H18 -> 3000
A28: Housing Allowances | G28: ='Infos Mensuelles'!I18 -> 1000
A29: Transport Allowances | G29: ='Infos Mensuelles'!J18 -> 1000
A30: School Allowances | G30: ='Infos Mensuelles'!K18 -> 0
A31: Monthly Bonus | G31: ='Infos Mensuelles'!L18 -> 0
A32: OT Hours Basic | G32: ='Infos Mensuelles'!AI18 -> 364
A33: OT Hours Public holidays | G33: ='Infos Mensuelles'!AL18 -> 0
A34: OT Days | G34: ='Infos Mensuelles'!AP18 -> 164
A35: Air Plane Ticket Refundable | G35: ='Infos Mensuelles'!AS18 -> 0
A37: Deductions
A38: Pension Locals Employees (Non eligible) | J38: 0
A39: Adjustment form previous month(s) | J39: ='Infos Mensuelles'!AV18 -> 0
A40: Advance salary | J40: ='Infos Mensuelles'!AW18 -> 0
A41: Absences | J41: ='Infos Mensuelles'!AA18 -> 0
A42: Unpaid leaves | J42: ='Infos Mensuelles'!X18 -> 0
A43: Emergency leave | J43: ='Infos Mensuelles'!Y18 -> 0
A44: Sick Leave Unpaid | J44: ='Infos Mensuelles'!Z18 -> 0
A46: TOTAL EARNINGS & DEDUCTIONS | G46: =SUM(G27:I35) -> 5528 | J46: =SUM(J40:L45) -> 0
A49: TOTAL AMOUNT : | G49: =G46-J46 -> 5528
A53: Payment informations:
A54: Date of payment: | D54: ='Infos Mensuelles'!E1 -> 46053
A55: Methode of payment: | D55: WPS
A56: If you need any informations please contact us at hr-dubai@chabe.com

Sheet Patma
A1: CHABE LUXURY TRANSPORT LLC
A2: 11B Street Warehouse 3b/27
A3: AL KHABAISI
A4: Dubai, UAE
A5: ='Infos Mensuelles'!A1 -> Salary Slip January 2026
A8: Employee last name: | D8: ='Infos Mensuelles'!B19 -> PADAMANATHAN | H8: Employee ID: | J8: ='Infos Mensuelles'!F19 -> 10022016768789
H9: Arrival date: | J9: ='Infos Mensuelles'!D19 -> 44095
A11: Employee first name | D11: ='Infos Mensuelles'!C19 -> Ramu | H11: Employee Position: | J11: ='Infos Mensuelles'!G19 -> Cleaner
A15: Employee Attendance
A16: Working days: | D16: ='Infos Mensuelles'!N19 -> 25 | E16: OT Hours Basic | H16: ='Infos Mensuelles'!AG19 -> 0 | I16: Absence day | L16: ='Infos Mensuelles'!W19 -> 0
A17: Working Public Holidays: | D17: ='Infos Mensuelles'!P19 -> 1 | E17: OT Hours Public holidays | H17: ='Infos Mensuelles'!AJ19 -> 0 | I17: Emergency Leave Unpaid : | L17: ='Infos Mensuelles'!U19 -> 0
A18: Off days: | D18: ='Infos Mensuelles'!O19 -> 5 | E18: OT Days | H18: ='Infos Mensuelles'!AJ19 -> 0 | I18: Leaves without pay: | L18: ='Infos Mensuelles'!T19 -> 0
A19: Sick Leave | D19: ='Infos Mensuelles'!R19 -> 0 | E19: Leave Payable: | H19: ='Infos Mensuelles'!Q19 -> 0
A20: Payable days: | D20: ='Infos Mensuelles'!S19 -> 31
A23: Earnings & Deductions
A24: Salary Head | G24: Amount Earnings (AED) | J24: Amount Deductions (AED)
A26: Earnings
A27: Basic Salary | G27: ='Infos Mensuelles'!H19 -> 2160
A28: Housing Allowances | G28: ='Infos Mensuelles'!I19 -> 720
A29: Transport Allowances | G29: ='Infos Mensuelles'!J19 -> 720
A30: School Allowances | G30: ='Infos Mensuelles'!K19 -> 0
A31: Monthly Bonus | G31: ='Infos Mensuelles'!L19 -> 0
A32: OT Hours Basic | G32: ='Infos Mensuelles'!AI19 -> 0
A33: OT Hours Public holidays | G33: ='Infos Mensuelles'!AL19 -> 0
A34: OT Days | G34: ='Infos Mensuelles'!AP19 -> 115
A35: Air Plane Ticket Refundable | G35: ='Infos Mensuelles'!AS19 -> 0
A37: Deductions
A38: Pension Locals Employees (Non eligible) | J38: ='Infos Mensuelles'!AU19 -> 0
A39: Adjustment form previous month(s) | J39: ='Infos Mensuelles'!AV19 -> 0
A40: Advance salary | J40: ='Infos Mensuelles'!AW19 -> 0
A41: Absences | J41: ='Infos Mensuelles'!AA19 -> 0
A42: Unpaid leaves | J42: ='Infos Mensuelles'!X19 -> 0
A43: Emergency leave | J43: ='Infos Mensuelles'!Y19 -> 0
A44: Sick Leave Unpaid
A46: TOTAL EARNINGS & DEDUCTIONS | G46: =SUM(G27:I35) -> 3715 | J46: =SUM(J40:L45) -> 0
A49: TOTAL AMOUNT : | G49: =G46-J46 -> 3715
A53: Payment informations:
A54: Date of payment: | D54: ='Infos Mensuelles'!E1 -> 46053
A55: Methode of payment: | D55: WPS
A56: If you need any informations please contact us at hr-dubai@chabe.com

Sheet Rather
A1: CHABE LUXURY TRANSPORT LLC
A2: 11B Street Warehouse 3b/27
A3: AL KHABAISI
A4: Dubai, UAE
A5: ='Infos Mensuelles'!A1 -> Salary Slip January 2026
A8: Employee last name: | D8: ='Infos Mensuelles'!B20 -> YAKKOOB | H8: Employee ID: | J8: ='Infos Mensuelles'!F20 -> 10007018981824
H9: Arrival date: | J9: ='Infos Mensuelles'!D20 -> 45955
A11: Employee first name | D11: ='Infos Mensuelles'!C20 -> Rather | H11: Employee Position: | J11: ='Infos Mensuelles'!G20 -> Cleaner
A15: Employee Attendance
A16: Working days: | D16: ='Infos Mensuelles'!N20 -> 25 | E16: OT Hours Basic | H16: ='Infos Mensuelles'!AG20 -> 0 | I16: Absence day | L16: ='Infos Mensuelles'!W20 -> 0
A17: Working Public Holidays: | D17: ='Infos Mensuelles'!P20 -> 1 | E17: OT Hours Public holidays | H17: ='Infos Mensuelles'!AJ20 -> 0 | I17: Emergency Leaves Unpaid : | L17: ='Infos Mensuelles'!U20 -> 0
A18: Off days: | D18: ='Infos Mensuelles'!O20 -> 5 | E18: OT Days | H18: ='Infos Mensuelles'!AN20 -> 1 | I18: Unpaid Leaves : | L18: ='Infos Mensuelles'!T20 -> 0
A19: Sick Leave | D19: ='Infos Mensuelles'!R20 -> 0 | E19: Leave Payable: | H19: ='Infos Mensuelles'!Q20 -> 0
A20: Payable days: | D20: ='Infos Mensuelles'!S20 -> 31
A23: Earnings & Deductions
A24: Salary Head | G24: Amount Earnings (AED) | J24: Amount Deductions (AED)
A26: Earnings
A27: Basic Salary | G27: ='Infos Mensuelles'!H20 -> 1800
A28: Housing Allowances | G28: ='Infos Mensuelles'!I20 -> 600
A29: Transport Allowances | G29: ='Infos Mensuelles'!J20 -> 600
A30: School Allowances | G30: ='Infos Mensuelles'!K20 -> 0
A31: Monthly Bonus | G31: ='Infos Mensuelles'!L20 -> 0
A32: OT Hours Basic | G32: ='Infos Mensuelles'!AI20 -> 0
A33: OT Hours Public holidays | G33: ='Infos Mensuelles'!AL20 -> 0
A34: OT Days | G34: ='Infos Mensuelles'!AP20 -> 99
A35: Air Plane Ticket Refundable | G35: ='Infos Mensuelles'!AS20 -> 0
A37: Deductions
A38: Pension Locals Employees (Non eligible) | J38: 0
A39: Adjustment form previous month(s) | J39: ='Infos Mensuelles'!AV20 -> 0
A40: Advance salary | J40: ='Infos Mensuelles'!AW20 -> 0
A41: Absences | J41: ='Infos Mensuelles'!AA20 -> 0
A42: Unpaid leaves | J42: ='Infos Mensuelles'!X20 -> 0
A43: Emergency leave | J43: ='Infos Mensuelles'!Y20 -> 0
A44: Sick Leave Unpaid | J44: ='Infos Mensuelles'!Z20 -> 0
A46: TOTAL EARNINGS & DEDUCTIONS | G46: =SUM(G27:I35) -> 3099 | J46: =SUM(J38:L45) -> 0
A49: TOTAL AMOUNT : | G49: =G46-J46 -> 3099
A53: Payment informations:
A54: Date of payment: | D54: ='Infos Mensuelles'!E1 -> 46053
A55: Methode of payment: | D55: WPS
A56: If you need any informations please contact us at hr-dubai@chabe.com

Sheet Mariam
A1: CHABE LUXURY TRANSPORT LLC
A2: 11B Street Warehouse 3b/27
A3: AL KHABAISI
A4: Dubai, UAE
A5: ='Infos Mensuelles'!A1 -> Salary Slip January 2026
A8: Employee last name: | D8: ='Infos Mensuelles'!B21 -> ALZAABI | H8: Employee ID: | J8: ='Infos Mensuelles'!F21 -> _02120129566913
H9: Arrival date: | J9: ='Infos Mensuelles'!D21 -> 45600
A11: Employee first name | D11: ='Infos Mensuelles'!C21 -> Mariam | H11: Employee Position: | J11: ='Infos Mensuelles'!G21 -> Operations Coordinator (Remote)
A15: Employee Attendance
A16: Working days: | D16: ='Infos Mensuelles'!N21 -> 21 | E16: OT Hours Basic | H16: ='Infos Mensuelles'!AG21 -> 0 | I16: Absence day | L16: ='Infos Mensuelles'!W21 -> 0
A17: Working Public Holidays: | D17: ='Infos Mensuelles'!P21 -> 1 | E17: OT Hours Public holidays | H17: ='Infos Mensuelles'!AJ21 -> 0 | I17: Emergency Leave Unpaid : | L17: ='Infos Mensuelles'!U21 -> 0
A18: Off days: | D18: ='Infos Mensuelles'!O21 -> 9 | E18: OT Days | H18: ='Infos Mensuelles'!AJ21 -> 0 | I18: Leaves without pay: | L18: ='Infos Mensuelles'!T21 -> 0
A19: Sick Leave | D19: ='Infos Mensuelles'!R21 -> 0 | E19: Leave Payable: | H19: ='Infos Mensuelles'!Q21 -> 0
A20: Payable days: | D20: ='Infos Mensuelles'!S21 -> 31
A23: Earnings & Deductions
A24: Salary Head | G24: Amount Earnings (AED) | J24: Amount Deductions (AED)
A26: Earnings
A27: Basic Salary | G27: ='Infos Mensuelles'!H21 -> 3000
A28: Housing Allowances | G28: ='Infos Mensuelles'!I21 -> 1000
A29: Transport Allowances | G29: ='Infos Mensuelles'!J21 -> 1000
A30: School Allowances | G30: ='Infos Mensuelles'!K21 -> 0
A31: Monthly Bonus | G31: ='Infos Mensuelles'!L21 -> 0
A32: OT Hours Basic | G32: ='Infos Mensuelles'!AI21 -> 0
A33: OT Hours Public holidays | G33: ='Infos Mensuelles'!AL21 -> 0
A34: OT Days | G34: ='Infos Mensuelles'!AP21 -> 0
A35: Air Plane Ticket Refundable (Non eligible) | G35: ='Infos Mensuelles'!AS21 -> 0
A37: Deductions
A38: Pension Locals Employees | J38: ='Infos Mensuelles'!AU21 -> 550
A39: Adjustment form previous month(s) | J39: ='Infos Mensuelles'!AV21 -> 0
A40: Advance salary | J40: ='Infos Mensuelles'!AW21 -> 0
A41: Absences | J41: ='Infos Mensuelles'!AA21 -> 0
A42: Unpaid leaves | J42: ='Infos Mensuelles'!X21 -> 0
A43: Emergency leave | J43: ='Infos Mensuelles'!Y21 -> 0
A44: Sick Leave Unpaid | J44: ='Infos Mensuelles'!Z21 -> 0
A45: Deductions related to a contract with a late start date | J45: ='Infos Mensuelles'!Z48 -> 0
A46: TOTAL EARNINGS & DEDUCTIONS | G46: =SUM(G27:I35) -> 5000 | J46: =SUM(J38:L45) -> 550
A49: TOTAL AMOUNT : | G49: =G46-J46 -> 4450
A53: Payment informations:
A54: Date of payment: | D54: ='Infos Mensuelles'!E1 -> 46053
A55: Methode of payment: | D55: WPS
...

Sheet Fetoun
A1: CHABE LUXURY TRANSPORT LLC
A2: 11B Street Warehouse 3b/27
A3: AL KHABAISI
A4: Dubai, UAE
A5: ='Infos Mensuelles'!A1 -> Salary Slip January 2026
A8: Employee last name: | D8: ='Infos Mensuelles'!B22 -> ALZAABI | H8: Employee ID: | J8: ='Infos Mensuelles'!F22 -> _02124060158242
H9: Arrival date: | J9: ='Infos Mensuelles'!D22 -> 45600
A11: Employee first name | D11: ='Infos Mensuelles'!C22 -> Fetoun | H11: Employee Position: | J11: ='Infos Mensuelles'!G22 -> Inside Sales Assistant (Remote)
A15: Employee Attendance
A16: Working days: | D16: ='Infos Mensuelles'!N22 -> 21 | E16: OT Hours Basic | H16: ='Infos Mensuelles'!AG22 -> 0 | I16: Absence day | L16: ='Infos Mensuelles'!W22 -> 0
A17: Working Public Holidays: | D17: ='Infos Mensuelles'!P22 -> 1 | E17: OT Hours Public holidays | H17: ='Infos Mensuelles'!AJ22 -> 0 | I17: Emergency Leave Unpaid : | L17: ='Infos Mensuelles'!U22 -> 0
A18: Off days: | D18: ='Infos Mensuelles'!O22 -> 9 | E18: OT Days | H18: ='Infos Mensuelles'!AJ22 -> 0 | I18: Leaves without pay: | L18: ='Infos Mensuelles'!T22 -> 0
A19: Sick Leave | D19: ='Infos Mensuelles'!R22 -> 0 | E19: Leave Payable: | H19: ='Infos Mensuelles'!Q22 -> 0
A20: Payable days: | D20: ='Infos Mensuelles'!S22 -> 31
A23: Earnings & Deductions
A24: Salary Head | G24: Amount Earnings (AED) | J24: Amount Deductions (AED)
A26: Earnings
A27: Basic Salary | G27: ='Infos Mensuelles'!H22 -> 3000
A28: Housing Allowances | G28: ='Infos Mensuelles'!I22 -> 1000
A29: Transport Allowances | G29: ='Infos Mensuelles'!J22 -> 1000
A30: School Allowances | G30: ='Infos Mensuelles'!K22 -> 0
A31: Monthly Bonus | G31: ='Infos Mensuelles'!L22 -> 0
A32: OT Hours Basic | G32: ='Infos Mensuelles'!AI22 -> 0
A33: OT Hours Public holidays | G33: ='Infos Mensuelles'!AL22 -> 0
A34: OT Days | G34: ='Infos Mensuelles'!AP22 -> 0
A35: Air Plane Ticket Refundable (Non eligible) | G35: ='Infos Mensuelles'!AS22 -> 0
A37: Deductions
A38: Pension Locals Employees (Non eligible) | J38: ='Infos Mensuelles'!AU22 -> 550
A39: Adjustment form previous month(s) | J39: ='Infos Mensuelles'!AV22 -> 0
A40: Advance salary | J40: ='Infos Mensuelles'!AW22 -> 0
A41: Absences | J41: ='Infos Mensuelles'!AA22 -> 0
A42: Unpaid leaves | J42: ='Infos Mensuelles'!X22 -> 0
A43: Emergency leave | J43: ='Infos Mensuelles'!Y22 -> 0
A44: Sick Leave Unpaid | J44: ='Infos Mensuelles'!Z22 -> 0
