Workbook

Sheet Infos Mensuelles
A1: Salary slip January 2026 | E1: 46053
A4: Informations Employee | H4: Contract base | L4: Earnings | AS4: Deductions | AV4: Total Earning | AW4: WPS Law | AZ4: Comments
A5: N° | B5: Last Name | C5: First Name | D5: Date of arrival | E5: Release date | F5: Employee ID | G5: Job name | H5: Basic salary | I5: Housing Allowances | J5: Transportation Allowance | K5: Total on Contract | L5: Working days | R5: Absence Days Unpaid | AA5: TOTAL of Days during the month | AB5: Paid | AE5: OT Hours | AL5: OT Days | AO5: Other Allowance | AP5: Adjustment for previous month | AQ5: Air plane Ticket | AR5: Total Earning | AS5: Advance payment/ Deduction Advance | AT5: Fines payment advance by the company | AU5: Adjustment for previous month | AV5: TOTAL RECEIVABLE | AW5: Need to be send by the law for WPS | AX5: Missing on salary | AY5: Adjustment to send
L6: No. working days | M6: Off days | N6: Public Holydays | O6: No. leave days PAID | P6: Sick Leave PAID | Q6: Total Working days payable | R6: No. leave days UNPAID | S6: Emergancy Leave UNPAID | T6: Sick leave UNPAID | U6: Absent days (not allowed) | V6: UNPAID Leave Amount | W6: Emergancy Leave Amount | X6: Sick leave UNPAID | Y6: Absent days (not allowed) | Z6: Total Working days unpayable | AB6: Leave PAID Amount | AC6: Sick Leave Amount | AD6: Salary | AE6: Hours | AF6: Amount Normal OT | AG6: Total | AH6: Public Holydays | AI6: Amont Public Holydays | AJ6: Total | AK6: Total | AL6: Days | AM6: Amount | AN6: Total
A7: D0001 | B7: MANNAPPAN THARAMMAL | C7: Abdulla | D7: 23.08.2022 | F7: 10028058458199 | G7: Light Vehicule Driver | H7: =K7*60% -> 2580 | I7: =K7*20% -> 860 | J7: =K7*20% -> 860 | K7: 4300 | L7: 28 | M7: 3 | N7: 0 | O7: 0 | P7: 0 | Q7: =L7+M7+N7+O7+P7 -> 31 | R7: 0 | S7: 0 | T7: 0 | U7: 0 | V7: =K7/31*R7 -> 0 | W7: =K7/31*S7 -> 0 | X7: =K7/31*T7 -> 0 | Y7: =K7/31*U7 -> 0 | Z7: =R7+S7+T7+U7 -> 0 | AA7: =Q7+Z7 -> 31 | AB7: =K7/31*O7 -> 0 | AC7: =K7/31*P7 -> 0 | AD7: =SUM(K7/31*Q7) -> 4300 | AE7: 5 | AF7: 12 | AG7: =AE7*AF7 -> 60 | AH7: 0 | AI7: 14 | AJ7: =AH7*AI7 -> 0 | AK7: =AG7+AJ7 -> 60 | AL7: 2 | AM7: 141 | AN7: =AL7*AM7 -> 282 | AQ7: 0 | AR7: =SUM(AD7+AK7+AN7+AO7+AP7+AQ7) -> 4642 | AS7: 0 | AT7: 0 | AU7: 0 | AV7: =AR7-AS7-AT7-AU7 -> 4642 | AW7: =SUM(K7*80%) -> 3440 | AX7: =AV7-AW7 -> 1202 | AY7: =+AV7-AW7-AX7 -> 0
A8: D0002 | B8: SYED NABI AHMAD | C8: Irfran Ahmed | D8: 44414 | F8: 10005027939914 | G8: Light Vehicule Driver | H8: =K8*60% -> 2640 | I8: =K8*20% -> 880 | J8: =K8*20% -> 880 | K8: 4400 | L8: 29 | M8: 2 | N8: 0 | O8: 0 | P8: 0 | Q8: =L8+M8+N8+O8+P8 -> 31 | R8: 0 | S8: 0 | T8: 0 | U8: 0 | V8: =K8/31*R8 -> 0 | W8: =K8/31*S8 -> 0 | X8: =K8/31*T8 -> 0 | Y8: =K8/31*U8 -> 0 | Z8: =R8+S8+T8+U8 -> 0 | AA8: =Q8+Z8 -> 31 | AB8: =K8/31*O8 -> 0 | AC8: =K8/31*P8 -> 0 | AD8: =SUM(K8/31*Q8) -> 4400 | AE8: 6 | AF8: 12 | AG8: =AE8*AF8 -> 72 | AH8: 0 | AI8: 14 | AJ8: =AH8*AI8 -> 0 | AK8: =AG8+AJ8 -> 72 | AL8: 3 | AM8: 145 | AN8: =AL8*AM8 -> 435 | AQ8: 0 | AR8: =SUM(AD8+AK8+AN8+AO8+AP8+AQ8) -> 4907 | AS8: 0 | AT8: 520 | AU8: 0 | AV8: =AR8-AS8-AT8-AU8 -> 4387 | AW8: =SUM(K8*80%) -> 3520 | AX8: =AV8-AW8 -> 867 | AY8: =+AV8-AW8-AX8 -> 0
A9: D0003 | B9: SHAMSUDEEN | C9: Amanullah | D9: 19.09.2021 | F9: 10013067459387 | G9: Light Vehicule Driver | H9: =K9*60% -> 2640 | I9: =K9*20% -> 880 | J9: =K9*20% -> 880 | K9: 4400 | L9: 28 | M9: 3 | N9: 0 | O9: 0 | P9: 0 | Q9: =L9+M9+N9+O9+P9 -> 31 | R9: 0 | S9: 0 | T9: 0 | U9: 0 | V9: =K9/31*R9 -> 0 | W9: =K9/31*S9 -> 0 | X9: =K9/31*T9 -> 0 | Y9: =K9/31*U9 -> 0 | Z9: =R9+S9+T9+U9 -> 0 | AA9: =Q9+Z9 -> 31 | AB9: =K9/31*O9 -> 0 | AC9: =K9/31*P9 -> 0 | AD9: =SUM(K9/31*Q9) -> 4400 | AE9: 6 | AF9: 12 | AG9: =AE9*AF9 -> 72 | AH9: 1 | AI9: 14 | AJ9: =AH9*AI9 -> 14 | AK9: =AG9+AJ9 -> 86 | AL9: 2 | AM9: 145 | AN9: =AL9*AM9 -> 290 | AQ9: 0 | AR9: =SUM(AD9+AK9+AN9+AO9+AP9+AQ9) -> 4776 | AS9: 0 | AT9: 300 | AU9: 0 | AV9: =AR9-AS9-AT9-AU9 -> 4476 | AW9: =SUM(K9*80%) -> 3520 | AX9: =AV9-AW9 -> 956 | AY9: =+AV9-AW9-AX9 -> 0
A10: D0004 | B10: BOGATTI | C10: Anam | D10: 42470 | F10: 31620017062269 | G10: Light Vehicule Driver | H10: =K10*60% -> 2700 | I10: =K10*20% -> 900 | J10: =K10*20% -> 900 | K10: 4500 | L10: 27 | M10: 4 | N10: 0 | O10: 0 | P10: 0 | Q10: =L10+M10+N10+O10+P10 -> 31 | R10: 0 | S10: 0 | T10: 0 | U10: 0 | V10: =K10/31*R10 -> 0 | W10: =K10/31*S10 -> 0 | X10: =K10/31*T10 -> 0 | Y10: =K10/31*U10 -> 0 | Z10: =R10+S10+T10+U10 -> 0 | AA10: =Q10+Z10 -> 31 | AB10: =K10/31*O10 -> 0 | AC10: =K10/31*P10 -> 0 | AD10: =SUM(K10/31*Q10) -> 4500 | AE10: 7 | AF10: 12 | AG10: =AE10*AF10 -> 84 | AH10: 0 | AI10: 15 | AJ10: =AH10*AI10 -> 0 | AK10: =AG10+AJ10 -> 84 | AL10: 1 | AM10: 148 | AN10: =AL10*AM10 -> 148 | AQ10: 0 | AR10: =SUM(AD10+AK10+AN10+AO10+AP10+AQ10) -> 4732 | AS10: 0 | AT10: 0 | AU10: 0 | AV10: =AR10-AS10-AT10-AU10 -> 4732 | AW10: =SUM(K10*80%) -> 3600 | AX10: =AV10-AW10 -> 1132 | AY10: =+AV10-AW10-AX10 -> 0
A11: D0005 | B11: SUNKADAKATTE ABDULKHADER | C11: Mohamed Aneefa | D11: 42898 | F11: 10019057895758 | G11: Light Vehicule Driver | H11: =K11*60% -> 2700 | I11: =K11*20% -> 900 | J11: =K11*20% -> 900 | K11: 4500 | L11: 28 | M11: 3 | N11: 0 | O11: 0 | P11: 0 | Q11: =L11+M11+N11+O11+P11 -> 31 | R11: 0 | S11: 0 | T11: 0 | U11: 0 | V11: =K11/31*R11 -> 0 | W11: =K11/31*S11 -> 0 | X11: =K11/31*T11 -> 0 | Y11: =K11/31*U11 -> 0 | Z11: =R11+S11+T11+U11 -> 0 | AA11: =Q11+Z11 -> 31 | AB11: =K11/31*O11 -> 0 | AC11: =K11/31*P11 -> 0 | AD11: =SUM(K11/31*Q11) -> 4500 | AE11: 2 | AF11: 12 | AG11: =AE11*AF11 -> 24 | AH11: 0 | AI11: 15 | AJ11: =AH11*AI11 -> 0 | AK11: =AG11+AJ11 -> 24 | AL11: 2 | AM11: 148 | AN11: =AL11*AM11 -> 296 | AQ11: 0 | AR11: =SUM(AD11+AK11+AN11+AO11+AP11+AQ11) -> 4820 | AS11: 0 | AT11: 0 | AU11: 0 | AV11: =AR11-AS11-AT11-AU11 -> 4820 | AW11: =SUM(K11*80%) -> 3600 | AX11: =AV11-AW11 -> 1220 | AY11: =+AV11-AW11-AX11 -> 0
A12: D0006 | B12: JAINULAPUDEEN MOHAMED | C12: Anees | D12: 44501 | F12: 10030078086699 | G12: Light Vehicule Driver | H12: =K12*60% -> 2640 | I12: =K12*20% -> 880 | J12: =K12*20% -> 880 | K12: 4400 | L12: 27 | M12: 4 | N12: 0 | O12: 0 | P12: 0 | Q12: =L12+M12+N12+O12+P12 -> 31 | R12: 0 | S12: 0 | T12: 0 | U12: 0 | V12: =K12/31*R12 -> 0 | W12: =K12/31*S12 -> 0 | X12: =K12/31*T12 -> 0 | Y12: =K12/31*U12 -> 0 | Z12: =R12+S12+T12+U12 -> 0 | AA12: =Q12+Z12 -> 31 | AB12: =K12/31*O12 -> 0 | AC12: =K12/31*P12 -> 0 | AD12: =SUM(K12/31*Q12) -> 4400 | AE12: 20 | AF12: 12 | AG12: =AE12*AF12 -> 240 | AH12: 0 | AI12: 14 | AJ12: =AH12*AI12 -> 0 | AK12: =AG12+AJ12 -> 240 | AL12: 0 | AM12: 145 | AN12: =AL12*AM12 -> 0 | AQ12: 0 | AR12: =SUM(AD12+AK12+AN12+AO12+AP12+AQ12) -> 4640 | AS12: 0 | AT12: 0 | AU12: 0 | AV12: =AR12-AS12-AT12-AU12 -> 4640 | AW12: =SUM(K12*80%) -> 3520 | AX12: =AV12-AW12 -> 1120 | AY12: =+AV12-AW12-AX12 -> 0
A13: D0007 | B13: SHAH MISAL SHAH BUKHARI | C13: Asal | D13: 44726 | F13: 20001018653644 | G13: Light Vehicule Driver | H13: =K13*60% -> 2580 | I13: =K13*20% -> 860 | J13: =K13*20% -> 860 | K13: 4300 | L13: 28 | M13: 3 | N13: 0 | O13: 0 | P13: 0 | Q13: =L13+M13+N13+O13+P13 -> 31 | R13: 0 | S13: 0 | T13: 0 | U13: 0 | V13: =K13/31*R13 -> 0 | W13: =K13/31*S13 -> 0 | X13: =K13/31*T13 -> 0 | Y13: =K13/31*U13 -> 0 | Z13: =R13+S13+T13+U13 -> 0 | AA13: =Q13+Z13 -> 31 | AB13: =K13/31*O13 -> 0 | AC13: =K13/31*P13 -> 0 | AD13: =SUM(K13/31*Q13) -> 4300 | AE13: 4 | AF13: 12 | AG13: =AE13*AF13 -> 48 | AH13: 0 | AI13: 14 | AJ13: =AH13*AI13 -> 0 | AK13: =AG13+AJ13 -> 48 | AL13: 2 | AM13: 141 | AN13: =AL13*AM13 -> 282 | AQ13: 0 | AR13: =SUM(AD13+AK13+AN13+AO13+AP13+AQ13) -> 4630 | AS13: 0 | AT13: 0 | AU13: 0 | AV13: =AR13-AS13-AT13-AU13 -> 4630 | AW13: =SUM(K13*80%) -> 3440 | AX13: =AV13-AW13 -> 1190 | AY13: =+AV13-AW13-AX13 -> 0
A14: D0008 | B14: FAZAL HUSSAIN | C14: Atta Rasool | D14: 42642 | F14: 20015018877124 | G14: Light Vehicule Driver | H14: =K14*60% -> 2700 | I14: =K14*20% -> 900 | J14: =K14*20% -> 900 | K14: 4500 | L14: 29 | M14: 2 | N14: 0 | O14: 0 | P14: 0 | Q14: =L14+M14+N14+O14+P14 -> 31 | R14: 0 | S14: 0 | T14: 0 | U14: 0 | V14: =K14/31*R14 -> 0 | W14: =K14/31*S14 -> 0 | X14: =K14/31*T14 -> 0 | Y14: =K14/31*U14 -> 0 | Z14: =R14+S14+T14+U14 -> 0 | AA14: =Q14+Z14 -> 31 | AB14: =K14/31*O14 -> 0 | AC14: =K14/31*P14 -> 0 | AD14: =SUM(K14/31*Q14) -> 4500 | AE14: 5 | AF14: 12 | AG14: =AE14*AF14 -> 60 | AH14: 0 | AI14: 15 | AJ14: =AH14*AI14 -> 0 | AK14: =AG14+AJ14 -> 60 | AL14: 3 | AM14: 148 | AN14: =AL14*AM14 -> 444 | AQ14: 0 | AR14: =SUM(AD14+AK14+AN14+AO14+AP14+AQ14) -> 5004 | AS14: 0 | AT14: 0 | AU14: 0 | AV14: =AR14-AS14-AT14-AU14 -> 5004 | AW14: =SUM(K14*80%) -> 3600 | AX14: =AV14-AW14 -> 1404 | AY14: =+AV14-AW14-AX14 -> 0
A15: D0009 | B15: ULLAH MUHAMMAD RIAZ | C15: Attiq | D15: 43507 | F15: 20010118687794 | G15: Light Vehicule Driver | H15: =K15*60% -> 2700 | I15: =K15*20% -> 900 | J15: =K15*20% -> 900 | K15: 4500 | L15: 28 | M15: 3 | N15: 0 | O15: 0 | P15: 0 | Q15: =L15+M15+N15+O15+P15 -> 31 | R15: 0 | S15: 0 | T15: 0 | U15: 0 | V15: =K15/31*R15 -> 0 | W15: =K15/31*S15 -> 0 | X15: =K15/31*T15 -> 0 | Y15: =K15/31*U15 -> 0 | Z15: =R15+S15+T15+U15 -> 0 | AA15: =Q15+Z15 -> 31 | AB15: =K15/31*O15 -> 0 | AC15: =K15/31*P15 -> 0 | AD15: =SUM(K15/31*Q15) -> 4500 | AE15: 7 | AF15: 12 | AG15: =AE15*AF15 -> 84 | AH15: 0 | AI15: 15 | AJ15: =AH15*AI15 -> 0 | AK15: =AG15+AJ15 -> 84 | AL15: 1 | AM15: 148 | AN15: =AL15*AM15 -> 148 | AQ15: 0 | AR15: =SUM(AD15+AK15+AN15+AO15+AP15+AQ15) -> 4732 | AS15: 0 | AT15: 0 | AU15: 0 | AV15: =AR15-AS15-AT15-AU15 -> 4732 | AW15: =SUM(K15*80%) -> 3600 | AX15: =AV15-AW15 -> 1132 | AY15: =+AV15-AW15-AX15 -> 0
A16: D0010 | B16: KHAN NAZIR | C16: Bilal | D16: 44664 | F16: 20011019277621 | G16: Light Vehicule Driver | H16: =K16*60% -> 2580 | I16: =K16*20% -> 860 | J16: =K16*20% -> 860 | K16: 4300 | L16: 25 | M16: 4 | N16: 0 | O16: 0 | P16: 2 | Q16: =L16+M16+N16+O16+P16 -> 31 | R16: 0 | S16: 0 | T16: 0 | U16: 0 | V16: =K16/31*R16 -> 0 | W16: =K16/31*S16 -> 0 | X16: =K16/31*T16 -> 0 | Y16: =K16/31*U16 -> 0 | Z16: =R16+S16+T16+U16 -> 0 | AA16: =Q16+Z16 -> 31 | AB16: =K16/31*O16 -> 0 | AC16: =K16/31*P16 -> 277.41935 | AD16: =SUM(K16/31*Q16) -> 4300 | AE16: 9 | AF16: 12 | AG16: =AE16*AF16 -> 108 | AH16: 0 | AI16: 14 | AJ16: =AH16*AI16 -> 0 | AK16: =AG16+AJ16 -> 108 | AL16: 1 | AM16: 141 | AN16: =AL16*AM16 -> 141 | AQ16: 0 | AR16: =SUM(AD16+AK16+AN16+AO16+AP16+AQ16) -> 4549 | AS16: 0 | AT16: 0 | AU16: 0 | AV16: =AR16-AS16-AT16-AU16 -> 4549 | AW16: =SUM(K16*80%) -> 3440 | AX16: =AV16-AW16 -> 1109 | AY16: =+AV16-AW16-AX16 -> 0 | AZ16: FAKE TICKET in 2024
A17: D0011 | B17: ISMAIL SAMSUDEEN | C17: Farook | D17: 45310 | F17: 10030079016477 | G17: Light Vehicule Driver | H17: =K17*60% -> 2520 | I17: =K17*20% -> 840 | J17: =K17*20% -> 840 | K17: 4200 | L17: 28 | M17: 3 | N17: 0 | O17: 0 | P17: 0 | Q17: =L17+M17+N17+O17+P17 -> 31 | R17: 0 | S17: 0 | T17: 0 | U17: 0 | V17: =K17/31*R17 -> 0 | W17: =K17/31*S17 -> 0 | X17: =K17/31*T17 -> 0 | Y17: =K17/31*U17 -> 0 | Z17: =R17+S17+T17+U17 -> 0 | AA17: =Q17+Z17 -> 31 | AB17: =K17/31*O17 -> 0 | AC17: =K17/31*P17 -> 0 | AD17: =SUM(K17/31*Q17) -> 4200 | AE17: 6 | AF17: 12 | AG17: =AE17*AF17 -> 72 | AH17: 0 | AI17: 14 | AJ17: =AH17*AI17 -> 0 | AK17: =AG17+AJ17 -> 72 | AL17: 2 | AM17: 138 | AN17: =AL17*AM17 -> 276 | AQ17: 0 | AR17: =SUM(AD17+AK17+AN17+AO17+AP17+AQ17) -> 4548 | AS17: 0 | AT17: 0 | AU17: 0 | AV17: =AR17-AS17-AT17-AU17 -> 4548 | AW17: =SUM(K17*80%) -> 3360 | AX17: =AV17-AW17 -> 1188 | AY17: =+AV17-AW17-AX17 -> 0
A18: D0012 | B18: MOHIDEEN ABDUL RAHUMAN | C18: Haja | D18: 43671 | F18: 10017048332090 | G18: Light Vehicule Driver | H18: =K18*60% -> 2700 | I18: =K18*20% -> 900 | J18: =K18*20% -> 900 | K18: 4500 | L18: 27 | M18: 4 | N18: 0 | O18: 0 | P18: 0 | Q18: =L18+M18+N18+O18+P18 -> 31 | R18: 0 | S18: 0 | T18: 0 | U18: 0 | V18: =K18/31*R18 -> 0 | W18: =K18/31*S18 -> 0 | X18: =K18/31*T18 -> 0 | Y18: =K18/31*U18 -> 0 | Z18: =R18+S18+T18+U18 -> 0 | AA18: =Q18+Z18 -> 31 | AB18: =K18/31*O18 -> 0 | AC18: =K18/31*P18 -> 0 | AD18: =SUM(K18/31*Q18) -> 4500 | AE18: 12 | AF18: 12 | AG18: =AE18*AF18 -> 144 | AH18: 0 | AI18: 15 | AJ18: =AH18*AI18 -> 0 | AK18: =AG18+AJ18 -> 144 | AL18: 0 | AM18: 148 | AN18: =AL18*AM18 -> 0 | AQ18: 1306.64 | AR18: =SUM(AD18+AK18+AN18+AO18+AP18+AQ18) -> 5950.64 | AS18: 0 | AT18: 800 | AU18: 0 | AV18: =AR18-AS18-AT18-AU18 -> 5150.64 | AW18: =SUM(K18*80%) -> 3600 | AX18: =AV18-AW18 -> 1550.64 | AY18: =+AV18-AW18-AX18 -> 0 | AZ18: AIR TICKET TO BE PAID
A19: D0013 | B19: KHAN AHMAD KHAN | C19: Ibrahim | D19: 44855 | F19: 20002038203486 | G19: Light Vehicule Driver | H19: =K19*60% -> 2580 | I19: =K19*20% -> 860 | J19: =K19*20% -> 860 | K19: 4300 | L19: 28 | M19: 3 | N19: 0 | O19: 0 | P19: 0 | Q19: =L19+M19+N19+O19+P19 -> 31 | R19: 0 | S19: 0 | T19: 0 | U19: 0 | V19: =K19/31*R19 -> 0 | W19: =K19/31*S19 -> 0 | X19: =K19/31*T19 -> 0 | Y19: =K19/31*U19 -> 0 | Z19: =R19+S19+T19+U19 -> 0 | AA19: =Q19+Z19 -> 31 | AB19: =K19/31*O19 -> 0 | AC19: =K19/31*P19 -> 0 | AD19: =SUM(K19/31*Q19) -> 4300 | AE19: 13 | AF19: 12 | AG19: =AE19*AF19 -> 156 | AH19: 0 | AI19: 14 | AJ19: =AH19*AI19 -> 0 | AK19: =AG19+AJ19 -> 156 | AL19: 1 | AM19: 141 | AN19: =AL19*AM19 -> 141 | AQ19: 0 | AR19: =SUM(AD19+AK19+AN19+AO19+AP19+AQ19) -> 4597 | AS19: 0 | AT19: 0 | AU19: 0 | AV19: =AR19-AS19-AT19-AU19 -> 4597 | AW19: =SUM(K19*80%) -> 3440 | AX19: =AV19-AW19 -> 1157 | AY19: =+AV19-AW19-AX19 -> 0
A20: D0014 | C20: Haider | D20: 46030 | F20: 20029018381980 | G20: Light Vehicule Driver | H20: =K20*60% -> 2100 | I20: =K20*20% -> 700 | J20: =K20*20% -> 700 | K20: 3500 | L20: 21 | M20: 3 | N20: 0 | O20: 0 | P20: 0 | Q20: =L20+M20+N20+O20+P20 -> 24 | R20: 0 | S20: 0 | T20: 0 | U20: 0 | V20: =K20/31*R20 -> 0 | W20: =K20/31*S20 -> 0 | X20: =K20/31*T20 -> 0 | Y20: =K20/31*U20 -> 0 | Z20: =R20+S20+T20+U20 -> 0 | AA20: =Q20+Z20 -> 24 | AB20: =K20/31*O20 -> 0 | AC20: =K20/31*P20 -> 0 | AD20: =SUM(K20/31*Q20) -> 2709.6774 | AE20: 2 | AF20: 10 | AG20: =AE20*AF20 -> 20 | AH20: 0 | AI20: 12 | AJ20: =AH20*AI20 -> 0 | AL20: 0 | AM20: 115 | AN20: =AL20*AM20 -> 0 | AQ20: 0 | AR20: =SUM(AD20+AK20+AN20+AO20+AP20+AQ20) -> 2709.6774 | AS20: 0 | AT20: 426 | AU20: 0 | AV20: =AR20-AS20-AT20-AU20 -> 2283.6774 | AW20: =SUM(K20*80%) -> 2800 | AX20: =AV20-AW20 -> -516.32258 | AY20: =+AV20-AW20-AX20 -> 0
A21: D0015 | B21: HUSSAIN JAINULLABUDEEN | C21: Jahir | D21: 43653 | F21: 10001066217554 | G21: Light Vehicule Driver | H21: =K21*60% -> 2700 | I21: =K21*20% -> 900 | J21: =K21*20% -> 900 | K21: 4500 | L21: 14 | M21: 2 | N21: 0 | O21: 0 | P21: 0 | Q21: =L21+M21+N21+O21+P21 -> 16 | R21: 15 | S21: 0 | T21: 0 | U21: 0 | V21: =K21/31*R21 -> 2177.4194 | W21: =K21/31*S21 -> 0 | X21: =K21/31*T21 -> 0 | Y21: =K21/31*U21 -> 0 | Z21: =R21+S21+T21+U21 -> 15 | AA21: =Q21+Z21 -> 31 | AB21: =K21/31*O21 -> 0 | AC21: =K21/31*P21 -> 0 | AD21: =SUM(K21/31*Q21) -> 2322.5806 | AE21: 4 | AF21: 12 | AG21: =AE21*AF21 -> 48 | AH21: 0 | AI21: 15 | AJ21: =AH21*AI21 -> 0 | AK21: =AG21+AJ21 -> 48 | AL21: 1 | AM21: 148 | AN21: =AL21*AM21 -> 148 | AQ21: 0 | AR21: =SUM(AD21+AK21+AN21+AO21+AP21+AQ21) -> 2518.5806 | AS21: 0 | AT21: 0 | AU21: 0 | AV21: =AR21-AS21-AT21-AU21 -> 2518.5806 | AW21: =SUM(K21*80%) -> 3600 | AX21: =AV21-AW21 -> -1081.4194 | AY21: =+AV21-AW21-AX21 -> 0
A22: D0016 | B22: CHERPANATH JOY | C22: Poulose | D22: 42956 | F22: 10029036003822 | G22: Light Vehicule Driver | H22: =K22*60% -> 2700 | I22: =K22*20% -> 900 | J22: =K22*20% -> 900 | K22: 4500 | L22: 28 | M22: 3 | N22: 0 | O22: 0 | P22: 0 | Q22: =L22+M22+N22+O22+P22 -> 31 | R22: 0 | S22: 0 | T22: 0 | U22: 0 | V22: =K22/31*R22 -> 0 | W22: =K22/31*S22 -> 0 | X22: =K22/31*T22 -> 0 | Y22: =K22/31*U22 -> 0 | Z22: =R22+S22+T22+U22 -> 0 | AA22: =Q22+Z22 -> 31 | AB22: =K22/31*O22 -> 0 | AC22: =K22/31*P22 -> 0 | AD22: =SUM(K22/31*Q22) -> 4500 | AE22: 1 | AF22: 12 | AG22: =AE22*AF22 -> 12 | AH22: 0 | AI22: 15 | AJ22: =AH22*AI22 -> 0 | AK22: =AG22+AJ22 -> 12 | AL22: 2 | AM22: 148 | AN22: =AL22*AM22 -> 296 | AQ22: 0 | AR22: =SUM(AD22+AK22+AN22+AO22+AP22+AQ22) -> 4808 | AS22: 0 | AT22: 0 | AU22: 0 | AV22: =AR22-AS22-AT22-AU22 -> 4808 | AW22: =SUM(K22*80%) -> 3600 | AX22: =AV22-AW22 -> 1208 | AY22: =+AV22-AW22-AX22 -> 0
A23: D0017 | B23: SIRAJ MUHAMMAD | C23: Kamran Khan | D23: 44797 | F23: 20028129188803 | G23: Light Vehicule Driver | H23: =K23*60% -> 2580 | I23: =K23*20% -> 860 | J23: =K23*20% -> 860 | K23: 4300 | L23: 28 | M23: 3 | N23: 0 | O23: 0 | P23: 0 | Q23: =L23+M23+N23+O23+P23 -> 31 | R23: 0 | S23: 0 | T23: 0 | U23: 0 | V23: =K23/31*R23 -> 0 | W23: =K23/31*S23 -> 0 | X23: =K23/31*T23 -> 0 | Y23: =K23/31*U23 -> 0 | Z23: =R23+S23+T23+U23 -> 0 | AA23: =Q23+Z23 -> 31 | AB23: =K23/31*O23 -> 0 | AC23: =K23/31*P23 -> 0 | AD23: =SUM(K23/31*Q23) -> 4300 | AE23: 29 | AF23: 12 | AG23: =AE23*AF23 -> 348 | AH23: 0 | AI23: 14 | AJ23: =AH23*AI23 -> 0 | AK23: =AG23+AJ23 -> 348 | AL23: 2 | AM23: 141 | AN23: =AL23*AM23 -> 282 | AO23: 160 | AQ23: 0 | AR23: =SUM(AD23+AK23+AN23+AO23+AP23+AQ23) -> 5090 | AS23: 0 | AT23: 0 | AU23: 0 | AV23: =AR23-AS23-AT23-AU23 -> 5090 | AW23: =SUM(K23*80%) -> 3440 | AX23: =AV23-AW23 -> 1650 | AY23: =+AV23-AW23-AX23 -> 0
A24: D0018 | B24: RICHARD SEA | C24: Kene | D24: 45287 | F24: 41023128217554 | G24: Light Vehicule Driver | H24: =K24*60% -> 2520 | I24: =K24*20% -> 840 | J24: =K24*20% -> 840 | K24: 4200 | L24: 28 | M24: 3 | N24: 0 | O24: 0 | P24: 0 | Q24: =L24+M24+N24+O24+P24 -> 31 | R24: 0 | S24: 0 | T24: 0 | U24: 0 | V24: =K24/31*R24 -> 0 | W24: =K24/31*S24 -> 0 | X24: =K24/31*T24 -> 0 | Y24: =K24/31*U24 -> 0 | Z24: =R24+S24+T24+U24 -> 0 | AA24: =Q24+Z24 -> 31 | AB24: =K24/31*O24 -> 0 | AC24: =K24/31*P24 -> 0 | AD24: =SUM(K24/31*Q24) -> 4200 | AE24: 18 | AF24: 12 | AG24: =AE24*AF24 -> 216 | AH24: 0 | AI24: 14 | AJ24: =AH24*AI24 -> 0 | AK24: =AG24+AJ24 -> 216 | AL24: 2 | AM24: 138 | AN24: =AL24*AM24 -> 276 | AQ24: 0 | AR24: =SUM(AD24+AK24+AN24+AO24+AP24+AQ24) -> 4692 | AS24: 0 | AT24: 0 | AU24: 0 | AV24: =AR24-AS24-AT24-AU24 -> 4692 | AW24: =SUM(K24*80%) -> 3360 | AX24: =AV24-AW24 -> 1332 | AY24: =+AV24-AW24-AX24 -> 0
A25: D0019 | B25: KAAMIL SYED ALI | C25: Mohsin | D25: 43079 | F25: 10022028260817 | G25: Light Vehicule Driver | H25: =K25*60% -> 2700 | I25: =K25*20% -> 900 | J25: =K25*20% -> 900 | K25: 4500 | L25: 20 | M25: 2 | N25: 0 | O25: 0 | P25: 0 | Q25: =L25+M25+N25+O25+P25 -> 22 | R25: 0 | S25: 9 | T25: 0 | U25: 0 | V25: =K25/31*R25 -> 0 | W25: =K25/31*S25 -> 1306.4516 | X25: =K25/31*T25 -> 0 | Y25: =K25/31*U25 -> 0 | Z25: =R25+S25+T25+U25 -> 9 | AA25: =Q25+Z25 -> 31 | AB25: =K25/31*O25 -> 0 | AC25: =K25/31*P25 -> 0 | AD25: =SUM(K25/31*Q25) -> 3193.5484 | AE25: 9 | AF25: 12 | AG25: =AE25*AF25 -> 108 | AH25: 0 | AI25: 15 | AJ25: =AH25*AI25 -> 0 | AK25: =AG25+AJ25 -> 108 | AL25: 2 | AM25: 148 | AN25: =AL25*AM25 -> 296 | AQ25: 0 | AR25: =SUM(AD25+AK25+AN25+AO25+AP25+AQ25) -> 3597.5484 | AS25: 0 | AT25: 0 | AU25: 0 | AV25: =AR25-AS25-AT25-AU25 -> 3597.5484 | AW25: =SUM(K25*80%) -> 3600 | AX25: =AV25-AW25 -> -2.4516129 | AY25: =+AV25-AW25-AX25 -> 0
A26: D0020 | B26: KUNHI MAVAL | C26: Moideen | D26: 44845 | F26: 10001067941432 | G26: Light Vehicule Driver | H26: =K26*60% -> 2580 | I26: =K26*20% -> 860 | J26: =K26*20% -> 860 | K26: 4300 | L26: 16 | M26: 1 | N26: 0 | O26: 0 | P26: 0 | Q26: =L26+M26+N26+O26+P26 -> 17 | R26: 0 | S26: 14 | T26: 0 | U26: 0 | V26: =K26/31*R26 -> 0 | W26: =K26/31*S26 -> 1941.9355 | X26: =K26/31*T26 -> 0 | Y26: =K26/31*U26 -> 0 | Z26: =R26+S26+T26+U26 -> 14 | AA26: =Q26+Z26 -> 31 | AB26: =K26/31*O26 -> 0 | AC26: =K26/31*P26 -> 0 | AD26: =SUM(K26/31*Q26) -> 2358.0645 | AE26: 19 | AF26: 12 | AG26: =AE26*AF26 -> 228 | AH26: 0 | AI26: 14 | AJ26: =AH26*AI26 -> 0 | AK26: =AG26+AJ26 -> 228 | AL26: 2 | AM26: 141 | AN26: =AL26*AM26 -> 282 | AQ26: 0 | AR26: =SUM(AD26+AK26+AN26+AO26+AP26+AQ26) -> 2868.0645 | AS26: 0 | AT26: 0 | AU26: 0 | AV26: =AR26-AS26-AT26-AU26 -> 2868.0645 | AW26: =SUM(K26*80%) -> 3440 | AX26: =AV26-AW26 -> -571.93548 | AY26: =+AV26-AW26-AX26 -> 0 | AZ26: FAKE TICKET in 2024
A27: D0021 | B27: SURYA GEETHA KUMAR THULASEEDHARAN | C27: Nandhan | D27: 45276 | F27: 10030109962464 | G27: Light Vehicule Driver | H27: =K27*60% -> 2520 | I27: =K27*20% -> 840 | J27: =K27*20% -> 840 | K27: 4200 | L27: 27 | M27: 4 | N27: 0 | O27: 0 | P27: 0 | Q27: =L27+M27+N27+O27+P27 -> 31 | R27: 0 | S27: 0 | T27: 0 | U27: 0 | V27: =K27/31*R27 -> 0 | W27: =K27/31*S27 -> 0 | X27: =K27/31*T27 -> 0 | Y27: =K27/31*U27 -> 0 | Z27: =R27+S27+T27+U27 -> 0 | AA27: =Q27+Z27 -> 31 | AB27: =K27/31*O27 -> 0 | AC27: =K27/31*P27 -> 0 | AD27: =SUM(K27/31*Q27) -> 4200 | AE27: 20 | AF27: 12 | AG27: =AE27*AF27 -> 240 | AH27: 0 | AI27: 14 | AJ27: =AH27*AI27 -> 0 | AK27: =AG27+AJ27 -> 240 | AL27: 1 | AM27: 138 | AN27: =AL27*AM27 -> 138 | AQ27: 0 | AR27: =SUM(AD27+AK27+AN27+AO27+AP27+AQ27) -> 4578 | AS27: 0 | AT27: 0 | AU27: 0 | AV27: =AR27-AS27-AT27-AU27 -> 4578 | AW27: =SUM(K27*80%) -> 3360 | AX27: =AV27-AW27 -> 1218 | AY27: =+AV27-AW27-AX27 -> 0
A28: D0022 | B28: MOHAMMED KOLLAROTHODIKA | C28: Naseem | D28: 42076 | F28: 10010018229793 | G28: Light Vehicule Driver | H28: =K28*60% -> 2700 | I28: =K28*20% -> 900 | J28: =K28*20% -> 900 | K28: 4500 | L28: 27 | M28: 4 | N28: 0 | O28: 0 | P28: 0 | Q28: =L28+M28+N28+O28+P28 -> 31 | R28: 0 | S28: 0 | T28: 0 | U28: 0 | V28: =K28/31*R28 -> 0 | W28: =K28/31*S28 -> 0 | X28: =K28/31*T28 -> 0 | Y28: =K28/31*U28 -> 0 | Z28: =R28+S28+T28+U28 -> 0 | AA28: =Q28+Z28 -> 31 | AB28: =K28/31*O28 -> 0 | AC28: =K28/31*P28 -> 0 | AD28: =SUM(K28/31*Q28) -> 4500 | AE28: 18 | AF28: 12 | AG28: =AE28*AF28 -> 216 | AH28: 0 | AI28: 15 | AJ28: =AH28*AI28 -> 0 | AK28: =AG28+AJ28 -> 216 | AL28: 1 | AM28: 148 | AN28: =AL28*AM28 -> 148 | AQ28: 0 | AR28: =SUM(AD28+AK28+AN28+AO28+AP28+AQ28) -> 4864 | AS28: 0 | AT28: 0 | AU28: 0 | AV28: =AR28-AS28-AT28-AU28 -> 4864 | AW28: =SUM(K28*80%) -> 3600 | AX28: =AV28-AW28 -> 1264 | AY28: =+AV28-AW28-AX28 -> 0
A29: D0023 | B29: ALLAH DITTA | C29: Nawaz Muhammad | D29: 45232 | F29: 20001016925583 | G29: Light Vehicule Driver | H29: =K29*60% -> 2520 | I29: =K29*20% -> 840 | J29: =K29*20% -> 840 | K29: 4200 | L29: 28 | M29: 3 | N29: 0 | O29: 0 | P29: 0 | Q29: =L29+M29+N29+O29+P29 -> 31 | R29: 0 | S29: 0 | T29: 0 | U29: 0 | V29: =K29/31*R29 -> 0 | W29: =K29/31*S29 -> 0 | X29: =K29/31*T29 -> 0 | Y29: =K29/31*U29 -> 0 | Z29: =R29+S29+T29+U29 -> 0 | AA29: =Q29+Z29 -> 31 | AB29: =K29/31*O29 -> 0 | AC29: =K29/31*P29 -> 0 | AD29: =SUM(K29/31*Q29) -> 4200 | AE29: 9 | AF29: 12 | AG29: =AE29*AF29 -> 108 | AH29: 0 | AI29: 14 | AJ29: =AH29*AI29 -> 0 | AK29: =AG29+AJ29 -> 108 | AL29: 2 | AM29: 138 | AN29: =AL29*AM29 -> 276 | AQ29: 0 | AR29: =SUM(AD29+AK29+AN29+AO29+AP29+AQ29) -> 4584 | AS29: 0 | AT29: 0 | AU29: 0 | AV29: =AR29-AS29-AT29-AU29 -> 4584 | AW29: =SUM(K29*80%) -> 3360 | AX29: =AV29-AW29 -> 1224 | AY29: =+AV29-AW29-AX29 -> 0
A30: D0024 | B30: MAHEEN KIDIR MOHAMMED MAHEEN | C30: Nizam | D30: 43661 | F30: 10013029316206 | G30: Light Vehicule Driver | H30: =K30*60% -> 2700 | I30: =K30*20% -> 900 | J30: =K30*20% -> 900 | K30: 4500 | L30: 28 | M30: 3 | N30: 0 | O30: 0 | P30: 0 | Q30: =L30+M30+N30+O30+P30 -> 31 | R30: 0 | S30: 0 | T30: 0 | U30: 0 | V30: =K30/31*R30 -> 0 | W30: =K30/31*S30 -> 0 | X30: =K30/31*T30 -> 0 | Y30: =K30/31*U30 -> 0 | Z30: =R30+S30+T30+U30 -> 0 | AA30: =Q30+Z30 -> 31 | AB30: =K30/31*O30 -> 0 | AC30: =K30/31*P30 -> 0 | AD30: =SUM(K30/31*Q30) -> 4500 | AE30: 12 | AF30: 12 | AG30: =AE30*AF30 -> 144 | AH30: 0 | AI30: 15 | AJ30: =AH30*AI30 -> 0 | AK30: =AG30+AJ30 -> 144 | AL30: 2 | AM30: 148 | AN30: =AL30*AM30 -> 296 | AQ30: 0 | AR30: =SUM(AD30+AK30+AN30+AO30+AP30+AQ30) -> 4940 | AS30: 0 | AT30: 0 | AU30: 0 | AV30: =AR30-AS30-AT30-AU30 -> 4940 | AW30: =SUM(K30*80%) -> 3600 | AX30: =AV30-AW30 -> 1340 | AY30: =+AV30-AW30-AX30 -> 0
A31: D0025 | B31: VEETIL KRISHNAN KUNNAMMAL | C31: Pranav | D31: 43650 | F31: 10020038912465 | G31: Light Vehicule Driver | H31: =K31*60% -> 2700 | I31: =K31*20% -> 900 | J31: =K31*20% -> 900 | K31: 4500 | L31: 28 | M31: 3 | N31: 0 | O31: 0 | P31: 0 | Q31: =L31+M31+N31+O31+P31 -> 31 | R31: 0 | S31: 0 | T31: 0 | U31: 0 | V31: =K31/31*R31 -> 0 | W31: =K31/31*S31 -> 0 | X31: =K31/31*T31 -> 0 | Y31: =K31/31*U31 -> 0 | Z31: =R31+S31+T31+U31 -> 0 | AA31: =Q31+Z31 -> 31 | AB31: =K31/31*O31 -> 0 | AC31: =K31/31*P31 -> 0 | AD31: =SUM(K31/31*Q31) -> 4500 | AE31: 9 | AF31: 12 | AG31: =AE31*AF31 -> 108 | AH31: 0 | AI31: 15 | AJ31: =AH31*AI31 -> 0 | AK31: =AG31+AJ31 -> 108 | AL31: 2 | AM31: 148 | AN31: =AL31*AM31 -> 296 | AQ31: 0 | AR31: =SUM(AD31+AK31+AN31+AO31+AP31+AQ31) -> 4904 | AS31: 0 | AT31: 0 | AU31: 0 | AV31: =AR31-AS31-AT31-AU31 -> 4904 | AW31: =SUM(K31*80%) -> 3600 | AX31: =AV31-AW31 -> 1304 | AY31: =+AV31-AW31-AX31 -> 0
A32: D0026 | B32: MUHAMMAD USMAN GHULAM | C32: Qadir | D32: 45287 | F32: 20024049662792 | G32: Light Vehicule Driver | H32: =K32*60% -> 2520 | I32: =K32*20% -> 840 | J32: =K32*20% -> 840 | K32: 4200 | L32: 28 | M32: 3 | N32: 0 | O32: 0 | P32: 0 | Q32: =L32+M32+N32+O32+P32 -> 31 | R32: 0 | S32: 0 | T32: 0 | U32: 0 | V32: =K32/31*R32 -> 0 | W32: =K32/31*S32 -> 0 | X32: =K32/31*T32 -> 0 | Y32: =K32/31*U32 -> 0 | Z32: =R32+S32+T32+U32 -> 0 | AA32: =Q32+Z32 -> 31 | AB32: =K32/31*O32 -> 0 | AC32: =K32/31*P32 -> 0 | AD32: =SUM(K32/31*Q32) -> 4200 | AE32: 5 | AF32: 12 | AG32: =AE32*AF32 -> 60 | AH32: 0 | AI32: 14 | AJ32: =AH32*AI32 -> 0 | AK32: =AG32+AJ32 -> 60 | AL32: 2 | AM32: 138 | AN32: =AL32*AM32 -> 276 | AQ32: 0 | AR32: =SUM(AD32+AK32+AN32+AO32+AP32+AQ32) -> 4536 | AS32: 0 | AT32: 0 | AU32: 0 | AV32: =AR32-AS32-AT32-AU32 -> 4536 | AW32: =SUM(K32*80%) -> 3360 | AX32: =AV32-AW32 -> 1176 | AY32: =+AV32-AW32-AX32 -> 0
A33: D0027 | B33: KOZHIPPURATH ABOOBACKER | C33: Rasheed | D33: 43570 | F33: 10021057922829 | G33: Light Vehicule Driver | H33: =K33*60% -> 2700 | I33: =K33*20% -> 900 | J33: =K33*20% -> 900 | K33: 4500 | L33: 28 | M33: 3 | N33: 0 | O33: 0 | P33: 0 | Q33: =L33+M33+N33+O33+P33 -> 31 | R33: 0 | S33: 0 | T33: 0 | U33: 0 | V33: =K33/31*R33 -> 0 | W33: =K33/31*S33 -> 0 | X33: =K33/31*T33 -> 0 | Y33: =K33/31*U33 -> 0 | Z33: =R33+S33+T33+U33 -> 0 | AA33: =Q33+Z33 -> 31 | AB33: =K33/31*O33 -> 0 | AC33: =K33/31*P33 -> 0 | AD33: =SUM(K33/31*Q33) -> 4500 | AE33: 50 | AF33: 12 | AG33: =AE33*AF33 -> 600 | AH33: 0 | AI33: 15 | AJ33: =AH33*AI33 -> 0 | AK33: =AG33+AJ33 -> 600 | AL33: 2 | AM33: 148 | AN33: =AL33*AM33 -> 296 | AQ33: 0 | AR33: =SUM(AD33+AK33+AN33+AO33+AP33+AQ33) -> 5396 | AS33: 0 | AT33: 0 | AU33: 0 | AV33: =AR33-AS33-AT33-AU33 -> 5396 | AW33: =SUM(K33*80%) -> 3600 | AX33: =AV33-AW33 -> 1796 | AY33: =+AV33-AW33-AX33 -> 0 | AZ33: FAKE TICKET in 2024
A34: D0028 | B34: ACHARYA | C34: Rajan | D34: 44830 | F34: 31601127390678 | G34: Light Vehicule Driver | H34: =K34*60% -> 2580 | I34: =K34*20% -> 860 | J34: =K34*20% -> 860 | K34: 4300 | L34: 27 | M34: 4 | N34: 0 | O34: 0 | P34: 0 | Q34: =L34+M34+N34+O34+P34 -> 31 | R34: 0 | S34: 0 | T34: 0 | U34: 0 | V34: =K34/31*R34 -> 0 | W34: =K34/31*S34 -> 0 | X34: =K34/31*T34 -> 0 | Y34: =K34/31*U34 -> 0 | Z34: =R34+S34+T34+U34 -> 0 | AA34: =Q34+Z34 -> 31 | AB34: =K34/31*O34 -> 0 | AC34: =K34/31*P34 -> 0 | AD34: =SUM(K34/31*Q34) -> 4300 | AE34: 10 | AF34: 12 | AG34: =AE34*AF34 -> 120 | AH34: 0 | AI34: 14 | AJ34: =AH34*AI34 -> 0 | AK34: =AG34+AJ34 -> 120 | AL34: 1 | AM34: 141 | AN34: =AL34*AM34 -> 141 | AQ34: 0 | AR34: =SUM(AD34+AK34+AN34+AO34+AP34+AQ34) -> 4561 | AS34: 0 | AT34: 0 | AU34: 0 | AV34: =AR34-AS34-AT34-AU34 -> 4561 | AW34: =SUM(K34*80%) -> 3440 | AX34: =AV34-AW34 -> 1121 | AY34: =+AV34-AW34-AX34 -> 0
A35: D0029 | B35: ALIPETTA UMMER | C35: Riyas | D35: 44796 | F35: 10025088010140 | G35: Light Vehicule Driver | H35: =K35*60% -> 2580 | I35: =K35*20% -> 860 | J35: =K35*20% -> 860 | K35: 4300 | L35: 28 | M35: 3 | N35: 0 | O35: 0 | P35: 0 | Q35: =L35+M35+N35+O35+P35 -> 31 | R35: 0 | S35: 0 | T35: 0 | U35: 0 | V35: =K35/31*R35 -> 0 | W35: =K35/31*S35 -> 0 | X35: =K35/31*T35 -> 0 | Y35: =K35/31*U35 -> 0 | Z35: =R35+S35+T35+U35 -> 0 | AA35: =Q35+Z35 -> 31 | AB35: =K35/31*O35 -> 0 | AC35: =K35/31*P35 -> 0 | AD35: =SUM(K35/31*Q35) -> 4300 | AE35: 23 | AF35: 12 | AG35: =AE35*AF35 -> 276 | AH35: 0 | AI35: 14 | AJ35: =AH35*AI35 -> 0 | AK35: =AG35+AJ35 -> 276 | AL35: 2 | AM35: 141 | AN35: =AL35*AM35 -> 282 | AQ35: 0 | AR35: =SUM(AD35+AK35+AN35+AO35+AP35+AQ35) -> 4858 | AS35: 0 | AT35: 0 | AU35: 0 | AV35: =AR35-AS35-AT35-AU35 -> 4858 | AW35: =SUM(K35*80%) -> 3440 | AX35: =AV35-AW35 -> 1418 | AY35: =+AV35-AW35-AX35 -> 0 | AZ35: FAKE TICKET in 2024
A36: D0030 | B36: GIRIJA MOHANDAS SREEDHARAN PANICKER | C36: Riju | D36: 45344 | F36: 10004078884984 | G36: Light Vehicule Driver | H36: =K36*60% -> 2520 | I36: =K36*20% -> 840 | J36: =K36*20% -> 840 | K36: 4200 | L36: 25 | M36: 4 | N36: 0 | O36: 0 | P36: 2 | Q36: =L36+M36+N36+O36+P36 -> 31 | R36: 0 | S36: 0 | T36: 0 | U36: 0 | V36: =K36/31*R36 -> 0 | W36: =K36/31*S36 -> 0 | X36: =K36/31*T36 -> 0 | Y36: =K36/31*U36 -> 0 | Z36: =R36+S36+T36+U36 -> 0 | AA36: =Q36+Z36 -> 31 | AB36: =K36/31*O36 -> 0 | AC36: =K36/31*P36 -> 270.96774 | AD36: =SUM(K36/31*Q36) -> 4200 | AE36: 31 | AF36: 12 | AG36: =AE36*AF36 -> 372 | AH36: 0 | AI36: 14 | AJ36: =AH36*AI36 -> 0 | AK36: =AG36+AJ36 -> 372 | AL36: 1 | AM36: 138 | AN36: =AL36*AM36 -> 138 | AQ36: 0 | AR36: =SUM(AD36+AK36+AN36+AO36+AP36+AQ36) -> 4710 | AS36: 0 | AT36: 0 | AU36: 0 | AV36: =AR36-AS36-AT36-AU36 -> 4710 | AW36: =SUM(K36*80%) -> 3360 | AX36: =AV36-AW36 -> 1350 | AY36: =+AV36-AW36-AX36 -> 0
A37: D0031 | B37: VANNATHAN POIYEL MOOSSA | C37: Sackeer | D37: 45293 | F37: 10021047655633 | G37: Light Vehicule Driver | H37: =K37*60% -> 2520 | I37: =K37*20% -> 840 | J37: =K37*20% -> 840 | K37: 4200 | L37: 27 | M37: 4 | N37: 0 | O37: 0 | P37: 0 | Q37: =L37+M37+N37+O37+P37 -> 31 | R37: 0 | S37: 0 | T37: 0 | U37: 0 | V37: =K37/31*R37 -> 0 | W37: =K37/31*S37 -> 0 | X37: =K37/31*T37 -> 0 | Y37: =K37/31*U37 -> 0 | Z37: =R37+S37+T37+U37 -> 0 | AA37: =Q37+Z37 -> 31 | AB37: =K37/31*O37 -> 0 | AC37: =K37/31*P37 -> 0 | AD37: =SUM(K37/31*Q37) -> 4200 | AE37: 19 | AF37: 12 | AG37: =AE37*AF37 -> 228 | AH37: 0 | AI37: 14 | AJ37: =AH37*AI37 -> 0 | AK37: =AG37+AJ37 -> 228 | AL37: 1 | AM37: 138 | AN37: =AL37*AM37 -> 138 | AQ37: 0 | AR37: =SUM(AD37+AK37+AN37+AO37+AP37+AQ37) -> 4566 | AS37: 0 | AT37: 0 | AU37: 0 | AV37: =AR37-AS37-AT37-AU37 -> 4566 | AW37: =SUM(K37*80%) -> 3360 | AX37: =AV37-AW37 -> 1206 | AY37: =+AV37-AW37-AX37 -> 0
A38: D0032 | B38: SHAMIL ARIYOLOKOYA ARIYOLI | C38: Muhammed | D38: 44802 | F38: 10012108936044 | G38: Light Vehicule Driver | H38: =K38*60% -> 2580 | I38: =K38*20% -> 860 | J38: =K38*20% -> 860 | K38: 4300 | L38: 28 | M38: 3 | N38: 0 | O38: 0 | P38: 0 | Q38: =L38+M38+N38+O38+P38 -> 31 | R38: 0 | S38: 0 | T38: 0 | U38: 0 | V38: =K38/31*R38 -> 0 | W38: =K38/31*S38 -> 0 | X38: =K38/31*T38 -> 0 | Y38: =K38/31*U38 -> 0 | Z38: =R38+S38+T38+U38 -> 0 | AA38: =Q38+Z38 -> 31 | AB38: =K38/31*O38 -> 0 | AC38: =K38/31*P38 -> 0 | AD38: =SUM(K38/31*Q38) -> 4300 | AE38: 5 | AF38: 12 | AG38: =AE38*AF38 -> 60 | AH38: 0 | AI38: 14 | AJ38: =AH38*AI38 -> 0 | AK38: =AG38+AJ38 -> 60 | AL38: 2 | AM38: 141 | AN38: =AL38*AM38 -> 282 | AQ38: 0 | AR38: =SUM(AD38+AK38+AN38+AO38+AP38+AQ38) -> 4642 | AS38: 0 | AT38: 590 | AU38: 0 | AV38: =AR38-AS38-AT38-AU38 -> 4052 | AW38: =SUM(K38*80%) -> 3440 | AX38: =AV38-AW38 -> 612 | AY38: =+AV38-AW38-AX38 -> 0 | AZ38: FAKE TICKET in 2024
A39: D0033 | B39: MUHAMMAD BILAL MEHMOOD | C39: Shah | D39: 45287 | F39: 20012108325991 | G39: Light Vehicule Driver | H39: =K39*60% -> 2520 | I39: =K39*20% -> 840 | J39: =K39*20% -> 840 | K39: 4200 | L39: 25 | M39: 3 | N39: 0 | O39: 0 | P39: 3 | Q39: =L39+M39+N39+O39+P39 -> 31 | R39: 0 | S39: 0 | T39: 0 | U39: 0 | V39: =K39/31*R39 -> 0 | W39: =K39/31*S39 -> 0 | X39: =K39/31*T39 -> 0 | Y39: =K39/31*U39 -> 0 | Z39: =R39+S39+T39+U39 -> 0 | AA39: =Q39+Z39 -> 31 | AB39: =K39/31*O39 -> 0 | AC39: =K39/31*P39 -> 406.45161 | AD39: =SUM(K39/31*Q39) -> 4200 | AE39: 5 | AF39: 12 | AG39: =AE39*AF39 -> 60 | AH39: 0 | AI39: 14 | AJ39: =AH39*AI39 -> 0 | AK39: =AG39+AJ39 -> 60 | AL39: 2 | AM39: 138 | AN39: =AL39*AM39 -> 276 | AQ39: 0 | AR39: =SUM(AD39+AK39+AN39+AO39+AP39+AQ39) -> 4536 | AS39: 0 | AT39: 0 | AU39: 0 | AV39: =AR39-AS39-AT39-AU39 -> 4536 | AW39: =SUM(K39*80%) -> 3360 | AX39: =AV39-AW39 -> 1176 | AY39: =+AV39-AW39-AX39 -> 0
A40: D0034 | B40: ISMAIL KHAN | C40: Shahzad | D40: 45287 | F40: 20021067796071 | G40: Light Vehicule Driver | H40: =K40*60% -> 2520 | I40: =K40*20% -> 840 | J40: =K40*20% -> 840 | K40: 4200 | L40: 26 | M40: 3 | N40: 0 | O40: 0 | P40: 2 | Q40: =L40+M40+N40+O40+P40 -> 31 | R40: 0 | S40: 0 | T40: 0 | U40: 0 | V40: =K40/31*R40 -> 0 | W40: =K40/31*S40 -> 0 | X40: =K40/31*T40 -> 0 | Y40: =K40/31*U40 -> 0 | Z40: =R40+S40+T40+U40 -> 0 | AA40: =Q40+Z40 -> 31 | AB40: =K40/31*O40 -> 0 | AC40: =K40/31*P40 -> 270.96774 | AD40: =SUM(K40/31*Q40) -> 4200 | AE40: 3 | AF40: 12 | AG40: =AE40*AF40 -> 36 | AH40: 0 | AI40: 14 | AJ40: =AH40*AI40 -> 0 | AK40: =AG40+AJ40 -> 36 | AL40: 2 | AM40: 138 | AN40: =AL40*AM40 -> 276 | AQ40: 0 | AR40: =SUM(AD40+AK40+AN40+AO40+AP40+AQ40) -> 4512 | AS40: 0 | AT40: 0 | AU40: 0 | AV40: =AR40-AS40-AT40-AU40 -> 4512 | AW40: =SUM(K40*80%) -> 3360 | AX40: =AV40-AW40 -> 1152 | AY40: =+AV40-AW40-AX40 -> 0
A41: D0035 | B41: KANDIRUTHY ACHUTHAN KANDIRUTHY KARAPAN | C41: Shiju | D41: 44525 | F41: 10020037771919 | G41: Light Vehicule Driver | H41: =K41*60% -> 2640 | I41: =K41*20% -> 880 | J41: =K41*20% -> 880 | K41: 4400 | L41: 28 | M41: 3 | N41: 0 | O41: 0 | P41: 0 | Q41: =L41+M41+N41+O41+P41 -> 31 | R41: 0 | S41: 0 | T41: 0 | U41: 0 | V41: =K41/31*R41 -> 0 | W41: =K41/31*S41 -> 0 | X41: =K41/31*T41 -> 0 | Y41: =K41/31*U41 -> 0 | Z41: =R41+S41+T41+U41 -> 0 | AA41: =Q41+Z41 -> 31 | AB41: =K41/31*O41 -> 0 | AC41: =K41/31*P41 -> 0 | AD41: =SUM(K41/31*Q41) -> 4400 | AE41: 11 | AF41: 12 | AG41: =AE41*AF41 -> 132 | AH41: 0 | AI41: 14 | AJ41: =AH41*AI41 -> 0 | AK41: =AG41+AJ41 -> 132 | AL41: 2 | AM41: 145 | AN41: =AL41*AM41 -> 290 | AQ41: 0 | AR41: =SUM(AD41+AK41+AN41+AO41+AP41+AQ41) -> 4822 | AS41: 0 | AT41: 0 | AU41: 0 | AV41: =AR41-AS41-AT41-AU41 -> 4822 | AW41: =SUM(K41*80%) -> 3520 | AX41: =AV41-AW41 -> 1302 | AY41: =+AV41-AW41-AX41 -> 0 | AZ41: FAKE TICKET in 2024
A42: D0036 | B42: SIRAJUDHEEN THOTTIKULATHIL | C42: Muhammed | D42: 44460 | F42: 10016058960893 | G42: Light Vehicule Driver | H42: =K42*60% -> 2640 | I42: =K42*20% -> 880 | J42: =K42*20% -> 880 | K42: 4400 | L42: 27 | M42: 4 | N42: 0 | O42: 0 | P42: 0 | Q42: =L42+M42+N42+O42+P42 -> 31 | R42: 0 | S42: 0 | T42: 0 | U42: 0 | V42: =K42/31*R42 -> 0 | W42: =K42/31*S42 -> 0 | X42: =K42/31*T42 -> 0 | Y42: =K42/31*U42 -> 0 | Z42: =R42+S42+T42+U42 -> 0 | AA42: =Q42+Z42 -> 31 | AB42: =K42/31*O42 -> 0 | AC42: =K42/31*P42 -> 0 | AD42: =SUM(K42/31*Q42) -> 4400 | AE42: 6 | AF42: 12 | AG42: =AE42*AF42 -> 72 | AH42: 0 | AI42: 14 | AJ42: =AH42*AI42 -> 0 | AK42: =AG42+AJ42 -> 72 | AL42: 0 | AM42: 145 | AN42: =AL42*AM42 -> 0 | AQ42: 0 | AR42: =SUM(AD42+AK42+AN42+AO42+AP42+AQ42) -> 4472 | AS42: 0 | AT42: 200 | AU42: 0 | AV42: =AR42-AS42-AT42-AU42 -> 4272 | AW42: =SUM(K42*80%) -> 3520 | AX42: =AV42-AW42 -> 752 | AY42: =+AV42-AW42-AX42 -> 0
...

Sheet 1
A1: CHABE LUXURY TRANSPORT LLC
A2: 11B Street Warehouse 3b/27
A3: AL KHABAISI
A4: Dubai, UAE
A5: ='Infos Mensuelles'!A1 -> Salary slip January 2026
A8: Employee last name: | D8: ='Infos Mensuelles'!B7 -> MANNAPPAN THARAMMAL | H8: Employee ID: | J8: ='Infos Mensuelles'!F7 -> 10028058458199
H9: Arrival date: | J9: ='Infos Mensuelles'!D7 -> 23.08.2022
A11: Employee first name | D11: ='Infos Mensuelles'!C7 -> Abdulla | H11: Employee Position: | J11: ='Infos Mensuelles'!G7 -> Light Vehicule Driver
A15: Employee Attendance
A16: Working days : | D16: ='Infos Mensuelles'!L7 -> 28 | E16: Emergency not payable: | H16: ='Infos Mensuelles'!S7 -> 0 | I16: OT Hours Basic : | L16: ='Infos Mensuelles'!AE7 -> 5
A17: Working Public Holidays : | D17: ='Infos Mensuelles'!N7 -> 0 | E17: Sick Leave not Payable: | H17: ='Infos Mensuelles'!T7 -> 0 | I17: OT Hours Public holidays : | L17: ='Infos Mensuelles'!AH7 -> 0
A18: Off days : | D18: ='Infos Mensuelles'!M7 -> 3 | E18: Absence day not payable: | H18: ='Infos Mensuelles'!U7 -> 0 | I18: OT Days : | L18: ='Infos Mensuelles'!AL7 -> 2
A19: Sick Leave Payable : | D19: ='Infos Mensuelles'!P7 -> 0 | E19: Unpaid Leaves: | H19: ='Infos Mensuelles'!R7 -> 0 | I19: Leave Payable : | L19: ='Infos Mensuelles'!O7 -> 0
A20: Total of payable days : | D20: ='Infos Mensuelles'!Q7 -> 31
A23: Earnings & Deductions
A24: Salary Head | G24: Amount Earnings (AED) | J24: Amount Deductions (AED)
A26: Earnings
A27: Basic Salary | G27: ='Infos Mensuelles'!H7 -> 2580
A28: Housing Allowances | G28: ='Infos Mensuelles'!I7 -> 860
A29: Transport Allowances | G29: ='Infos Mensuelles'!J7 -> 860
A30: OT Hours Basic | G30: ='Infos Mensuelles'!AG7 -> 60
A31: OT Hours Public holidays | G31: ='Infos Mensuelles'!AJ7 -> 0
A32: OT Days | G32: ='Infos Mensuelles'!AN7 -> 282
A33: Air Plane Ticket Refundable | G33: ='Infos Mensuelles'!AQ7 -> 0
A34: Other Allowance | G34: ='Infos Mensuelles'!AO7 -> 0
A35: Adjustment form previous month | G35: ='Infos Mensuelles'!AP7 -> 0
A36: Deductions
A37: Advance salary | J37: ='Infos Mensuelles'!AS7 -> 0
A38: Your Fines paid by the company | J38: ='Infos Mensuelles'!AT7 -> 0
A39: Absence | J39: ='Infos Mensuelles'!Y7 -> 0
A40: Unpaid leaves | J40: ='Infos Mensuelles'!V7 -> 0
A41: Sick leave unpaid | J41: ='Infos Mensuelles'!X7 -> 0
A42: Adjustment form previous month | J42: ='Infos Mensuelles'!AU7 -> 0
A43: Emergency leave Unpaid | J43: ='Infos Mensuelles'!W7 -> 0
A45: TOTAL EARNINGS & DEDUCTIONS | G45: =SUM(G26:I44) -> 4642 | J45: =SUM(J26:L44) -> 0
A48: TOTAL AMOUNT : | G48: =G45-J45 -> 4642
A52: Payment informations:
A53: Date of payment: | D53: ='Infos Mensuelles'!E1 -> 46053
A54: Methode of payment: | D54: WPS
A55: If you need any informations please contact us at hr-dubai@chabe.com

Sheet 2
A1: CHABE LUXURY TRANSPORT LLC
A2: 11B Street Warehouse 3b/27
A3: AL KHABAISI
A4: Dubai, UAE
A5: ='Infos Mensuelles'!A1 -> Salary slip January 2026
A8: Employee last name: | D8: ='Infos Mensuelles'!B8 -> SYED NABI AHMAD | H8: Employee ID: | J8: ='Infos Mensuelles'!F8 -> 10005027939914
H9: Arrival date: | J9: ='Infos Mensuelles'!D8 -> 44414
A11: Employee first name | D11: ='Infos Mensuelles'!C8 -> Irfran Ahmed | H11: Employee Position: | J11: ='Infos Mensuelles'!G8 -> Light Vehicule Driver
A15: Employee Attendance
A16: Working days : | D16: ='Infos Mensuelles'!L8 -> 29 | E16: Emergency not payable: | H16: ='Infos Mensuelles'!S8 -> 0 | I16: OT Hours Basic : | L16: ='Infos Mensuelles'!AE8 -> 6
A17: Working Public Holidays : | D17: ='Infos Mensuelles'!N8 -> 0 | E17: Sick Leave not Payable: | H17: ='Infos Mensuelles'!T8 -> 0 | I17: OT Hours Public holidays : | L17: ='Infos Mensuelles'!AH8 -> 0
A18: Off days : | D18: ='Infos Mensuelles'!M8 -> 2 | E18: Absence day not payable: | H18: ='Infos Mensuelles'!U8 -> 0 | I18: OT Days : | L18: ='Infos Mensuelles'!AL8 -> 3
A19: Sick Leave Payable : | D19: ='Infos Mensuelles'!P8 -> 0 | E19: Unpaid Leaves: | H19: ='Infos Mensuelles'!R8 -> 0 | I19: Leave Payable : | L19: ='Infos Mensuelles'!O8 -> 0
A20: Total of payable days : | D20: ='Infos Mensuelles'!Q8 -> 31
A23: Earnings & Deductions
A24: Salary Head | G24: Amount Earnings (AED) | J24: Amount Deductions (AED)
A26: Earnings
A27: Basic Salary | G27: ='Infos Mensuelles'!H8 -> 2640
A28: Housing Allowances | G28: ='Infos Mensuelles'!I8 -> 880
A29: Transport Allowances | G29: ='Infos Mensuelles'!J8 -> 880
A30: OT Hours Basic | G30: ='Infos Mensuelles'!AG8 -> 72
A31: OT Hours Public holidays | G31: ='Infos Mensuelles'!AJ8 -> 0
A32: OT Days | G32: ='Infos Mensuelles'!AN8 -> 435
A33: Air Plane Ticket Refundable | G33: ='Infos Mensuelles'!AQ8 -> 0
A34: Other Allowance | G34: ='Infos Mensuelles'!AO8 -> 0
A35: Adjustment form previous month | G35: ='Infos Mensuelles'!AP8 -> 0
A36: Deductions
A37: Advance salary | J37: ='Infos Mensuelles'!AS8 -> 0
A38: Your Fines paid by the company | J38: ='Infos Mensuelles'!AT8 -> 520
A39: Absence | J39: ='Infos Mensuelles'!Y8 -> 0
A40: Unpaid leaves | J40: ='Infos Mensuelles'!V8 -> 0
A41: Sick leave unpaid | J41: ='Infos Mensuelles'!X8 -> 0
A42: Adjustment form previous month | J42: ='Infos Mensuelles'!AU8 -> 0
A43: Emergency leave Unpaid | J43: ='Infos Mensuelles'!W8 -> 0
A45: TOTAL EARNINGS & DEDUCTIONS | G45: =SUM(G26:I44) -> 4907 | J45: =SUM(J26:L44) -> 520
A48: TOTAL AMOUNT : | G48: =G45-J45 -> 4387
A52: Payment informations:
A53: Date of payment: | D53: ='Infos Mensuelles'!E1 -> 46053
A54: Methode of payment: | D54: WPS
A55: If you need any informations please contact us at hr-dubai@chabe.com

Sheet 3
A1: CHABE LUXURY TRANSPORT LLC
A2: 11B Street Warehouse 3b/27
A3: AL KHABAISI
A4: Dubai, UAE
A5: ='Infos Mensuelles'!A1 -> Salary slip January 2026
A8: Employee last name: | D8: ='Infos Mensuelles'!B9 -> SHAMSUDEEN | H8: Employee ID: | J8: ='Infos Mensuelles'!F9 -> 10013067459387
H9: Arrival date: | J9: ='Infos Mensuelles'!D9 -> 19.09.2021
A11: Employee first name | D11: ='Infos Mensuelles'!C9 -> Amanullah | H11: Employee Position: | J11: ='Infos Mensuelles'!G9 -> Light Vehicule Driver
A15: Employee Attendance
A16: Working days : | D16: ='Infos Mensuelles'!L9 -> 28 | E16: Emergency not payable: | H16: ='Infos Mensuelles'!S9 -> 0 | I16: OT Hours Basic : | L16: ='Infos Mensuelles'!AE9 -> 6
A17: Working Public Holidays : | D17: ='Infos Mensuelles'!N9 -> 0 | E17: Sick Leave not Payable: | H17: ='Infos Mensuelles'!T9 -> 0 | I17: OT Hours Public holidays : | L17: ='Infos Mensuelles'!AH9 -> 1
A18: Off days : | D18: ='Infos Mensuelles'!M9 -> 3 | E18: Absence day not payable: | H18: ='Infos Mensuelles'!U9 -> 0 | I18: OT Days : | L18: ='Infos Mensuelles'!AL9 -> 2
A19: Sick Leave Payable : | D19: ='Infos Mensuelles'!P9 -> 0 | E19: Unpaid Leaves: | H19: ='Infos Mensuelles'!R9 -> 0 | I19: Leave Payable : | L19: ='Infos Mensuelles'!O9 -> 0
A20: Total of payable days : | D20: ='Infos Mensuelles'!Q9 -> 31
A23: Earnings & Deductions
A24: Salary Head | G24: Amount Earnings (AED) | J24: Amount Deductions (AED)
A26: Earnings
A27: Basic Salary | G27: ='Infos Mensuelles'!H9 -> 2640
A28: Housing Allowances | G28: ='Infos Mensuelles'!I9 -> 880
A29: Transport Allowances | G29: ='Infos Mensuelles'!J9 -> 880
A30: OT Hours Basic | G30: ='Infos Mensuelles'!AG9 -> 72
A31: OT Hours Public holidays | G31: ='Infos Mensuelles'!AJ9 -> 14
A32: OT Days | G32: ='Infos Mensuelles'!AN9 -> 290
A33: Air Plane Ticket Refundable | G33: ='Infos Mensuelles'!AQ9 -> 0
A34: Other Allowance | G34: ='Infos Mensuelles'!AO9 -> 0
A35: Adjustment form previous month | G35: ='Infos Mensuelles'!AP9 -> 0
A36: Deductions
A37: Advance salary | J37: ='Infos Mensuelles'!AS9 -> 0
A38: Your Fines paid by the company | J38: ='Infos Mensuelles'!AT9 -> 300
A39: Absence | J39: ='Infos Mensuelles'!Y9 -> 0
A40: Unpaid leaves | J40: ='Infos Mensuelles'!V9 -> 0
A41: Sick leave unpaid | J41: ='Infos Mensuelles'!X9 -> 0
A42: Adjustment form previous month | J42: ='Infos Mensuelles'!AU9 -> 0
A43: Emergency leave Unpaid | J43: ='Infos Mensuelles'!W9 -> 0
A45: TOTAL EARNINGS & DEDUCTIONS | G45: =SUM(G26:I44) -> 4776 | J45: =SUM(J26:L44) -> 300
A48: TOTAL AMOUNT : | G48: =G45-J45 -> 4476
A52: Payment informations:
A53: Date of payment: | D53: ='Infos Mensuelles'!E1 -> 46053
A54: Methode of payment: | D54: WPS
A55: If you need any informations please contact us at hr-dubai@chabe.com

Sheet 4
A1: CHABE LUXURY TRANSPORT LLC
A2: 11B Street Warehouse 3b/27
A3: AL KHABAISI
A4: Dubai, UAE
A5: ='Infos Mensuelles'!A1 -> Salary slip January 2026
A8: Employee last name: | D8: ='Infos Mensuelles'!B10 -> BOGATTI | H8: Employee ID: | J8: ='Infos Mensuelles'!F10 -> 31620017062269
H9: Arrival date: | J9: ='Infos Mensuelles'!D10 -> 42470
A11: Employee first name | D11: ='Infos Mensuelles'!C10 -> Anam | H11: Employee Position: | J11: ='Infos Mensuelles'!G10 -> Light Vehicule Driver
A15: Employee Attendance
A16: Working days : | D16: ='Infos Mensuelles'!L10 -> 27 | E16: Emergency not payable: | H16: ='Infos Mensuelles'!S10 -> 0 | I16: OT Hours Basic : | L16: ='Infos Mensuelles'!AE10 -> 7
A17: Working Public Holidays : | D17: ='Infos Mensuelles'!N10 -> 0 | E17: Sick Leave not Payable: | H17: ='Infos Mensuelles'!T10 -> 0 | I17: OT Hours Public holidays : | L17: ='Infos Mensuelles'!AH10 -> 0
A18: Off days : | D18: ='Infos Mensuelles'!M10 -> 4 | E18: Absence day not payable: | H18: ='Infos Mensuelles'!U10 -> 0 | I18: OT Days : | L18: ='Infos Mensuelles'!AL10 -> 1
A19: Sick Leave Payable : | D19: ='Infos Mensuelles'!P10 -> 0 | E19: Unpaid Leaves: | H19: ='Infos Mensuelles'!R10 -> 0 | I19: Leave Payable : | L19: ='Infos Mensuelles'!O10 -> 0
A20: Total of payable days : | D20: ='Infos Mensuelles'!Q10 -> 31
A23: Earnings & Deductions
A24: Salary Head | G24: Amount Earnings (AED) | J24: Amount Deductions (AED)
A26: Earnings
A27: Basic Salary | G27: ='Infos Mensuelles'!H10 -> 2700
A28: Housing Allowances | G28: ='Infos Mensuelles'!I10 -> 900
A29: Transport Allowances | G29: ='Infos Mensuelles'!J10 -> 900
A30: OT Hours Basic | G30: ='Infos Mensuelles'!AG10 -> 84
A31: OT Hours Public holidays | G31: ='Infos Mensuelles'!AJ10 -> 0
A32: OT Days | G32: ='Infos Mensuelles'!AN10 -> 148
A33: Air Plane Ticket Refundable | G33: ='Infos Mensuelles'!AQ10 -> 0
A34: Other Allowance | G34: ='Infos Mensuelles'!AO10 -> 0
A35: Adjustment form previous month | G35: ='Infos Mensuelles'!AP10 -> 0
A36: Deductions
A37: Advance salary | J37: ='Infos Mensuelles'!AS10 -> 0
A38: Your Fines paid by the company | J38: ='Infos Mensuelles'!AT10 -> 0
A39: Absence | J39: ='Infos Mensuelles'!Y10 -> 0
A40: Unpaid leaves | J40: ='Infos Mensuelles'!V10 -> 0
A41: Sick leave unpaid | J41: ='Infos Mensuelles'!X10 -> 0
A42: Adjustment form previous month | J42: ='Infos Mensuelles'!AU10 -> 0
A43: Emergency leave Unpaid | J43: ='Infos Mensuelles'!W10 -> 0
A45: TOTAL EARNINGS & DEDUCTIONS | G45: =SUM(G27:I36) -> 4732 | J45: =SUM(J42:L43) -> 0
A48: TOTAL AMOUNT : | G48: =G45-J45 -> 4732
A52: Payment informations:
A53: Date of payment: | D53: ='Infos Mensuelles'!E1 -> 46053
A54: Methode of payment: | D54: WPS
A55: If you need any informations please contact us at hr-dubai@chabe.com

Sheet 5
A1: CHABE LUXURY TRANSPORT LLC
A2: 11B Street Warehouse 3b/27
A3: AL KHABAISI
A4: Dubai, UAE
A5: ='Infos Mensuelles'!A1 -> Salary slip January 2026
A8: Employee last name: | D8: ='Infos Mensuelles'!B11 -> SUNKADAKATTE ABDULKHADER | H8: Employee ID: | J8: ='Infos Mensuelles'!F11 -> 10019057895758
H9: Arrival date: | J9: ='Infos Mensuelles'!D11 -> 42898
A11: Employee first name | D11: ='Infos Mensuelles'!C11 -> Mohamed Aneefa | H11: Employee Position: | J11: ='Infos Mensuelles'!G11 -> Light Vehicule Driver
A15: Employee Attendance
A16: Working days : | D16: ='Infos Mensuelles'!L11 -> 28 | E16: Emergency not payable: | H16: ='Infos Mensuelles'!S11 -> 0 | I16: OT Hours Basic : | L16: ='Infos Mensuelles'!AE11 -> 2
A17: Working Public Holidays : | D17: ='Infos Mensuelles'!N11 -> 0 | E17: Sick Leave not Payable: | H17: ='Infos Mensuelles'!T11 -> 0 | I17: OT Hours Public holidays : | L17: ='Infos Mensuelles'!AH11 -> 0
A18: Off days : | D18: ='Infos Mensuelles'!M11 -> 3 | E18: Absence day not payable: | H18: ='Infos Mensuelles'!U11 -> 0 | I18: OT Days : | L18: ='Infos Mensuelles'!AL11 -> 2
A19: Sick Leave Payable : | D19: ='Infos Mensuelles'!P11 -> 0 | E19: Unpaid Leaves: | H19: ='Infos Mensuelles'!R11 -> 0 | I19: Leave Payable : | L19: ='Infos Mensuelles'!O11 -> 0
A20: Total of payable days : | D20: ='Infos Mensuelles'!Q11 -> 31
A23: Earnings & Deductions
A24: Salary Head | G24: Amount Earnings (AED) | J24: Amount Deductions (AED)
A26: Earnings
A27: Basic Salary | G27: ='Infos Mensuelles'!H11 -> 2700
A28: Housing Allowances | G28: ='Infos Mensuelles'!I11 -> 900
A29: Transport Allowances | G29: ='Infos Mensuelles'!J11 -> 900
A30: OT Hours Basic | G30: ='Infos Mensuelles'!AG11 -> 24
A31: OT Hours Public holidays | G31: ='Infos Mensuelles'!AJ11 -> 0
A32: OT Days | G32: ='Infos Mensuelles'!AN11 -> 296
A33: Air Plane Ticket Refundable | G33: ='Infos Mensuelles'!AQ11 -> 0
A34: Other Allowance | G34: ='Infos Mensuelles'!AO11 -> 0
A35: Adjustment form previous month | G35: ='Infos Mensuelles'!AP11 -> 0
A36: Deductions
A37: Advance salary | J37: ='Infos Mensuelles'!AS11 -> 0
A38: Your Fines paid by the company | J38: ='Infos Mensuelles'!AT11 -> 0
A39: Absence | J39: ='Infos Mensuelles'!Y11 -> 0
A40: Unpaid leaves | J40: ='Infos Mensuelles'!V11 -> 0
A41: Sick leave unpaid | J41: ='Infos Mensuelles'!X11 -> 0
A42: Adjustment form previous month | J42: ='Infos Mensuelles'!AU11 -> 0
A43: Emergency leave Unpaid | J43: ='Infos Mensuelles'!W11 -> 0
A45: TOTAL EARNINGS & DEDUCTIONS | G45: =SUM(G27:I36) -> 4820 | J45: =SUM(J42:L43) -> 0
A48: TOTAL AMOUNT : | G48: =G45-J45 -> 4820
A52: Payment informations:
A53: Date of payment: | D53: ='Infos Mensuelles'!E1 -> 46053
A54: Methode of payment: | D54: WPS
A55: If you need any informations please contact us at hr-dubai@chabe.com

Sheet 6
A1: CHABE LUXURY TRANSPORT LLC
A2: 11B Street Warehouse 3b/27
A3: AL KHABAISI
A4: Dubai, UAE
A5: ='Infos Mensuelles'!A1 -> Salary slip January 2026
A8: Employee last name: | D8: ='Infos Mensuelles'!B12 -> JAINULAPUDEEN MOHAMED | H8: Employee ID: | J8: ='Infos Mensuelles'!F12 -> 10030078086699
H9: Arrival date: | J9: ='Infos Mensuelles'!D12 -> 44501
A11: Employee first name | D11: ='Infos Mensuelles'!C12 -> Anees | H11: Employee Position: | J11: ='Infos Mensuelles'!G12 -> Light Vehicule Driver
A15: Employee Attendance
A16: Working days : | D16: ='Infos Mensuelles'!L12 -> 27 | E16: Emergency not payable: | H16: ='Infos Mensuelles'!S12 -> 0 | I16: OT Hours Basic : | L16: ='Infos Mensuelles'!AE12 -> 20
A17: Working Public Holidays : | D17: ='Infos Mensuelles'!N12 -> 0 | E17: Sick Leave not Payable: | H17: ='Infos Mensuelles'!T12 -> 0 | I17: OT Hours Public holidays : | L17: ='Infos Mensuelles'!AH12 -> 0
A18: Off days : | D18: ='Infos Mensuelles'!M12 -> 4 | E18: Absence day not payable: | H18: ='Infos Mensuelles'!U12 -> 0 | I18: OT Days : | L18: ='Infos Mensuelles'!AL12 -> 0
A19: Sick Leave Payable : | D19: ='Infos Mensuelles'!P12 -> 0 | E19: Unpaid Leaves: | H19: ='Infos Mensuelles'!R12 -> 0 | I19: Leave Payable : | L19: ='Infos Mensuelles'!O12 -> 0
A20: Total of payable days : | D20: ='Infos Mensuelles'!Q12 -> 31
A23: Earnings & Deductions
A24: Salary Head | G24: Amount Earnings (AED) | J24: Amount Deductions (AED)
A26: Earnings
A27: Basic Salary | G27: ='Infos Mensuelles'!H12 -> 2640
A28: Housing Allowances | G28: ='Infos Mensuelles'!I12 -> 880
A29: Transport Allowances | G29: ='Infos Mensuelles'!J12 -> 880
A30: OT Hours Basic | G30: ='Infos Mensuelles'!AG12 -> 240
A31: OT Hours Public holidays | G31: ='Infos Mensuelles'!AJ12 -> 0
A32: OT Days | G32: ='Infos Mensuelles'!AN12 -> 0
A33: Air Plane Ticket Refundable | G33: ='Infos Mensuelles'!AQ12 -> 0
A34: Other Allowance | G34: ='Infos Mensuelles'!AO12 -> 0
A35: Adjustment form previous month | G35: ='Infos Mensuelles'!AP12 -> 0
A36: Deductions
A37: Advance salary | J37: ='Infos Mensuelles'!AS12 -> 0
A38: Your Fines paid by the company | J38: ='Infos Mensuelles'!AT12 -> 0
A39: Absence | J39: ='Infos Mensuelles'!Y12 -> 0
A40: Unpaid leaves | J40: ='Infos Mensuelles'!V12 -> 0
A41: Sick leave unpaid | J41: ='Infos Mensuelles'!X12 -> 0
A42: Adjustment form previous month | J42: ='Infos Mensuelles'!AU12 -> 0
A43: Emergency leave Unpaid | J43: ='Infos Mensuelles'!W12 -> 0
A45: TOTAL EARNINGS & DEDUCTIONS | G45: =SUM(G27:I36) -> 4640 | J45: =SUM(J42:L43) -> 0
A48: TOTAL AMOUNT : | G48: =G45-J45 -> 4640
A52: Payment informations:
A53: Date of payment: | D53: ='Infos Mensuelles'!E1 -> 46053
A54: Methode of payment: | D54: WPS
A55: If you need any informations please contact us at hr-dubai@chabe.com

Sheet 7
A1: CHABE LUXURY TRANSPORT LLC
A2: 11B Street Warehouse 3b/27
A3: AL KHABAISI
A4: Dubai, UAE
A5: ='Infos Mensuelles'!A1 -> Salary slip January 2026
A8: Employee last name: | D8: ='Infos Mensuelles'!B13 -> SHAH MISAL SHAH BUKHARI | H8: Employee ID: | J8: ='Infos Mensuelles'!F13 -> 20001018653644
H9: Arrival date: | J9: ='Infos Mensuelles'!D13 -> 44726
A11: Employee first name | D11: ='Infos Mensuelles'!C13 -> Asal | H11: Employee Position: | J11: ='Infos Mensuelles'!G13 -> Light Vehicule Driver
A15: Employee Attendance
A16: Working days : | D16: ='Infos Mensuelles'!L13 -> 28 | E16: Emergency not payable: | H16: ='Infos Mensuelles'!S13 -> 0 | I16: OT Hours Basic : | L16: ='Infos Mensuelles'!AE13 -> 4
A17: Working Public Holidays : | D17: ='Infos Mensuelles'!N13 -> 0 | E17: Sick Leave not Payable: | H17: ='Infos Mensuelles'!T13 -> 0 | I17: OT Hours Public holidays : | L17: ='Infos Mensuelles'!AH13 -> 0
A18: Off days : | D18: ='Infos Mensuelles'!M13 -> 3 | E18: Absence day not payable: | H18: ='Infos Mensuelles'!U13 -> 0 | I18: OT Days : | L18: ='Infos Mensuelles'!AL13 -> 2
A19: Sick Leave Payable : | D19: ='Infos Mensuelles'!P13 -> 0 | E19: Unpaid Leaves: | H19: ='Infos Mensuelles'!R13 -> 0 | I19: Leave Payable : | L19: ='Infos Mensuelles'!O13 -> 0
A20: Total of payable days : | D20: ='Infos Mensuelles'!Q13 -> 31
A23: Earnings & Deductions
A24: Salary Head | G24: Amount Earnings (AED) | J24: Amount Deductions (AED)
A26: Earnings
A27: Basic Salary | G27: ='Infos Mensuelles'!H13 -> 2580
A28: Housing Allowances | G28: ='Infos Mensuelles'!I13 -> 860
A29: Transport Allowances | G29: ='Infos Mensuelles'!J13 -> 860
A30: OT Hours Basic | G30: ='Infos Mensuelles'!AG13 -> 48
A31: OT Hours Public holidays | G31: ='Infos Mensuelles'!AJ13 -> 0
A32: OT Days | G32: ='Infos Mensuelles'!AN13 -> 282
A33: Air Plane Ticket Refundable | G33: ='Infos Mensuelles'!AQ13 -> 0
A34: Other Allowance | G34: ='Infos Mensuelles'!AO13 -> 0
A35: Adjustment form previous month | G35: ='Infos Mensuelles'!AP13 -> 0
A36: Deductions
A37: Advance salary | J37: ='Infos Mensuelles'!AS13 -> 0
A38: Your Fines paid by the company | J38: ='Infos Mensuelles'!AT13 -> 0
A39: Absence | J39: ='Infos Mensuelles'!Y13 -> 0
A40: Unpaid leaves | J40: ='Infos Mensuelles'!V13 -> 0
A41: Sick leave unpaid | J41: ='Infos Mensuelles'!X13 -> 0
A42: Adjustment form previous month | J42: ='Infos Mensuelles'!AU13 -> 0
A43: Emergency leave Unpaid | J43: ='Infos Mensuelles'!W13 -> 0
A45: TOTAL EARNINGS & DEDUCTIONS | G45: =SUM(G27:I36) -> 4630 | J45: =SUM(J42:L43) -> 0
A48: TOTAL AMOUNT : | G48: =G45-J45 -> 4630
A52: Payment informations:
A53: Date of payment: | D53: ='Infos Mensuelles'!E1 -> 46053
A54: Methode of payment: | D54: WPS
A55: If you need any informations please contact us at hr-dubai@chabe.com

Sheet 8
A1: CHABE LUXURY TRANSPORT LLC
A2: 11B Street Warehouse 3b/27
A3: AL KHABAISI
A4: Dubai, UAE
A5: ='Infos Mensuelles'!A1 -> Salary slip January 2026
A8: Employee last name: | D8: ='Infos Mensuelles'!B14 -> FAZAL HUSSAIN | H8: Employee ID: | J8: ='Infos Mensuelles'!F14 -> 20015018877124
H9: Arrival date: | J9: ='Infos Mensuelles'!D14 -> 42642
A11: Employee first name | D11: ='Infos Mensuelles'!C14 -> Atta Rasool | H11: Employee Position: | J11: ='Infos Mensuelles'!G14 -> Light Vehicule Driver
A15: Employee Attendance
A16: Working days : | D16: ='Infos Mensuelles'!L14 -> 29 | E16: Emergency not payable: | H16: ='Infos Mensuelles'!S14 -> 0 | I16: OT Hours Basic : | L16: ='Infos Mensuelles'!AE14 -> 5
A17: Working Public Holidays : | D17: ='Infos Mensuelles'!N14 -> 0 | E17: Sick Leave not Payable: | H17: ='Infos Mensuelles'!T14 -> 0 | I17: OT Hours Public holidays : | L17: ='Infos Mensuelles'!AH14 -> 0
A18: Off days : | D18: ='Infos Mensuelles'!M14 -> 2 | E18: Absence day not payable: | H18: ='Infos Mensuelles'!U14 -> 0 | I18: OT Days : | L18: ='Infos Mensuelles'!AL14 -> 3
A19: Sick Leave Payable : | D19: ='Infos Mensuelles'!P14 -> 0 | E19: Unpaid Leaves: | H19: ='Infos Mensuelles'!R14 -> 0 | I19: Leave Payable : | L19: ='Infos Mensuelles'!O14 -> 0
A20: Total of payable days : | D20: ='Infos Mensuelles'!Q14 -> 31
A23: Earnings & Deductions
A24: Salary Head | G24: Amount Earnings (AED) | J24: Amount Deductions (AED)
A26: Earnings
A27: Basic Salary | G27: ='Infos Mensuelles'!H14 -> 2700
A28: Housing Allowances | G28: ='Infos Mensuelles'!I14 -> 900
A29: Transport Allowances | G29: ='Infos Mensuelles'!J14 -> 900
A30: OT Hours Basic | G30: ='Infos Mensuelles'!AG14 -> 60
A31: OT Hours Public holidays | G31: ='Infos Mensuelles'!AJ14 -> 0
A32: OT Days | G32: ='Infos Mensuelles'!AN14 -> 444
A33: Air Plane Ticket Refundable | G33: ='Infos Mensuelles'!AQ14 -> 0
A34: Other Allowance | G34: ='Infos Mensuelles'!AO14 -> 0
A35: Adjustment form previous month | G35: ='Infos Mensuelles'!AP14 -> 0
A36: Deductions
A37: Advance salary | J37: ='Infos Mensuelles'!AS14 -> 0
A38: Your Fines paid by the company | J38: ='Infos Mensuelles'!AT14 -> 0
A39: Absence | J39: ='Infos Mensuelles'!Y14 -> 0
A40: Unpaid leaves | J40: ='Infos Mensuelles'!V14 -> 0
A41: Sick leave unpaid | J41: ='Infos Mensuelles'!X14 -> 0
A42: Adjustment form previous month | J42: ='Infos Mensuelles'!AU14 -> 0
A43: Emergency leave Unpaid | J43: ='Infos Mensuelles'!W14 -> 0
A45: TOTAL EARNINGS & DEDUCTIONS | G45: =SUM(G27:I36) -> 5004 | J45: =SUM(J42:L43) -> 0
A48: TOTAL AMOUNT : | G48: =G45-J45 -> 5004
A52: Payment informations:
A53: Date of payment: | D53: ='Infos Mensuelles'!E1 -> 46053
A54: Methode of payment: | D54: WPS
A55: If you need any informations please contact us at hr-dubai@chabe.com

Sheet 9
A1: CHABE LUXURY TRANSPORT LLC
A2: 11B Street Warehouse 3b/27
A3: AL KHABAISI
A4: Dubai, UAE
A5: ='Infos Mensuelles'!A1 -> Salary slip January 2026
A8: Employee last name: | D8: ='Infos Mensuelles'!B15 -> ULLAH MUHAMMAD RIAZ | H8: Employee ID: | J8: ='Infos Mensuelles'!F15 -> 20010118687794
H9: Arrival date: | J9: ='Infos Mensuelles'!D15 -> 43507
A11: Employee first name | D11: ='Infos Mensuelles'!C15 -> Attiq | H11: Employee Position: | J11: ='Infos Mensuelles'!G15 -> Light Vehicule Driver
A15: Employee Attendance
A16: Working days : | D16: ='Infos Mensuelles'!L15 -> 28 | E16: Emergency not payable: | H16: ='Infos Mensuelles'!S15 -> 0 | I16: OT Hours Basic : | L16: ='Infos Mensuelles'!AE15 -> 7
A17: Working Public Holidays : | D17: ='Infos Mensuelles'!N15 -> 0 | E17: Sick Leave not Payable: | H17: ='Infos Mensuelles'!T15 -> 0 | I17: OT Hours Public holidays : | L17: ='Infos Mensuelles'!AH15 -> 0
A18: Off days : | D18: ='Infos Mensuelles'!M15 -> 3 | E18: Absence day not payable: | H18: ='Infos Mensuelles'!U15 -> 0 | I18: OT Days : | L18: ='Infos Mensuelles'!AL15 -> 1
A19: Sick Leave Payable : | D19: ='Infos Mensuelles'!P15 -> 0 | E19: Unpaid Leaves: | H19: ='Infos Mensuelles'!R15 -> 0 | I19: Leave Payable : | L19: ='Infos Mensuelles'!O15 -> 0
A20: Total of payable days : | D20: ='Infos Mensuelles'!Q15 -> 31
A23: Earnings & Deductions
A24: Salary Head | G24: Amount Earnings (AED) | J24: Amount Deductions (AED)
A26: Earnings
A27: Basic Salary | G27: ='Infos Mensuelles'!H15 -> 2700
A28: Housing Allowances | G28: ='Infos Mensuelles'!I15 -> 900
A29: Transport Allowances | G29: ='Infos Mensuelles'!J15 -> 900
A30: OT Hours Basic | G30: ='Infos Mensuelles'!AG15 -> 84
A31: OT Hours Public holidays | G31: ='Infos Mensuelles'!AJ15 -> 0
A32: OT Days | G32: ='Infos Mensuelles'!AN15 -> 148
A33: Air Plane Ticket Refundable | G33: ='Infos Mensuelles'!AQ15 -> 0
A34: Other Allowance | G34: ='Infos Mensuelles'!AO15 -> 0
A35: Adjustment form previous month | G35: ='Infos Mensuelles'!AP15 -> 0
A36: Deductions
A37: Advance salary | J37: ='Infos Mensuelles'!AS15 -> 0
A38: Your Fines paid by the company | J38: ='Infos Mensuelles'!AT15 -> 0
A39: Absence | J39: ='Infos Mensuelles'!Y15 -> 0
A40: Unpaid leaves | J40: ='Infos Mensuelles'!V15 -> 0
A41: Sick leave unpaid | J41: ='Infos Mensuelles'!X15 -> 0
A42: Adjustment form previous month | J42: ='Infos Mensuelles'!AU15 -> 0
A43: Emergency leave Unpaid | J43: ='Infos Mensuelles'!W15 -> 0
A45: TOTAL EARNINGS & DEDUCTIONS | G45: =SUM(G27:I36) -> 4732 | J45: =SUM(J42:L43) -> 0
A48: TOTAL AMOUNT : | G48: =G45-J45 -> 4732
A52: Payment informations:
A53: Date of payment: | D53: ='Infos Mensuelles'!E1 -> 46053
A54: Methode of payment: | D54: WPS
A55: If you need any informations please contact us at hr-dubai@chabe.com

