Workbook

Sheet Infos Mensuelles
A1: Salary slip February 2026 | E1: 46081
A4: Informations Employee | H4: Contract base | L4: Earnings | AT4: Deductions | AW4: Total Earning | AX4: WPS Law | BA4: Comments
A5: N° | B5: Last Name | C5: First Name | D5: Date of arrival | E5: Release date | F5: Employee ID | G5: Job name | H5: Basic salary | I5: Housing Allowances | J5: Transportation Allowance | K5: Total on Contract | L5: Working days | S5: Absence Days Unpaid | AB5: TOTAL of Days during the month | AC5: Paid | AF5: OT Hours | AM5: OT Days | AP5: Other Allowance | AQ5: Adjustment for previous month | AR5: Air plane Ticket | AS5: Total Earning | AT5: Advance payment/ Deduction Advance | AU5: Fines payment advance by the company | AV5: Adjustment for previous month | AW5: TOTAL RECEIVABLE | AX5: Need to be send by the law for WPS | AY5: Missing on salary | AZ5: Adjustment to send
L6: No. working days | M6: Off days | N6: Public Holydays | O6: No. leave days PAID | P6: Sick Leave PAID | Q6: Adj | R6: Total Working days payable | S6: No. leave days UNPAID | T6: Emergancy Leave UNPAID | U6: Sick leave UNPAID | V6: Absent days (not allowed) | W6: UNPAID Leave Amount | X6: Emergancy Leave Amount | Y6: Sick leave UNPAID | Z6: Absent days (not allowed) | AA6: Total Working days unpayable | AC6: Leave PAID Amount | AD6: Sick Leave Amount | AE6: Salary | AF6: Hours | AG6: Amount Normal OT | AH6: Total | AI6: Public Holydays | AJ6: Amont Public Holydays | AK6: Total | AL6: Total | AM6: Days | AN6: Amount | AO6: Total
A7: D0001 | B7: MANNAPPAN THARAMMAL | C7: Abdulla | D7: 23.08.2022 | F7: 10028058458199 | G7: Light Vehicule Driver | H7: =K7*60% -> 2580 | I7: =K7*20% -> 860 | J7: =K7*20% -> 860 | K7: 4300 | L7: 21 | M7: 4 | N7: 0 | O7: 0 | P7: 3 | Q7: 2 | R7: =L7+M7+N7+O7+P7+Q7 -> 30 | S7: 0 | T7: 0 | U7: 0 | V7: 0 | W7: =K7/30*S7 -> 0 | X7: =K7/30*T7 -> 0 | Y7: =K7/30*U7 -> 0 | Z7: =K7/30*V7 -> 0 | AA7: =S7+T7+U7+V7 -> 0 | AB7: =R7+AA7 -> 30 | AC7: =K7/30*O7 -> 0 | AD7: =K7/30*P7 -> 430 | AE7: =SUM(K7/30*R7) -> 4300 | AF7: 10 | AG7: 12 | AH7: =AF7*AG7 -> 120 | AI7: 0 | AJ7: 14 | AK7: =AI7*AJ7 -> 0 | AL7: =AH7+AK7 -> 120 | AM7: 0 | AN7: 141 | AO7: =AM7*AN7 -> 0 | AR7: 0 | AS7: =SUM(AE7+AL7+AO7+AP7+AQ7+AR7) -> 4420 | AT7: 0 | AU7: 0 | AV7: 0 | AW7: =AS7-AT7-AU7-AV7 -> 4420 | AX7: =SUM(K7*80%) -> 3440 | AY7: =AW7-AX7 -> 980 | AZ7: =+AW7-AX7-AY7 -> 0
A8: D0002 | B8: SYED NABI AHMAD | C8: Irfran Ahmed | D8: 44414 | F8: 10005027939914 | G8: Light Vehicule Driver | H8: =K8*60% -> 2640 | I8: =K8*20% -> 880 | J8: =K8*20% -> 880 | K8: 4400 | L8: 24 | M8: 4 | N8: 0 | O8: 0 | P8: 0 | Q8: 2 | R8: =L8+M8+N8+O8+P8+Q8 -> 30 | S8: 0 | T8: 0 | U8: 0 | V8: 0 | W8: =K8/30*S8 -> 0 | X8: =K8/30*T8 -> 0 | Y8: =K8/30*U8 -> 0 | Z8: =K8/30*V8 -> 0 | AA8: =S8+T8+U8+V8 -> 0 | AB8: =R8+AA8 -> 30 | AC8: =K8/30*O8 -> 0 | AD8: =K8/30*P8 -> 0 | AE8: =SUM(K8/30*R8) -> 4400 | AF8: 34 | AG8: 12 | AH8: =AF8*AG8 -> 408 | AI8: 0 | AJ8: 14 | AK8: =AI8*AJ8 -> 0 | AL8: =AH8+AK8 -> 408 | AM8: 0 | AN8: 145 | AO8: =AM8*AN8 -> 0 | AR8: 0 | AS8: =SUM(AE8+AL8+AO8+AP8+AQ8+AR8) -> 4808 | AT8: 0 | AU8: 800 | AV8: 0 | AW8: =AS8-AT8-AU8-AV8 -> 4008 | AX8: =SUM(K8*80%) -> 3520 | AY8: =AW8-AX8 -> 488 | AZ8: =+AW8-AX8-AY8 -> 0
A9: D0003 | B9: SHAMSUDEEN | C9: Amanullah | D9: 19.09.2021 | F9: 10013067459387 | G9: Light Vehicule Driver | H9: =K9*60% -> 2640 | I9: =K9*20% -> 880 | J9: =K9*20% -> 880 | K9: 4400 | L9: 24 | M9: 4 | N9: 0 | O9: 0 | P9: 0 | Q9: 2 | R9: =L9+M9+N9+O9+P9+Q9 -> 30 | S9: 0 | T9: 0 | U9: 0 | V9: 0 | W9: =K9/30*S9 -> 0 | X9: =K9/30*T9 -> 0 | Y9: =K9/30*U9 -> 0 | Z9: =K9/30*V9 -> 0 | AA9: =S9+T9+U9+V9 -> 0 | AB9: =R9+AA9 -> 30 | AC9: =K9/30*O9 -> 0 | AD9: =K9/30*P9 -> 0 | AE9: =SUM(K9/30*R9) -> 4400 | AF9: 30 | AG9: 12 | AH9: =AF9*AG9 -> 360 | AI9: 0 | AJ9: 14 | AK9: =AI9*AJ9 -> 0 | AL9: =AH9+AK9 -> 360 | AM9: 0 | AN9: 145 | AO9: =AM9*AN9 -> 0 | AR9: 0 | AS9: =SUM(AE9+AL9+AO9+AP9+AQ9+AR9) -> 4760 | AT9: 0 | AU9: 0 | AV9: 0 | AW9: =AS9-AT9-AU9-AV9 -> 4760 | AX9: =SUM(K9*80%) -> 3520 | AY9: =AW9-AX9 -> 1240 | AZ9: =+AW9-AX9-AY9 -> 0
A10: D0004 | B10: BOGATTI | C10: Anam | D10: 42470 | F10: 31620017062269 | G10: Light Vehicule Driver | H10: =K10*60% -> 2700 | I10: =K10*20% -> 900 | J10: =K10*20% -> 900 | K10: 4500 | L10: 24 | M10: 4 | N10: 0 | O10: 0 | P10: 0 | Q10: 2 | R10: =L10+M10+N10+O10+P10+Q10 -> 30 | S10: 0 | T10: 0 | U10: 0 | V10: 0 | W10: =K10/30*S10 -> 0 | X10: =K10/30*T10 -> 0 | Y10: =K10/30*U10 -> 0 | Z10: =K10/30*V10 -> 0 | AA10: =S10+T10+U10+V10 -> 0 | AB10: =R10+AA10 -> 30 | AC10: =K10/30*O10 -> 0 | AD10: =K10/30*P10 -> 0 | AE10: =SUM(K10/30*R10) -> 4500 | AF10: 30 | AG10: 12 | AH10: =AF10*AG10 -> 360 | AI10: 0 | AJ10: 15 | AK10: =AI10*AJ10 -> 0 | AL10: =AH10+AK10 -> 360 | AM10: 0 | AN10: 148 | AO10: =AM10*AN10 -> 0 | AR10: 0 | AS10: =SUM(AE10+AL10+AO10+AP10+AQ10+AR10) -> 4860 | AT10: 0 | AU10: 0 | AV10: 0 | AW10: =AS10-AT10-AU10-AV10 -> 4860 | AX10: =SUM(K10*80%) -> 3600 | AY10: =AW10-AX10 -> 1260 | AZ10: =+AW10-AX10-AY10 -> 0
A11: D0005 | B11: SUNKADAKATTE ABDULKHADER | C11: Mohamed Aneefa | D11: 42898 | F11: 10019057895758 | G11: Light Vehicule Driver | H11: =K11*60% -> 2700 | I11: =K11*20% -> 900 | J11: =K11*20% -> 900 | K11: 4500 | L11: 24 | M11: 4 | N11: 0 | O11: 0 | P11: 0 | Q11: 2 | R11: =L11+M11+N11+O11+P11+Q11 -> 30 | S11: 0 | T11: 0 | U11: 0 | V11: 0 | W11: =K11/30*S11 -> 0 | X11: =K11/30*T11 -> 0 | Y11: =K11/30*U11 -> 0 | Z11: =K11/30*V11 -> 0 | AA11: =S11+T11+U11+V11 -> 0 | AB11: =R11+AA11 -> 30 | AC11: =K11/30*O11 -> 0 | AD11: =K11/30*P11 -> 0 | AE11: =SUM(K11/30*R11) -> 4500 | AF11: 36 | AG11: 12 | AH11: =AF11*AG11 -> 432 | AI11: 0 | AJ11: 15 | AK11: =AI11*AJ11 -> 0 | AL11: =AH11+AK11 -> 432 | AM11: 0 | AN11: 148 | AO11: =AM11*AN11 -> 0 | AR11: 0 | AS11: =SUM(AE11+AL11+AO11+AP11+AQ11+AR11) -> 4932 | AT11: 0 | AU11: 0 | AV11: 0 | AW11: =AS11-AT11-AU11-AV11 -> 4932 | AX11: =SUM(K11*80%) -> 3600 | AY11: =AW11-AX11 -> 1332 | AZ11: =+AW11-AX11-AY11 -> 0
A12: D0006 | B12: JAINULAPUDEEN MOHAMED | C12: Anees | D12: 44501 | F12: 10030078086699 | G12: Light Vehicule Driver | H12: =K12*60% -> 2640 | I12: =K12*20% -> 880 | J12: =K12*20% -> 880 | K12: 4400 | L12: 24 | M12: 4 | N12: 0 | O12: 0 | P12: 0 | Q12: 2 | R12: =L12+M12+N12+O12+P12+Q12 -> 30 | S12: 0 | T12: 0 | U12: 0 | V12: 0 | W12: =K12/30*S12 -> 0 | X12: =K12/30*T12 -> 0 | Y12: =K12/30*U12 -> 0 | Z12: =K12/30*V12 -> 0 | AA12: =S12+T12+U12+V12 -> 0 | AB12: =R12+AA12 -> 30 | AC12: =K12/30*O12 -> 0 | AD12: =K12/30*P12 -> 0 | AE12: =SUM(K12/30*R12) -> 4400 | AF12: 24 | AG12: 12 | AH12: =AF12*AG12 -> 288 | AI12: 0 | AJ12: 14 | AK12: =AI12*AJ12 -> 0 | AL12: =AH12+AK12 -> 288 | AM12: 0 | AN12: 145 | AO12: =AM12*AN12 -> 0 | AR12: 0 | AS12: =SUM(AE12+AL12+AO12+AP12+AQ12+AR12) -> 4688 | AT12: 0 | AU12: 0 | AV12: 0 | AW12: =AS12-AT12-AU12-AV12 -> 4688 | AX12: =SUM(K12*80%) -> 3520 | AY12: =AW12-AX12 -> 1168 | AZ12: =+AW12-AX12-AY12 -> 0
A13: D0007 | B13: SHAH MISAL SHAH BUKHARI | C13: Asal | D13: 44726 | F13: 20001018653644 | G13: Light Vehicule Driver | H13: =K13*60% -> 2580 | I13: =K13*20% -> 860 | J13: =K13*20% -> 860 | K13: 4300 | L13: 24 | M13: 4 | N13: 0 | O13: 0 | P13: 0 | Q13: 2 | R13: =L13+M13+N13+O13+P13+Q13 -> 30 | S13: 0 | T13: 0 | U13: 0 | V13: 0 | W13: =K13/30*S13 -> 0 | X13: =K13/30*T13 -> 0 | Y13: =K13/30*U13 -> 0 | Z13: =K13/30*V13 -> 0 | AA13: =S13+T13+U13+V13 -> 0 | AB13: =R13+AA13 -> 30 | AC13: =K13/30*O13 -> 0 | AD13: =K13/30*P13 -> 0 | AE13: =SUM(K13/30*R13) -> 4300 | AF13: 30 | AG13: 12 | AH13: =AF13*AG13 -> 360 | AI13: 0 | AJ13: 14 | AK13: =AI13*AJ13 -> 0 | AL13: =AH13+AK13 -> 360 | AM13: 0 | AN13: 141 | AO13: =AM13*AN13 -> 0 | AR13: 0 | AS13: =SUM(AE13+AL13+AO13+AP13+AQ13+AR13) -> 4660 | AT13: 0 | AU13: 0 | AV13: 0 | AW13: =AS13-AT13-AU13-AV13 -> 4660 | AX13: =SUM(K13*80%) -> 3440 | AY13: =AW13-AX13 -> 1220 | AZ13: =+AW13-AX13-AY13 -> 0
A14: D0008 | B14: FAZAL HUSSAIN | C14: Atta Rasool | D14: 42642 | F14: 20015018877124 | G14: Light Vehicule Driver | H14: =K14*60% -> 2700 | I14: =K14*20% -> 900 | J14: =K14*20% -> 900 | K14: 4500 | L14: 25 | M14: 3 | N14: 0 | O14: 0 | P14: 0 | Q14: 2 | R14: =L14+M14+N14+O14+P14+Q14 -> 30 | S14: 0 | T14: 0 | U14: 0 | V14: 0 | W14: =K14/30*S14 -> 0 | X14: =K14/30*T14 -> 0 | Y14: =K14/30*U14 -> 0 | Z14: =K14/30*V14 -> 0 | AA14: =S14+T14+U14+V14 -> 0 | AB14: =R14+AA14 -> 30 | AC14: =K14/30*O14 -> 0 | AD14: =K14/30*P14 -> 0 | AE14: =SUM(K14/30*R14) -> 4500 | AF14: 36 | AG14: 12 | AH14: =AF14*AG14 -> 432 | AI14: 0 | AJ14: 15 | AK14: =AI14*AJ14 -> 0 | AL14: =AH14+AK14 -> 432 | AM14: 1 | AN14: 148 | AO14: =AM14*AN14 -> 148 | AR14: 0 | AS14: =SUM(AE14+AL14+AO14+AP14+AQ14+AR14) -> 5080 | AT14: 0 | AU14: 0 | AV14: 0 | AW14: =AS14-AT14-AU14-AV14 -> 5080 | AX14: =SUM(K14*80%) -> 3600 | AY14: =AW14-AX14 -> 1480 | AZ14: =+AW14-AX14-AY14 -> 0
A15: D0009 | B15: ULLAH MUHAMMAD RIAZ | C15: Attiq | D15: 43507 | F15: 20010118687794 | G15: Light Vehicule Driver | H15: =K15*60% -> 2700 | I15: =K15*20% -> 900 | J15: =K15*20% -> 900 | K15: 4500 | L15: 24 | M15: 4 | N15: 0 | O15: 0 | P15: 0 | Q15: 2 | R15: =L15+M15+N15+O15+P15+Q15 -> 30 | S15: 0 | T15: 0 | U15: 0 | V15: 0 | W15: =K15/30*S15 -> 0 | X15: =K15/30*T15 -> 0 | Y15: =K15/30*U15 -> 0 | Z15: =K15/30*V15 -> 0 | AA15: =S15+T15+U15+V15 -> 0 | AB15: =R15+AA15 -> 30 | AC15: =K15/30*O15 -> 0 | AD15: =K15/30*P15 -> 0 | AE15: =SUM(K15/30*R15) -> 4500 | AF15: 34 | AG15: 12 | AH15: =AF15*AG15 -> 408 | AI15: 0 | AJ15: 15 | AK15: =AI15*AJ15 -> 0 | AL15: =AH15+AK15 -> 408 | AM15: 1 | AN15: 148 | AO15: =AM15*AN15 -> 148 | AR15: 0 | AS15: =SUM(AE15+AL15+AO15+AP15+AQ15+AR15) -> 5056 | AT15: 0 | AU15: 0 | AV15: 0 | AW15: =AS15-AT15-AU15-AV15 -> 5056 | AX15: =SUM(K15*80%) -> 3600 | AY15: =AW15-AX15 -> 1456 | AZ15: =+AW15-AX15-AY15 -> 0
A16: D0010 | B16: KHAN NAZIR | C16: Bilal | D16: 44664 | F16: 20011019277621 | G16: Light Vehicule Driver | H16: =K16*60% -> 2580 | I16: =K16*20% -> 860 | J16: =K16*20% -> 860 | K16: 4300 | L16: 23 | M16: 4 | N16: 0 | O16: 0 | P16: 1 | Q16: 2 | R16: =L16+M16+N16+O16+P16+Q16 -> 30 | S16: 0 | T16: 0 | U16: 0 | V16: 0 | W16: =K16/30*S16 -> 0 | X16: =K16/30*T16 -> 0 | Y16: =K16/30*U16 -> 0 | Z16: =K16/30*V16 -> 0 | AA16: =S16+T16+U16+V16 -> 0 | AB16: =R16+AA16 -> 30 | AC16: =K16/30*O16 -> 0 | AD16: =K16/30*P16 -> 143.33333 | AE16: =SUM(K16/30*R16) -> 4300 | AF16: 27 | AG16: 12 | AH16: =AF16*AG16 -> 324 | AI16: 0 | AJ16: 14 | AK16: =AI16*AJ16 -> 0 | AL16: =AH16+AK16 -> 324 | AM16: 0 | AN16: 141 | AO16: =AM16*AN16 -> 0 | AR16: 0 | AS16: =SUM(AE16+AL16+AO16+AP16+AQ16+AR16) -> 4624 | AT16: 0 | AU16: 0 | AV16: 0 | AW16: =AS16-AT16-AU16-AV16 -> 4624 | AX16: =SUM(K16*80%) -> 3440 | AY16: =AW16-AX16 -> 1184 | AZ16: =+AW16-AX16-AY16 -> 0 | BA16: FAKE TICKET in 2024
A17: D0011 | B17: ISMAIL SAMSUDEEN | C17: Farook | D17: 45310 | F17: 10030079016477 | G17: Light Vehicule Driver | H17: =K17*60% -> 2520 | I17: =K17*20% -> 840 | J17: =K17*20% -> 840 | K17: 4200 | L17: 25 | M17: 3 | N17: 0 | O17: 0 | P17: 0 | Q17: 2 | R17: =L17+M17+N17+O17+P17+Q17 -> 30 | S17: 0 | T17: 0 | U17: 0 | V17: 0 | W17: =K17/30*S17 -> 0 | X17: =K17/30*T17 -> 0 | Y17: =K17/30*U17 -> 0 | Z17: =K17/30*V17 -> 0 | AA17: =S17+T17+U17+V17 -> 0 | AB17: =R17+AA17 -> 30 | AC17: =K17/30*O17 -> 0 | AD17: =K17/30*P17 -> 0 | AE17: =SUM(K17/30*R17) -> 4200 | AF17: 37 | AG17: 12 | AH17: =AF17*AG17 -> 444 | AI17: 0 | AJ17: 14 | AK17: =AI17*AJ17 -> 0 | AL17: =AH17+AK17 -> 444 | AM17: 1 | AN17: 138 | AO17: =AM17*AN17 -> 138 | AR17: 0 | AS17: =SUM(AE17+AL17+AO17+AP17+AQ17+AR17) -> 4782 | AT17: 0 | AU17: 0 | AV17: 0 | AW17: =AS17-AT17-AU17-AV17 -> 4782 | AX17: =SUM(K17*80%) -> 3360 | AY17: =AW17-AX17 -> 1422 | AZ17: =+AW17-AX17-AY17 -> 0
A18: D0012 | B18: MOHIDEEN ABDUL RAHUMAN | C18: Haja | D18: 43671 | F18: 10017048332090 | G18: Light Vehicule Driver | H18: =K18*60% -> 2700 | I18: =K18*20% -> 900 | J18: =K18*20% -> 900 | K18: 4500 | L18: 24 | M18: 4 | N18: 0 | O18: 0 | P18: 0 | Q18: 2 | R18: =L18+M18+N18+O18+P18+Q18 -> 30 | S18: 0 | T18: 0 | U18: 0 | V18: 0 | W18: =K18/30*S18 -> 0 | X18: =K18/30*T18 -> 0 | Y18: =K18/30*U18 -> 0 | Z18: =K18/30*V18 -> 0 | AA18: =S18+T18+U18+V18 -> 0 | AB18: =R18+AA18 -> 30 | AC18: =K18/30*O18 -> 0 | AD18: =K18/30*P18 -> 0 | AE18: =SUM(K18/30*R18) -> 4500 | AF18: 35 | AG18: 12 | AH18: =AF18*AG18 -> 420 | AI18: 0 | AJ18: 15 | AK18: =AI18*AJ18 -> 0 | AL18: =AH18+AK18 -> 420 | AM18: 0 | AN18: 148 | AO18: =AM18*AN18 -> 0 | AR18: 0 | AS18: =SUM(AE18+AL18+AO18+AP18+AQ18+AR18) -> 4920 | AT18: 0 | AU18: 275 | AV18: 0 | AW18: =AS18-AT18-AU18-AV18 -> 4645 | AX18: =SUM(K18*80%) -> 3600 | AY18: =AW18-AX18 -> 1045 | AZ18: =+AW18-AX18-AY18 -> 0 | BA18: AIR TICKET TO BE PAID
A19: D0013 | B19: KHAN AHMAD KHAN | C19: Ibrahim | D19: 44855 | F19: 20002038203486 | G19: Light Vehicule Driver | H19: =K19*60% -> 2580 | I19: =K19*20% -> 860 | J19: =K19*20% -> 860 | K19: 4300 | L19: 24 | M19: 4 | N19: 0 | O19: 0 | P19: 0 | Q19: 2 | R19: =L19+M19+N19+O19+P19+Q19 -> 30 | S19: 0 | T19: 0 | U19: 0 | V19: 0 | W19: =K19/30*S19 -> 0 | X19: =K19/30*T19 -> 0 | Y19: =K19/30*U19 -> 0 | Z19: =K19/30*V19 -> 0 | AA19: =S19+T19+U19+V19 -> 0 | AB19: =R19+AA19 -> 30 | AC19: =K19/30*O19 -> 0 | AD19: =K19/30*P19 -> 0 | AE19: =SUM(K19/30*R19) -> 4300 | AF19: 22 | AG19: 12 | AH19: =AF19*AG19 -> 264 | AI19: 0 | AJ19: 14 | AK19: =AI19*AJ19 -> 0 | AL19: =AH19+AK19 -> 264 | AM19: 0 | AN19: 141 | AO19: =AM19*AN19 -> 0 | AR19: 0 | AS19: =SUM(AE19+AL19+AO19+AP19+AQ19+AR19) -> 4564 | AT19: 0 | AU19: 400 | AV19: 0 | AW19: =AS19-AT19-AU19-AV19 -> 4164 | AX19: =SUM(K19*80%) -> 3440 | AY19: =AW19-AX19 -> 724 | AZ19: =+AW19-AX19-AY19 -> 0
A20: D0014 | B20: ZAMAN | C20: Haider | D20: 46030 | F20: 20029018381980 | G20: Light Vehicule Driver | H20: =K20*60% -> 2100 | I20: =K20*20% -> 700 | J20: =K20*20% -> 700 | K20: 3500 | L20: 24 | M20: 4 | N20: 0 | O20: 0 | P20: 0 | Q20: 2 | R20: =L20+M20+N20+O20+P20+Q20 -> 30 | S20: 0 | T20: 0 | U20: 0 | V20: 0 | W20: =K20/30*S20 -> 0 | X20: =K20/30*T20 -> 0 | Y20: =K20/30*U20 -> 0 | Z20: =K20/30*V20 -> 0 | AA20: =S20+T20+U20+V20 -> 0 | AB20: =R20+AA20 -> 30 | AC20: =K20/30*O20 -> 0 | AD20: =K20/30*P20 -> 0 | AE20: =SUM(K20/30*R20) -> 3500 | AF20: 2 | AG20: 10 | AH20: =AF20*AG20 -> 20 | AI20: 0 | AJ20: 12 | AK20: =AI20*AJ20 -> 0 | AM20: 0 | AN20: 115 | AO20: =AM20*AN20 -> 0 | AR20: 0 | AS20: =SUM(AE20+AL20+AO20+AP20+AQ20+AR20) -> 3500 | AT20: 0 | AU20: 0 | AV20: 0 | AW20: =AS20-AT20-AU20-AV20 -> 3500 | AX20: =SUM(K20*80%) -> 2800 | AY20: =AW20-AX20 -> 700 | AZ20: =+AW20-AX20-AY20 -> 0
A21: D0015 | B21: HUSSAIN JAINULLABUDEEN | C21: Jahir | D21: 43653 | F21: 10001066217554 | G21: Light Vehicule Driver | H21: =K21*60% -> 2700 | I21: =K21*20% -> 900 | J21: =K21*20% -> 900 | K21: 4500 | L21: 25 | M21: 3 | N21: 0 | O21: 0 | P21: 0 | Q21: 2 | R21: =L21+M21+N21+O21+P21+Q21 -> 30 | S21: 0 | T21: 0 | U21: 0 | V21: 0 | W21: =K21/30*S21 -> 0 | X21: =K21/30*T21 -> 0 | Y21: =K21/30*U21 -> 0 | Z21: =K21/30*V21 -> 0 | AA21: =S21+T21+U21+V21 -> 0 | AB21: =R21+AA21 -> 30 | AC21: =K21/30*O21 -> 0 | AD21: =K21/30*P21 -> 0 | AE21: =SUM(K21/30*R21) -> 4500 | AF21: 16 | AG21: 12 | AH21: =AF21*AG21 -> 192 | AI21: 0 | AJ21: 15 | AK21: =AI21*AJ21 -> 0 | AL21: =AH21+AK21 -> 192 | AM21: 1 | AN21: 148 | AO21: =AM21*AN21 -> 148 | AR21: 0 | AS21: =SUM(AE21+AL21+AO21+AP21+AQ21+AR21) -> 4840 | AT21: 0 | AU21: 0 | AV21: 0 | AW21: =AS21-AT21-AU21-AV21 -> 4840 | AX21: =SUM(K21*80%) -> 3600 | AY21: =AW21-AX21 -> 1240 | AZ21: =+AW21-AX21-AY21 -> 0
A22: D0016 | B22: CHERPANATH JOY | C22: Poulose | D22: 42956 | F22: 10029036003822 | G22: Light Vehicule Driver | H22: =K22*60% -> 2700 | I22: =K22*20% -> 900 | J22: =K22*20% -> 900 | K22: 4500 | L22: 24 | M22: 4 | N22: 0 | O22: 0 | P22: 0 | Q22: 2 | R22: =L22+M22+N22+O22+P22+Q22 -> 30 | S22: 0 | T22: 0 | U22: 0 | V22: 0 | W22: =K22/30*S22 -> 0 | X22: =K22/30*T22 -> 0 | Y22: =K22/30*U22 -> 0 | Z22: =K22/30*V22 -> 0 | AA22: =S22+T22+U22+V22 -> 0 | AB22: =R22+AA22 -> 30 | AC22: =K22/30*O22 -> 0 | AD22: =K22/30*P22 -> 0 | AE22: =SUM(K22/30*R22) -> 4500 | AF22: 29 | AG22: 12 | AH22: =AF22*AG22 -> 348 | AI22: 0 | AJ22: 15 | AK22: =AI22*AJ22 -> 0 | AL22: =AH22+AK22 -> 348 | AM22: 0 | AN22: 148 | AO22: =AM22*AN22 -> 0 | AR22: 0 | AS22: =SUM(AE22+AL22+AO22+AP22+AQ22+AR22) -> 4848 | AT22: 0 | AU22: 0 | AV22: 0 | AW22: =AS22-AT22-AU22-AV22 -> 4848 | AX22: =SUM(K22*80%) -> 3600 | AY22: =AW22-AX22 -> 1248 | AZ22: =+AW22-AX22-AY22 -> 0
A23: D0017 | B23: SIRAJ MUHAMMAD | C23: Kamran Khan | D23: 44797 | F23: 20028129188803 | G23: Light Vehicule Driver | H23: =K23*60% -> 2580 | I23: =K23*20% -> 860 | J23: =K23*20% -> 860 | K23: 4300 | L23: 24 | M23: 4 | N23: 0 | O23: 0 | P23: 0 | Q23: 2 | R23: =L23+M23+N23+O23+P23+Q23 -> 30 | S23: 0 | T23: 0 | U23: 0 | V23: 0 | W23: =K23/30*S23 -> 0 | X23: =K23/30*T23 -> 0 | Y23: =K23/30*U23 -> 0 | Z23: =K23/30*V23 -> 0 | AA23: =S23+T23+U23+V23 -> 0 | AB23: =R23+AA23 -> 30 | AC23: =K23/30*O23 -> 0 | AD23: =K23/30*P23 -> 0 | AE23: =SUM(K23/30*R23) -> 4300 | AF23: 28 | AG23: 12 | AH23: =AF23*AG23 -> 336 | AI23: 0 | AJ23: 14 | AK23: =AI23*AJ23 -> 0 | AL23: =AH23+AK23 -> 336 | AM23: 0 | AN23: 141 | AO23: =AM23*AN23 -> 0 | AR23: 0 | AS23: =SUM(AE23+AL23+AO23+AP23+AQ23+AR23) -> 4636 | AT23: 0 | AU23: 0 | AV23: 0 | AW23: =AS23-AT23-AU23-AV23 -> 4636 | AX23: =SUM(K23*80%) -> 3440 | AY23: =AW23-AX23 -> 1196 | AZ23: =+AW23-AX23-AY23 -> 0
A24: D0018 | B24: RICHARD SEA | C24: Kene | D24: 45287 | F24: 41023128217554 | G24: Light Vehicule Driver | H24: =K24*60% -> 2520 | I24: =K24*20% -> 840 | J24: =K24*20% -> 840 | K24: 4200 | L24: 24 | M24: 4 | N24: 0 | O24: 0 | P24: 0 | Q24: 2 | R24: =L24+M24+N24+O24+P24+Q24 -> 30 | S24: 0 | T24: 0 | U24: 0 | V24: 0 | W24: =K24/30*S24 -> 0 | X24: =K24/30*T24 -> 0 | Y24: =K24/30*U24 -> 0 | Z24: =K24/30*V24 -> 0 | AA24: =S24+T24+U24+V24 -> 0 | AB24: =R24+AA24 -> 30 | AC24: =K24/30*O24 -> 0 | AD24: =K24/30*P24 -> 0 | AE24: =SUM(K24/30*R24) -> 4200 | AF24: 34 | AG24: 12 | AH24: =AF24*AG24 -> 408 | AI24: 0 | AJ24: 14 | AK24: =AI24*AJ24 -> 0 | AL24: =AH24+AK24 -> 408 | AM24: 0 | AN24: 138 | AO24: =AM24*AN24 -> 0 | AR24: 0 | AS24: =SUM(AE24+AL24+AO24+AP24+AQ24+AR24) -> 4608 | AT24: 0 | AU24: 0 | AV24: 0 | AW24: =AS24-AT24-AU24-AV24 -> 4608 | AX24: =SUM(K24*80%) -> 3360 | AY24: =AW24-AX24 -> 1248 | AZ24: =+AW24-AX24-AY24 -> 0
A25: D0019 | B25: KAAMIL SYED ALI | C25: Mohsin | D25: 43079 | F25: 10022028260817 | G25: Light Vehicule Driver | H25: =K25*60% -> 2700 | I25: =K25*20% -> 900 | J25: =K25*20% -> 900 | K25: 4500 | L25: 19 | M25: 3 | N25: 0 | O25: 0 | P25: 0 | Q25: 2 | R25: =L25+M25+N25+O25+P25+Q25 -> 24 | T25: 6 | W25: =K25/30*S25 -> 0 | X25: =K25/30*T25 -> 900 | Y25: =K25/30*U25 -> 0 | Z25: =K25/30*V25 -> 0 | AA25: =S25+T25+U25+V25 -> 6 | AB25: =R25+AA25 -> 30 | AC25: =K25/30*O25 -> 0 | AD25: =K25/30*P25 -> 0 | AE25: =SUM(K25/30*R25) -> 3600 | AF25: 30 | AG25: 12 | AH25: =AF25*AG25 -> 360 | AI25: 0 | AJ25: 15 | AK25: =AI25*AJ25 -> 0 | AL25: =AH25+AK25 -> 360 | AM25: 0 | AN25: 148 | AO25: =AM25*AN25 -> 0 | AR25: 0 | AS25: =SUM(AE25+AL25+AO25+AP25+AQ25+AR25) -> 3960 | AT25: 0 | AU25: 0 | AV25: 0 | AW25: =AS25-AT25-AU25-AV25 -> 3960 | AX25: =SUM(K25*80%) -> 3600 | AY25: =AW25-AX25 -> 360 | AZ25: =+AW25-AX25-AY25 -> 0
A26: D0020 | B26: KUNHI MAVAL | C26: Moideen | D26: 44845 | F26: 10001067941432 | G26: Light Vehicule Driver | H26: =K26*60% -> 2580 | I26: =K26*20% -> 860 | J26: =K26*20% -> 860 | K26: 4300 | L26: 24 | M26: 4 | N26: 0 | O26: 0 | P26: 0 | Q26: 2 | R26: =L26+M26+N26+O26+P26+Q26 -> 30 | S26: 0 | T26: 0 | U26: 0 | V26: 0 | W26: =K26/30*S26 -> 0 | X26: =K26/30*T26 -> 0 | Y26: =K26/30*U26 -> 0 | Z26: =K26/30*V26 -> 0 | AA26: =S26+T26+U26+V26 -> 0 | AB26: =R26+AA26 -> 30 | AC26: =K26/30*O26 -> 0 | AD26: =K26/30*P26 -> 0 | AE26: =SUM(K26/30*R26) -> 4300 | AF26: 27 | AG26: 12 | AH26: =AF26*AG26 -> 324 | AI26: 0 | AJ26: 14 | AK26: =AI26*AJ26 -> 0 | AL26: =AH26+AK26 -> 324 | AM26: 0 | AN26: 141 | AO26: =AM26*AN26 -> 0 | AR26: 0 | AS26: =SUM(AE26+AL26+AO26+AP26+AQ26+AR26) -> 4624 | AT26: 0 | AU26: 520 | AV26: 0 | AW26: =AS26-AT26-AU26-AV26 -> 4104 | AX26: =SUM(K26*80%) -> 3440 | AY26: =AW26-AX26 -> 664 | AZ26: =+AW26-AX26-AY26 -> 0 | BA26: FAKE TICKET in 2024
A27: D0021 | B27: SURYA GEETHA KUMAR THULASEEDHARAN | C27: Nandhan | D27: 45276 | F27: 10030109962464 | G27: Light Vehicule Driver | H27: =K27*60% -> 2520 | I27: =K27*20% -> 840 | J27: =K27*20% -> 840 | K27: 4200 | L27: 25 | M27: 3 | N27: 0 | O27: 0 | P27: 0 | Q27: 2 | R27: =L27+M27+N27+O27+P27+Q27 -> 30 | S27: 0 | T27: 0 | U27: 0 | V27: 0 | W27: =K27/30*S27 -> 0 | X27: =K27/30*T27 -> 0 | Y27: =K27/30*U27 -> 0 | Z27: =K27/30*V27 -> 0 | AA27: =S27+T27+U27+V27 -> 0 | AB27: =R27+AA27 -> 30 | AC27: =K27/30*O27 -> 0 | AD27: =K27/30*P27 -> 0 | AE27: =SUM(K27/30*R27) -> 4200 | AF27: 54 | AG27: 12 | AH27: =AF27*AG27 -> 648 | AI27: 0 | AJ27: 14 | AK27: =AI27*AJ27 -> 0 | AL27: =AH27+AK27 -> 648 | AM27: 1 | AN27: 138 | AO27: =AM27*AN27 -> 138 | AR27: 0 | AS27: =SUM(AE27+AL27+AO27+AP27+AQ27+AR27) -> 4986 | AT27: 0 | AU27: 0 | AV27: 0 | AW27: =AS27-AT27-AU27-AV27 -> 4986 | AX27: =SUM(K27*80%) -> 3360 | AY27: =AW27-AX27 -> 1626 | AZ27: =+AW27-AX27-AY27 -> 0
A28: D0022 | B28: MOHAMMED KOLLAROTHODIKA | C28: Naseem | D28: 42076 | F28: 10010018229793 | G28: Light Vehicule Driver | H28: =K28*60% -> 2700 | I28: =K28*20% -> 900 | J28: =K28*20% -> 900 | K28: 4500 | L28: 24 | M28: 4 | N28: 0 | O28: 0 | P28: 0 | Q28: 2 | R28: =L28+M28+N28+O28+P28+Q28 -> 30 | S28: 0 | T28: 0 | U28: 0 | V28: 0 | W28: =K28/30*S28 -> 0 | X28: =K28/30*T28 -> 0 | Y28: =K28/30*U28 -> 0 | Z28: =K28/30*V28 -> 0 | AA28: =S28+T28+U28+V28 -> 0 | AB28: =R28+AA28 -> 30 | AC28: =K28/30*O28 -> 0 | AD28: =K28/30*P28 -> 0 | AE28: =SUM(K28/30*R28) -> 4500 | AF28: 20 | AG28: 12 | AH28: =AF28*AG28 -> 240 | AI28: 0 | AJ28: 15 | AK28: =AI28*AJ28 -> 0 | AL28: =AH28+AK28 -> 240 | AM28: 0 | AN28: 148 | AO28: =AM28*AN28 -> 0 | AR28: 0 | AS28: =SUM(AE28+AL28+AO28+AP28+AQ28+AR28) -> 4740 | AT28: 0 | AU28: 0 | AV28: 0 | AW28: =AS28-AT28-AU28-AV28 -> 4740 | AX28: =SUM(K28*80%) -> 3600 | AY28: =AW28-AX28 -> 1140 | AZ28: =+AW28-AX28-AY28 -> 0
A29: D0023 | B29: ALLAH DITTA | C29: Nawaz Muhammad | D29: 45232 | F29: 20001016925583 | G29: Light Vehicule Driver | H29: =K29*60% -> 2520 | I29: =K29*20% -> 840 | J29: =K29*20% -> 840 | K29: 4200 | L29: 24 | M29: 4 | N29: 0 | O29: 0 | P29: 0 | Q29: 2 | R29: =L29+M29+N29+O29+P29+Q29 -> 30 | S29: 0 | T29: 0 | U29: 0 | V29: 0 | W29: =K29/30*S29 -> 0 | X29: =K29/30*T29 -> 0 | Y29: =K29/30*U29 -> 0 | Z29: =K29/30*V29 -> 0 | AA29: =S29+T29+U29+V29 -> 0 | AB29: =R29+AA29 -> 30 | AC29: =K29/30*O29 -> 0 | AD29: =K29/30*P29 -> 0 | AE29: =SUM(K29/30*R29) -> 4200 | AF29: 34 | AG29: 12 | AH29: =AF29*AG29 -> 408 | AI29: 0 | AJ29: 14 | AK29: =AI29*AJ29 -> 0 | AL29: =AH29+AK29 -> 408 | AM29: 0 | AN29: 138 | AO29: =AM29*AN29 -> 0 | AR29: 0 | AS29: =SUM(AE29+AL29+AO29+AP29+AQ29+AR29) -> 4608 | AT29: 0 | AU29: 0 | AV29: 0 | AW29: =AS29-AT29-AU29-AV29 -> 4608 | AX29: =SUM(K29*80%) -> 3360 | AY29: =AW29-AX29 -> 1248 | AZ29: =+AW29-AX29-AY29 -> 0
A30: D0024 | B30: MAHEEN KIDIR MOHAMMED MAHEEN | C30: Nizam | D30: 43661 | F30: 10013029316206 | G30: Light Vehicule Driver | H30: =K30*60% -> 2700 | I30: =K30*20% -> 900 | J30: =K30*20% -> 900 | K30: 4500 | L30: 22 | M30: 4 | N30: 0 | O30: 0 | P30: 2 | Q30: 2 | R30: =L30+M30+N30+O30+P30+Q30 -> 30 | S30: 0 | T30: 0 | U30: 0 | V30: 0 | W30: =K30/30*S30 -> 0 | X30: =K30/30*T30 -> 0 | Y30: =K30/30*U30 -> 0 | Z30: =K30/30*V30 -> 0 | AA30: =S30+T30+U30+V30 -> 0 | AB30: =R30+AA30 -> 30 | AC30: =K30/30*O30 -> 0 | AD30: =K30/30*P30 -> 300 | AE30: =SUM(K30/30*R30) -> 4500 | AF30: 31 | AG30: 12 | AH30: =AF30*AG30 -> 372 | AI30: 0 | AJ30: 15 | AK30: =AI30*AJ30 -> 0 | AL30: =AH30+AK30 -> 372 | AM30: 0 | AN30: 148 | AO30: =AM30*AN30 -> 0 | AR30: 0 | AS30: =SUM(AE30+AL30+AO30+AP30+AQ30+AR30) -> 4872 | AT30: 0 | AU30: 0 | AV30: 0 | AW30: =AS30-AT30-AU30-AV30 -> 4872 | AX30: =SUM(K30*80%) -> 3600 | AY30: =AW30-AX30 -> 1272 | AZ30: =+AW30-AX30-AY30 -> 0
A31: D0025 | B31: VEETIL KRISHNAN KUNNAMMAL | C31: Pranav | D31: 43650 | F31: 10020038912465 | G31: Light Vehicule Driver | H31: =K31*60% -> 2700 | I31: =K31*20% -> 900 | J31: =K31*20% -> 900 | K31: 4500 | L31: 24 | M31: 4 | N31: 0 | O31: 0 | P31: 0 | Q31: 2 | R31: =L31+M31+N31+O31+P31+Q31 -> 30 | S31: 0 | T31: 0 | U31: 0 | V31: 0 | W31: =K31/30*S31 -> 0 | X31: =K31/30*T31 -> 0 | Y31: =K31/30*U31 -> 0 | Z31: =K31/30*V31 -> 0 | AA31: =S31+T31+U31+V31 -> 0 | AB31: =R31+AA31 -> 30 | AC31: =K31/30*O31 -> 0 | AD31: =K31/30*P31 -> 0 | AE31: =SUM(K31/30*R31) -> 4500 | AF31: 39 | AG31: 12 | AH31: =AF31*AG31 -> 468 | AI31: 0 | AJ31: 15 | AK31: =AI31*AJ31 -> 0 | AL31: =AH31+AK31 -> 468 | AM31: 0 | AN31: 148 | AO31: =AM31*AN31 -> 0 | AR31: 0 | AS31: =SUM(AE31+AL31+AO31+AP31+AQ31+AR31) -> 4968 | AT31: 0 | AU31: 0 | AV31: 0 | AW31: =AS31-AT31-AU31-AV31 -> 4968 | AX31: =SUM(K31*80%) -> 3600 | AY31: =AW31-AX31 -> 1368 | AZ31: =+AW31-AX31-AY31 -> 0
A32: D0026 | B32: MUHAMMAD USMAN GHULAM | C32: Qadir | D32: 45287 | F32: 20024049662792 | G32: Light Vehicule Driver | H32: =K32*60% -> 2520 | I32: =K32*20% -> 840 | J32: =K32*20% -> 840 | K32: 4200 | L32: 24 | M32: 4 | N32: 0 | O32: 0 | P32: 0 | Q32: 2 | R32: =L32+M32+N32+O32+P32+Q32 -> 30 | S32: 0 | T32: 0 | U32: 0 | V32: 0 | W32: =K32/30*S32 -> 0 | X32: =K32/30*T32 -> 0 | Y32: =K32/30*U32 -> 0 | Z32: =K32/30*V32 -> 0 | AA32: =S32+T32+U32+V32 -> 0 | AB32: =R32+AA32 -> 30 | AC32: =K32/30*O32 -> 0 | AD32: =K32/30*P32 -> 0 | AE32: =SUM(K32/30*R32) -> 4200 | AF32: 31 | AG32: 12 | AH32: =AF32*AG32 -> 372 | AI32: 0 | AJ32: 14 | AK32: =AI32*AJ32 -> 0 | AL32: =AH32+AK32 -> 372 | AM32: 0 | AN32: 138 | AO32: =AM32*AN32 -> 0 | AR32: 0 | AS32: =SUM(AE32+AL32+AO32+AP32+AQ32+AR32) -> 4572 | AT32: 0 | AU32: 0 | AV32: 0 | AW32: =AS32-AT32-AU32-AV32 -> 4572 | AX32: =SUM(K32*80%) -> 3360 | AY32: =AW32-AX32 -> 1212 | AZ32: =+AW32-AX32-AY32 -> 0
A33: D0027 | B33: KOZHIPPURATH ABOOBACKER | C33: Rasheed | D33: 43570 | F33: 10021057922829 | G33: Light Vehicule Driver | H33: =K33*60% -> 2700 | I33: =K33*20% -> 900 | J33: =K33*20% -> 900 | K33: 4500 | L33: 25 | M33: 3 | N33: 0 | O33: 0 | P33: 0 | Q33: 2 | R33: =L33+M33+N33+O33+P33+Q33 -> 30 | S33: 0 | T33: 0 | U33: 0 | V33: 0 | W33: =K33/30*S33 -> 0 | X33: =K33/30*T33 -> 0 | Y33: =K33/30*U33 -> 0 | Z33: =K33/30*V33 -> 0 | AA33: =S33+T33+U33+V33 -> 0 | AB33: =R33+AA33 -> 30 | AC33: =K33/30*O33 -> 0 | AD33: =K33/30*P33 -> 0 | AE33: =SUM(K33/30*R33) -> 4500 | AF33: 67 | AG33: 12 | AH33: =AF33*AG33 -> 804 | AI33: 0 | AJ33: 15 | AK33: =AI33*AJ33 -> 0 | AL33: =AH33+AK33 -> 804 | AM33: 1 | AN33: 148 | AO33: =AM33*AN33 -> 148 | AR33: 0 | AS33: =SUM(AE33+AL33+AO33+AP33+AQ33+AR33) -> 5452 | AT33: 0 | AU33: 0 | AV33: 0 | AW33: =AS33-AT33-AU33-AV33 -> 5452 | AX33: =SUM(K33*80%) -> 3600 | AY33: =AW33-AX33 -> 1852 | AZ33: =+AW33-AX33-AY33 -> 0 | BA33: FAKE TICKET in 2024
A34: D0028 | B34: ACHARYA | C34: Rajan | D34: 44830 | F34: 31601127390678 | G34: Light Vehicule Driver | H34: =K34*60% -> 2580 | I34: =K34*20% -> 860 | J34: =K34*20% -> 860 | K34: 4300 | L34: 25 | M34: 3 | N34: 0 | O34: 0 | P34: 0 | Q34: 2 | R34: =L34+M34+N34+O34+P34+Q34 -> 30 | S34: 0 | T34: 0 | U34: 0 | V34: 0 | W34: =K34/30*S34 -> 0 | X34: =K34/30*T34 -> 0 | Y34: =K34/30*U34 -> 0 | Z34: =K34/30*V34 -> 0 | AA34: =S34+T34+U34+V34 -> 0 | AB34: =R34+AA34 -> 30 | AC34: =K34/30*O34 -> 0 | AD34: =K34/30*P34 -> 0 | AE34: =SUM(K34/30*R34) -> 4300 | AF34: 23 | AG34: 12 | AH34: =AF34*AG34 -> 276 | AI34: 0 | AJ34: 14 | AK34: =AI34*AJ34 -> 0 | AL34: =AH34+AK34 -> 276 | AM34: 1 | AN34: 141 | AO34: =AM34*AN34 -> 141 | AR34: 0 | AS34: =SUM(AE34+AL34+AO34+AP34+AQ34+AR34) -> 4717 | AT34: 0 | AU34: 0 | AV34: 0 | AW34: =AS34-AT34-AU34-AV34 -> 4717 | AX34: =SUM(K34*80%) -> 3440 | AY34: =AW34-AX34 -> 1277 | AZ34: =+AW34-AX34-AY34 -> 0
A35: D0029 | B35: ALIPETTA UMMER | C35: Riyas | D35: 44796 | F35: 10025088010140 | G35: Light Vehicule Driver | H35: =K35*60% -> 2580 | I35: =K35*20% -> 860 | J35: =K35*20% -> 860 | K35: 4300 | L35: 25 | M35: 3 | N35: 0 | O35: 0 | P35: 0 | Q35: 2 | R35: =L35+M35+N35+O35+P35+Q35 -> 30 | S35: 0 | T35: 0 | U35: 0 | V35: 0 | W35: =K35/30*S35 -> 0 | X35: =K35/30*T35 -> 0 | Y35: =K35/30*U35 -> 0 | Z35: =K35/30*V35 -> 0 | AA35: =S35+T35+U35+V35 -> 0 | AB35: =R35+AA35 -> 30 | AC35: =K35/30*O35 -> 0 | AD35: =K35/30*P35 -> 0 | AE35: =SUM(K35/30*R35) -> 4300 | AF35: 47 | AG35: 12 | AH35: =AF35*AG35 -> 564 | AI35: 0 | AJ35: 14 | AK35: =AI35*AJ35 -> 0 | AL35: =AH35+AK35 -> 564 | AM35: 1 | AN35: 141 | AO35: =AM35*AN35 -> 141 | AR35: 0 | AS35: =SUM(AE35+AL35+AO35+AP35+AQ35+AR35) -> 5005 | AT35: 0 | AU35: 170 | AV35: 0 | AW35: =AS35-AT35-AU35-AV35 -> 4835 | AX35: =SUM(K35*80%) -> 3440 | AY35: =AW35-AX35 -> 1395 | AZ35: =+AW35-AX35-AY35 -> 0 | BA35: FAKE TICKET in 2024
A36: D0030 | B36: GIRIJA MOHANDAS SREEDHARAN PANICKER | C36: Riju | D36: 45344 | F36: 10004078884984 | G36: Light Vehicule Driver | H36: =K36*60% -> 2520 | I36: =K36*20% -> 840 | J36: =K36*20% -> 840 | K36: 4200 | L36: 24 | M36: 4 | N36: 0 | O36: 0 | P36: 0 | Q36: 2 | R36: =L36+M36+N36+O36+P36+Q36 -> 30 | S36: 0 | T36: 0 | U36: 0 | V36: 0 | W36: =K36/30*S36 -> 0 | X36: =K36/30*T36 -> 0 | Y36: =K36/30*U36 -> 0 | Z36: =K36/30*V36 -> 0 | AA36: =S36+T36+U36+V36 -> 0 | AB36: =R36+AA36 -> 30 | AC36: =K36/30*O36 -> 0 | AD36: =K36/30*P36 -> 0 | AE36: =SUM(K36/30*R36) -> 4200 | AF36: 21 | AG36: 12 | AH36: =AF36*AG36 -> 252 | AI36: 0 | AJ36: 14 | AK36: =AI36*AJ36 -> 0 | AL36: =AH36+AK36 -> 252 | AM36: 0 | AN36: 138 | AO36: =AM36*AN36 -> 0 | AR36: 0 | AS36: =SUM(AE36+AL36+AO36+AP36+AQ36+AR36) -> 4452 | AT36: 0 | AU36: 0 | AV36: 0 | AW36: =AS36-AT36-AU36-AV36 -> 4452 | AX36: =SUM(K36*80%) -> 3360 | AY36: =AW36-AX36 -> 1092 | AZ36: =+AW36-AX36-AY36 -> 0
A37: D0031 | B37: VANNATHAN POIYEL MOOSSA | C37: Sackeer | D37: 45293 | F37: 10021047655633 | G37: Light Vehicule Driver | H37: =K37*60% -> 2520 | I37: =K37*20% -> 840 | J37: =K37*20% -> 840 | K37: 4200 | L37: 24 | M37: 4 | N37: 0 | O37: 0 | P37: 0 | Q37: 2 | R37: =L37+M37+N37+O37+P37+Q37 -> 30 | S37: 0 | T37: 0 | U37: 0 | V37: 0 | W37: =K37/30*S37 -> 0 | X37: =K37/30*T37 -> 0 | Y37: =K37/30*U37 -> 0 | Z37: =K37/30*V37 -> 0 | AA37: =S37+T37+U37+V37 -> 0 | AB37: =R37+AA37 -> 30 | AC37: =K37/30*O37 -> 0 | AD37: =K37/30*P37 -> 0 | AE37: =SUM(K37/30*R37) -> 4200 | AF37: 15 | AG37: 12 | AH37: =AF37*AG37 -> 180 | AI37: 0 | AJ37: 14 | AK37: =AI37*AJ37 -> 0 | AL37: =AH37+AK37 -> 180 | AM37: 0 | AN37: 138 | AO37: =AM37*AN37 -> 0 | AR37: 0 | AS37: =SUM(AE37+AL37+AO37+AP37+AQ37+AR37) -> 4380 | AT37: 0 | AU37: 0 | AV37: 0 | AW37: =AS37-AT37-AU37-AV37 -> 4380 | AX37: =SUM(K37*80%) -> 3360 | AY37: =AW37-AX37 -> 1020 | AZ37: =+AW37-AX37-AY37 -> 0
A38: D0032 | B38: SHAMIL ARIYOLOKOYA ARIYOLI | C38: Muhammed | D38: 44802 | F38: 10012108936044 | G38: Light Vehicule Driver | H38: =K38*60% -> 2580 | I38: =K38*20% -> 860 | J38: =K38*20% -> 860 | K38: 4300 | L38: 24 | M38: 4 | N38: 0 | O38: 0 | P38: 0 | Q38: 2 | R38: =L38+M38+N38+O38+P38+Q38 -> 30 | S38: 0 | T38: 0 | U38: 0 | V38: 0 | W38: =K38/30*S38 -> 0 | X38: =K38/30*T38 -> 0 | Y38: =K38/30*U38 -> 0 | Z38: =K38/30*V38 -> 0 | AA38: =S38+T38+U38+V38 -> 0 | AB38: =R38+AA38 -> 30 | AC38: =K38/30*O38 -> 0 | AD38: =K38/30*P38 -> 0 | AE38: =SUM(K38/30*R38) -> 4300 | AF38: 32 | AG38: 12 | AH38: =AF38*AG38 -> 384 | AI38: 0 | AJ38: 14 | AK38: =AI38*AJ38 -> 0 | AL38: =AH38+AK38 -> 384 | AM38: 0 | AN38: 141 | AO38: =AM38*AN38 -> 0 | AR38: 0 | AS38: =SUM(AE38+AL38+AO38+AP38+AQ38+AR38) -> 4684 | AT38: 0 | AU38: 0 | AV38: 0 | AW38: =AS38-AT38-AU38-AV38 -> 4684 | AX38: =SUM(K38*80%) -> 3440 | AY38: =AW38-AX38 -> 1244 | AZ38: =+AW38-AX38-AY38 -> 0 | BA38: FAKE TICKET in 2024
A39: D0033 | B39: MUHAMMAD BILAL MEHMOOD | C39: Shah | D39: 45287 | F39: 20012108325991 | G39: Light Vehicule Driver | H39: =K39*60% -> 2520 | I39: =K39*20% -> 840 | J39: =K39*20% -> 840 | K39: 4200 | L39: 24 | M39: 4 | N39: 0 | O39: 0 | P39: 0 | Q39: 2 | R39: =L39+M39+N39+O39+P39+Q39 -> 30 | S39: 0 | T39: 0 | U39: 0 | V39: 0 | W39: =K39/30*S39 -> 0 | X39: =K39/30*T39 -> 0 | Y39: =K39/30*U39 -> 0 | Z39: =K39/30*V39 -> 0 | AA39: =S39+T39+U39+V39 -> 0 | AB39: =R39+AA39 -> 30 | AC39: =K39/30*O39 -> 0 | AD39: =K39/30*P39 -> 0 | AE39: =SUM(K39/30*R39) -> 4200 | AF39: 39 | AG39: 12 | AH39: =AF39*AG39 -> 468 | AI39: 0 | AJ39: 14 | AK39: =AI39*AJ39 -> 0 | AL39: =AH39+AK39 -> 468 | AM39: 0 | AN39: 138 | AO39: =AM39*AN39 -> 0 | AR39: 0 | AS39: =SUM(AE39+AL39+AO39+AP39+AQ39+AR39) -> 4668 | AT39: 0 | AU39: 0 | AV39: 0 | AW39: =AS39-AT39-AU39-AV39 -> 4668 | AX39: =SUM(K39*80%) -> 3360 | AY39: =AW39-AX39 -> 1308 | AZ39: =+AW39-AX39-AY39 -> 0
A40: D0034 | B40: ISMAIL KHAN | C40: Shahzad | D40: 45287 | F40: 20021067796071 | G40: Light Vehicule Driver | H40: =K40*60% -> 2520 | I40: =K40*20% -> 840 | J40: =K40*20% -> 840 | K40: 4200 | L40: 24 | M40: 4 | N40: 0 | O40: 0 | P40: 0 | Q40: 2 | R40: =L40+M40+N40+O40+P40+Q40 -> 30 | S40: 0 | T40: 0 | U40: 0 | V40: 0 | W40: =K40/30*S40 -> 0 | X40: =K40/30*T40 -> 0 | Y40: =K40/30*U40 -> 0 | Z40: =K40/30*V40 -> 0 | AA40: =S40+T40+U40+V40 -> 0 | AB40: =R40+AA40 -> 30 | AC40: =K40/30*O40 -> 0 | AD40: =K40/30*P40 -> 0 | AE40: =SUM(K40/30*R40) -> 4200 | AF40: 27 | AG40: 12 | AH40: =AF40*AG40 -> 324 | AI40: 0 | AJ40: 14 | AK40: =AI40*AJ40 -> 0 | AL40: =AH40+AK40 -> 324 | AM40: 0 | AN40: 138 | AO40: =AM40*AN40 -> 0 | AR40: 0 | AS40: =SUM(AE40+AL40+AO40+AP40+AQ40+AR40) -> 4524 | AT40: 0 | AU40: 0 | AV40: 0 | AW40: =AS40-AT40-AU40-AV40 -> 4524 | AX40: =SUM(K40*80%) -> 3360 | AY40: =AW40-AX40 -> 1164 | AZ40: =+AW40-AX40-AY40 -> 0
A41: D0035 | B41: KANDIRUTHY ACHUTHAN KANDIRUTHY KARAPAN | C41: Shiju | D41: 44525 | F41: 10020037771919 | G41: Light Vehicule Driver | H41: =K41*60% -> 2640 | I41: =K41*20% -> 880 | J41: =K41*20% -> 880 | K41: 4400 | L41: 25 | M41: 3 | N41: 0 | O41: 0 | P41: 0 | Q41: 2 | R41: =L41+M41+N41+O41+P41+Q41 -> 30 | S41: 0 | T41: 0 | U41: 0 | V41: 0 | W41: =K41/30*S41 -> 0 | X41: =K41/30*T41 -> 0 | Y41: =K41/30*U41 -> 0 | Z41: =K41/30*V41 -> 0 | AA41: =S41+T41+U41+V41 -> 0 | AB41: =R41+AA41 -> 30 | AC41: =K41/30*O41 -> 0 | AD41: =K41/30*P41 -> 0 | AE41: =SUM(K41/30*R41) -> 4400 | AF41: 35 | AG41: 12 | AH41: =AF41*AG41 -> 420 | AI41: 0 | AJ41: 14 | AK41: =AI41*AJ41 -> 0 | AL41: =AH41+AK41 -> 420 | AM41: 1 | AN41: 145 | AO41: =AM41*AN41 -> 145 | AR41: 0 | AS41: =SUM(AE41+AL41+AO41+AP41+AQ41+AR41) -> 4965 | AT41: 0 | AU41: 0 | AV41: 0 | AW41: =AS41-AT41-AU41-AV41 -> 4965 | AX41: =SUM(K41*80%) -> 3520 | AY41: =AW41-AX41 -> 1445 | AZ41: =+AW41-AX41-AY41 -> 0 | BA41: FAKE TICKET in 2024
A42: D0036 | B42: SIRAJUDHEEN THOTTIKULATHIL | C42: Muhammed | D42: 44460 | F42: 10016058960893 | G42: Light Vehicule Driver | H42: =K42*60% -> 2640 | I42: =K42*20% -> 880 | J42: =K42*20% -> 880 | K42: 4400 | L42: 9 | M42: 2 | N42: 0 | O42: 0 | P42: 0 | Q42: 2 | R42: =L42+M42+N42+O42+P42+Q42 -> 13 | S42: 0 | T42: 17 | U42: 0 | V42: 0 | W42: =K42/30*S42 -> 0 | X42: =K42/30*T42 -> 2493.3333 | Y42: =K42/30*U42 -> 0 | Z42: =K42/30*V42 -> 0 | AA42: =S42+T42+U42+V42 -> 17 | AB42: =R42+AA42 -> 30 | AC42: =K42/30*O42 -> 0 | AD42: =K42/30*P42 -> 0 | AE42: =SUM(K42/30*R42) -> 1906.6667 | AF42: 4 | AG42: 12 | AH42: =AF42*AG42 -> 48 | AI42: 0 | AJ42: 14 | AK42: =AI42*AJ42 -> 0 | AL42: =AH42+AK42 -> 48 | AM42: 0 | AN42: 145 | AO42: =AM42*AN42 -> 0 | AR42: 0 | AS42: =SUM(AE42+AL42+AO42+AP42+AQ42+AR42) -> 1954.6667 | AT42: 0 | AU42: 0 | AV42: 0 | AW42: =AS42-AT42-AU42-AV42 -> 1954.6667 | AX42: =SUM(K42*80%) -> 3520 | AY42: =AW42-AX42 -> -1565.3333 | AZ42: =+AW42-AX42-AY42 -> 0
...

Sheet 1
A1: CHABE LUXURY TRANSPORT LLC
A2: 11B Street Warehouse 3b/27
A3: AL KHABAISI
A4: Dubai, UAE
A5: ='Infos Mensuelles'!A1 -> Salary slip February 2026
A8: Employee last name: | D8: ='Infos Mensuelles'!B7 -> MANNAPPAN THARAMMAL | H8: Employee ID: | J8: ='Infos Mensuelles'!F7 -> 10028058458199
H9: Arrival date: | J9: ='Infos Mensuelles'!D7 -> 23.08.2022
A11: Employee first name | D11: ='Infos Mensuelles'!C7 -> Abdulla | H11: Employee Position: | J11: ='Infos Mensuelles'!G7 -> Light Vehicule Driver
A15: Employee Attendance
A16: Working days : | D16: ='Infos Mensuelles'!L7 -> 21 | E16: Emergency not payable: | H16: ='Infos Mensuelles'!T7 -> 0 | I16: OT Hours Basic : | L16: ='Infos Mensuelles'!AF7 -> 10
A17: Working Public Holidays : | D17: ='Infos Mensuelles'!N7 -> 0 | E17: Sick Leave not Payable: | H17: ='Infos Mensuelles'!U7 -> 0 | I17: OT Hours Public holidays : | L17: ='Infos Mensuelles'!AI7 -> 0
A18: Off days : | D18: ='Infos Mensuelles'!M7 -> 4 | E18: Absence day not payable: | H18: ='Infos Mensuelles'!V7 -> 0 | I18: OT Days : | L18: ='Infos Mensuelles'!AM7 -> 0
A19: Sick Leave Payable : | D19: ='Infos Mensuelles'!P7 -> 3 | E19: Unpaid Leaves: | H19: ='Infos Mensuelles'!S7 -> 0 | I19: Leave Payable : | L19: ='Infos Mensuelles'!O7 -> 0
A20: Total of payable days : | D20: ='Infos Mensuelles'!R7 -> 30
A23: Earnings & Deductions
A24: Salary Head | G24: Amount Earnings (AED) | J24: Amount Deductions (AED)
A26: Earnings
A27: Basic Salary | G27: ='Infos Mensuelles'!H7 -> 2580
A28: Housing Allowances | G28: ='Infos Mensuelles'!I7 -> 860
A29: Transport Allowances | G29: ='Infos Mensuelles'!J7 -> 860
A30: OT Hours Basic | G30: ='Infos Mensuelles'!AH7 -> 120
A31: OT Hours Public holidays | G31: ='Infos Mensuelles'!AK7 -> 0
A32: OT Days | G32: ='Infos Mensuelles'!AO7 -> 0
A33: Air Plane Ticket Refundable | G33: ='Infos Mensuelles'!AR7 -> 0
A34: Other Allowance | G34: ='Infos Mensuelles'!AP7 -> 0
A35: Adjustment form previous month | G35: ='Infos Mensuelles'!AQ7 -> 0
A36: Deductions
A37: Advance salary | J37: ='Infos Mensuelles'!AT7 -> 0
A38: Your Fines paid by the company | J38: ='Infos Mensuelles'!AU7 -> 0
A39: Absence | J39: ='Infos Mensuelles'!Z7 -> 0
A40: Unpaid leaves | J40: ='Infos Mensuelles'!W7 -> 0
A41: Sick leave unpaid | J41: ='Infos Mensuelles'!Y7 -> 0
A42: Adjustment form previous month | J42: ='Infos Mensuelles'!AV7 -> 0
A43: Emergency leave Unpaid | J43: ='Infos Mensuelles'!X7 -> 0
A45: TOTAL EARNINGS & DEDUCTIONS | G45: =SUM(G26:I44) -> 4420 | J45: =SUM(J26:L44) -> 0
A48: TOTAL AMOUNT : | G48: =G45-J45 -> 4420
A52: Payment informations:
A53: Date of payment: | D53: ='Infos Mensuelles'!E1 -> 46081
A54: Methode of payment: | D54: WPS
A55: If you need any informations please contact us at hr-dubai@chabe.com

Sheet 2
A1: CHABE LUXURY TRANSPORT LLC
A2: 11B Street Warehouse 3b/27
A3: AL KHABAISI
A4: Dubai, UAE
A5: ='Infos Mensuelles'!A1 -> Salary slip February 2026
A8: Employee last name: | D8: ='Infos Mensuelles'!B8 -> SYED NABI AHMAD | H8: Employee ID: | J8: ='Infos Mensuelles'!F8 -> 10005027939914
H9: Arrival date: | J9: ='Infos Mensuelles'!D8 -> 44414
A11: Employee first name | D11: ='Infos Mensuelles'!C8 -> Irfran Ahmed | H11: Employee Position: | J11: ='Infos Mensuelles'!G8 -> Light Vehicule Driver
A15: Employee Attendance
A16: Working days : | D16: ='Infos Mensuelles'!L8 -> 24 | E16: Emergency not payable: | H16: ='Infos Mensuelles'!T8 -> 0 | I16: OT Hours Basic : | L16: ='Infos Mensuelles'!AF8 -> 34
A17: Working Public Holidays : | D17: ='Infos Mensuelles'!N8 -> 0 | E17: Sick Leave not Payable: | H17: ='Infos Mensuelles'!U8 -> 0 | I17: OT Hours Public holidays : | L17: ='Infos Mensuelles'!AI8 -> 0
A18: Off days : | D18: ='Infos Mensuelles'!M8 -> 4 | E18: Absence day not payable: | H18: ='Infos Mensuelles'!V8 -> 0 | I18: OT Days : | L18: ='Infos Mensuelles'!AM8 -> 0
A19: Sick Leave Payable : | D19: ='Infos Mensuelles'!P8 -> 0 | E19: Unpaid Leaves: | H19: ='Infos Mensuelles'!S8 -> 0 | I19: Leave Payable : | L19: ='Infos Mensuelles'!O8 -> 0
A20: Total of payable days : | D20: ='Infos Mensuelles'!R8 -> 30
A23: Earnings & Deductions
A24: Salary Head | G24: Amount Earnings (AED) | J24: Amount Deductions (AED)
A26: Earnings
A27: Basic Salary | G27: ='Infos Mensuelles'!H8 -> 2640
A28: Housing Allowances | G28: ='Infos Mensuelles'!I8 -> 880
A29: Transport Allowances | G29: ='Infos Mensuelles'!J8 -> 880
A30: OT Hours Basic | G30: ='Infos Mensuelles'!AH8 -> 408
A31: OT Hours Public holidays | G31: ='Infos Mensuelles'!AK8 -> 0
A32: OT Days | G32: ='Infos Mensuelles'!AO8 -> 0
A33: Air Plane Ticket Refundable | G33: ='Infos Mensuelles'!AR8 -> 0
A34: Other Allowance | G34: ='Infos Mensuelles'!AP8 -> 0
A35: Adjustment form previous month | G35: ='Infos Mensuelles'!AQ8 -> 0
A36: Deductions
A37: Advance salary | J37: ='Infos Mensuelles'!AT8 -> 0
A38: Your Fines paid by the company | J38: ='Infos Mensuelles'!AU8 -> 800
A39: Absence | J39: ='Infos Mensuelles'!Z8 -> 0
A40: Unpaid leaves | J40: ='Infos Mensuelles'!W8 -> 0
A41: Sick leave unpaid | J41: ='Infos Mensuelles'!Y8 -> 0
A42: Adjustment form previous month | J42: ='Infos Mensuelles'!AV8 -> 0
A43: Emergency leave Unpaid | J43: ='Infos Mensuelles'!X8 -> 0
A45: TOTAL EARNINGS & DEDUCTIONS | G45: =SUM(G26:I44) -> 4808 | J45: =SUM(J26:L44) -> 800
A48: TOTAL AMOUNT : | G48: =G45-J45 -> 4008
A52: Payment informations:
A53: Date of payment: | D53: ='Infos Mensuelles'!E1 -> 46081
A54: Methode of payment: | D54: WPS
A55: If you need any informations please contact us at hr-dubai@chabe.com

Sheet 3
A1: CHABE LUXURY TRANSPORT LLC
A2: 11B Street Warehouse 3b/27
A3: AL KHABAISI
A4: Dubai, UAE
A5: ='Infos Mensuelles'!A1 -> Salary slip February 2026
A8: Employee last name: | D8: ='Infos Mensuelles'!B9 -> SHAMSUDEEN | H8: Employee ID: | J8: ='Infos Mensuelles'!F9 -> 10013067459387
H9: Arrival date: | J9: ='Infos Mensuelles'!D9 -> 19.09.2021
A11: Employee first name | D11: ='Infos Mensuelles'!C9 -> Amanullah | H11: Employee Position: | J11: ='Infos Mensuelles'!G9 -> Light Vehicule Driver
A15: Employee Attendance
A16: Working days : | D16: ='Infos Mensuelles'!L9 -> 24 | E16: Emergency not payable: | H16: ='Infos Mensuelles'!T9 -> 0 | I16: OT Hours Basic : | L16: ='Infos Mensuelles'!AF9 -> 30
A17: Working Public Holidays : | D17: ='Infos Mensuelles'!N9 -> 0 | E17: Sick Leave not Payable: | H17: ='Infos Mensuelles'!U9 -> 0 | I17: OT Hours Public holidays : | L17: ='Infos Mensuelles'!AI9 -> 0
A18: Off days : | D18: ='Infos Mensuelles'!M9 -> 4 | E18: Absence day not payable: | H18: ='Infos Mensuelles'!V9 -> 0 | I18: OT Days : | L18: ='Infos Mensuelles'!AM9 -> 0
A19: Sick Leave Payable : | D19: ='Infos Mensuelles'!P9 -> 0 | E19: Unpaid Leaves: | H19: ='Infos Mensuelles'!S9 -> 0 | I19: Leave Payable : | L19: ='Infos Mensuelles'!O9 -> 0
A20: Total of payable days : | D20: ='Infos Mensuelles'!R9 -> 30
A23: Earnings & Deductions
A24: Salary Head | G24: Amount Earnings (AED) | J24: Amount Deductions (AED)
A26: Earnings
A27: Basic Salary | G27: ='Infos Mensuelles'!H9 -> 2640
A28: Housing Allowances | G28: ='Infos Mensuelles'!I9 -> 880
A29: Transport Allowances | G29: ='Infos Mensuelles'!J9 -> 880
A30: OT Hours Basic | G30: ='Infos Mensuelles'!AH9 -> 360
A31: OT Hours Public holidays | G31: ='Infos Mensuelles'!AK9 -> 0
A32: OT Days | G32: ='Infos Mensuelles'!AO9 -> 0
A33: Air Plane Ticket Refundable | G33: ='Infos Mensuelles'!AR9 -> 0
A34: Other Allowance | G34: ='Infos Mensuelles'!AP9 -> 0
A35: Adjustment form previous month | G35: ='Infos Mensuelles'!AQ9 -> 0
A36: Deductions
A37: Advance salary | J37: ='Infos Mensuelles'!AT9 -> 0
A38: Your Fines paid by the company | J38: ='Infos Mensuelles'!AU9 -> 0
A39: Absence | J39: ='Infos Mensuelles'!Z9 -> 0
A40: Unpaid leaves | J40: ='Infos Mensuelles'!W9 -> 0
A41: Sick leave unpaid | J41: ='Infos Mensuelles'!Y9 -> 0
A42: Adjustment form previous month | J42: ='Infos Mensuelles'!AV9 -> 0
A43: Emergency leave Unpaid | J43: ='Infos Mensuelles'!X9 -> 0
A45: TOTAL EARNINGS & DEDUCTIONS | G45: =SUM(G26:I44) -> 4760 | J45: =SUM(J26:L44) -> 0
A48: TOTAL AMOUNT : | G48: =G45-J45 -> 4760
A52: Payment informations:
A53: Date of payment: | D53: ='Infos Mensuelles'!E1 -> 46081
A54: Methode of payment: | D54: WPS
A55: If you need any informations please contact us at hr-dubai@chabe.com

Sheet 4
A1: CHABE LUXURY TRANSPORT LLC
A2: 11B Street Warehouse 3b/27
A3: AL KHABAISI
A4: Dubai, UAE
A5: ='Infos Mensuelles'!A1 -> Salary slip February 2026
A8: Employee last name: | D8: ='Infos Mensuelles'!B10 -> BOGATTI | H8: Employee ID: | J8: ='Infos Mensuelles'!F10 -> 31620017062269
H9: Arrival date: | J9: ='Infos Mensuelles'!D10 -> 42470
A11: Employee first name | D11: ='Infos Mensuelles'!C10 -> Anam | H11: Employee Position: | J11: ='Infos Mensuelles'!G10 -> Light Vehicule Driver
A15: Employee Attendance
A16: Working days : | D16: ='Infos Mensuelles'!L10 -> 24 | E16: Emergency not payable: | H16: ='Infos Mensuelles'!T10 -> 0 | I16: OT Hours Basic : | L16: ='Infos Mensuelles'!AF10 -> 30
A17: Working Public Holidays : | D17: ='Infos Mensuelles'!N10 -> 0 | E17: Sick Leave not Payable: | H17: ='Infos Mensuelles'!U10 -> 0 | I17: OT Hours Public holidays : | L17: ='Infos Mensuelles'!AI10 -> 0
A18: Off days : | D18: ='Infos Mensuelles'!M10 -> 4 | E18: Absence day not payable: | H18: ='Infos Mensuelles'!V10 -> 0 | I18: OT Days : | L18: ='Infos Mensuelles'!AM10 -> 0
A19: Sick Leave Payable : | D19: ='Infos Mensuelles'!P10 -> 0 | E19: Unpaid Leaves: | H19: ='Infos Mensuelles'!S10 -> 0 | I19: Leave Payable : | L19: ='Infos Mensuelles'!O10 -> 0
A20: Total of payable days : | D20: ='Infos Mensuelles'!R10 -> 30
A23: Earnings & Deductions
A24: Salary Head | G24: Amount Earnings (AED) | J24: Amount Deductions (AED)
A26: Earnings
A27: Basic Salary | G27: ='Infos Mensuelles'!H10 -> 2700
A28: Housing Allowances | G28: ='Infos Mensuelles'!I10 -> 900
A29: Transport Allowances | G29: ='Infos Mensuelles'!J10 -> 900
A30: OT Hours Basic | G30: ='Infos Mensuelles'!AH10 -> 360
A31: OT Hours Public holidays | G31: ='Infos Mensuelles'!AK10 -> 0
A32: OT Days | G32: ='Infos Mensuelles'!AO10 -> 0
A33: Air Plane Ticket Refundable | G33: ='Infos Mensuelles'!AR10 -> 0
A34: Other Allowance | G34: ='Infos Mensuelles'!AP10 -> 0
A35: Adjustment form previous month | G35: ='Infos Mensuelles'!AQ10 -> 0
A36: Deductions
A37: Advance salary | J37: ='Infos Mensuelles'!AT10 -> 0
A38: Your Fines paid by the company | J38: ='Infos Mensuelles'!AU10 -> 0
A39: Absence | J39: ='Infos Mensuelles'!Z10 -> 0
A40: Unpaid leaves | J40: ='Infos Mensuelles'!W10 -> 0
A41: Sick leave unpaid | J41: ='Infos Mensuelles'!Y10 -> 0
A42: Adjustment form previous month | J42: ='Infos Mensuelles'!AV10 -> 0
A43: Emergency leave Unpaid | J43: ='Infos Mensuelles'!X10 -> 0
A45: TOTAL EARNINGS & DEDUCTIONS | G45: =SUM(G27:I36) -> 4860 | J45: =SUM(J42:L43) -> 0
A48: TOTAL AMOUNT : | G48: =G45-J45 -> 4860
A52: Payment informations:
A53: Date of payment: | D53: ='Infos Mensuelles'!E1 -> 46081
A54: Methode of payment: | D54: WPS
A55: If you need any informations please contact us at hr-dubai@chabe.com

Sheet 5
A1: CHABE LUXURY TRANSPORT LLC
A2: 11B Street Warehouse 3b/27
A3: AL KHABAISI
A4: Dubai, UAE
A5: ='Infos Mensuelles'!A1 -> Salary slip February 2026
A8: Employee last name: | D8: ='Infos Mensuelles'!B11 -> SUNKADAKATTE ABDULKHADER | H8: Employee ID: | J8: ='Infos Mensuelles'!F11 -> 10019057895758
H9: Arrival date: | J9: ='Infos Mensuelles'!D11 -> 42898
A11: Employee first name | D11: ='Infos Mensuelles'!C11 -> Mohamed Aneefa | H11: Employee Position: | J11: ='Infos Mensuelles'!G11 -> Light Vehicule Driver
A15: Employee Attendance
A16: Working days : | D16: ='Infos Mensuelles'!L11 -> 24 | E16: Emergency not payable: | H16: ='Infos Mensuelles'!T11 -> 0 | I16: OT Hours Basic : | L16: ='Infos Mensuelles'!AF11 -> 36
A17: Working Public Holidays : | D17: ='Infos Mensuelles'!N11 -> 0 | E17: Sick Leave not Payable: | H17: ='Infos Mensuelles'!U11 -> 0 | I17: OT Hours Public holidays : | L17: ='Infos Mensuelles'!AI11 -> 0
A18: Off days : | D18: ='Infos Mensuelles'!M11 -> 4 | E18: Absence day not payable: | H18: ='Infos Mensuelles'!V11 -> 0 | I18: OT Days : | L18: ='Infos Mensuelles'!AM11 -> 0
A19: Sick Leave Payable : | D19: ='Infos Mensuelles'!P11 -> 0 | E19: Unpaid Leaves: | H19: ='Infos Mensuelles'!S11 -> 0 | I19: Leave Payable : | L19: ='Infos Mensuelles'!O11 -> 0
A20: Total of payable days : | D20: ='Infos Mensuelles'!R11 -> 30
A23: Earnings & Deductions
A24: Salary Head | G24: Amount Earnings (AED) | J24: Amount Deductions (AED)
A26: Earnings
A27: Basic Salary | G27: ='Infos Mensuelles'!H11 -> 2700
A28: Housing Allowances | G28: ='Infos Mensuelles'!I11 -> 900
A29: Transport Allowances | G29: ='Infos Mensuelles'!J11 -> 900
A30: OT Hours Basic | G30: ='Infos Mensuelles'!AH11 -> 432
A31: OT Hours Public holidays | G31: ='Infos Mensuelles'!AK11 -> 0
A32: OT Days | G32: ='Infos Mensuelles'!AO11 -> 0
A33: Air Plane Ticket Refundable | G33: ='Infos Mensuelles'!AR11 -> 0
A34: Other Allowance | G34: ='Infos Mensuelles'!AP11 -> 0
A35: Adjustment form previous month | G35: ='Infos Mensuelles'!AQ11 -> 0
A36: Deductions
A37: Advance salary | J37: ='Infos Mensuelles'!AT11 -> 0
A38: Your Fines paid by the company | J38: ='Infos Mensuelles'!AU11 -> 0
A39: Absence | J39: ='Infos Mensuelles'!Z11 -> 0
A40: Unpaid leaves | J40: ='Infos Mensuelles'!W11 -> 0
A41: Sick leave unpaid | J41: ='Infos Mensuelles'!Y11 -> 0
A42: Adjustment form previous month | J42: ='Infos Mensuelles'!AV11 -> 0
A43: Emergency leave Unpaid | J43: ='Infos Mensuelles'!X11 -> 0
A45: TOTAL EARNINGS & DEDUCTIONS | G45: =SUM(G27:I36) -> 4932 | J45: =SUM(J42:L43) -> 0
A48: TOTAL AMOUNT : | G48: =G45-J45 -> 4932
A52: Payment informations:
A53: Date of payment: | D53: ='Infos Mensuelles'!E1 -> 46081
A54: Methode of payment: | D54: WPS
A55: If you need any informations please contact us at hr-dubai@chabe.com

Sheet 6
A1: CHABE LUXURY TRANSPORT LLC
A2: 11B Street Warehouse 3b/27
A3: AL KHABAISI
A4: Dubai, UAE
A5: ='Infos Mensuelles'!A1 -> Salary slip February 2026
A8: Employee last name: | D8: ='Infos Mensuelles'!B12 -> JAINULAPUDEEN MOHAMED | H8: Employee ID: | J8: ='Infos Mensuelles'!F12 -> 10030078086699
H9: Arrival date: | J9: ='Infos Mensuelles'!D12 -> 44501
A11: Employee first name | D11: ='Infos Mensuelles'!C12 -> Anees | H11: Employee Position: | J11: ='Infos Mensuelles'!G12 -> Light Vehicule Driver
A15: Employee Attendance
A16: Working days : | D16: ='Infos Mensuelles'!L12 -> 24 | E16: Emergency not payable: | H16: ='Infos Mensuelles'!T12 -> 0 | I16: OT Hours Basic : | L16: ='Infos Mensuelles'!AF12 -> 24
A17: Working Public Holidays : | D17: ='Infos Mensuelles'!N12 -> 0 | E17: Sick Leave not Payable: | H17: ='Infos Mensuelles'!U12 -> 0 | I17: OT Hours Public holidays : | L17: ='Infos Mensuelles'!AI12 -> 0
A18: Off days : | D18: ='Infos Mensuelles'!M12 -> 4 | E18: Absence day not payable: | H18: ='Infos Mensuelles'!V12 -> 0 | I18: OT Days : | L18: ='Infos Mensuelles'!AM12 -> 0
A19: Sick Leave Payable : | D19: ='Infos Mensuelles'!P12 -> 0 | E19: Unpaid Leaves: | H19: ='Infos Mensuelles'!S12 -> 0 | I19: Leave Payable : | L19: ='Infos Mensuelles'!O12 -> 0
A20: Total of payable days : | D20: ='Infos Mensuelles'!R12 -> 30
A23: Earnings & Deductions
A24: Salary Head | G24: Amount Earnings (AED) | J24: Amount Deductions (AED)
A26: Earnings
A27: Basic Salary | G27: ='Infos Mensuelles'!H12 -> 2640
A28: Housing Allowances | G28: ='Infos Mensuelles'!I12 -> 880
A29: Transport Allowances | G29: ='Infos Mensuelles'!J12 -> 880
A30: OT Hours Basic | G30: ='Infos Mensuelles'!AH12 -> 288
A31: OT Hours Public holidays | G31: ='Infos Mensuelles'!AK12 -> 0
A32: OT Days | G32: ='Infos Mensuelles'!AO12 -> 0
A33: Air Plane Ticket Refundable | G33: ='Infos Mensuelles'!AR12 -> 0
A34: Other Allowance | G34: ='Infos Mensuelles'!AP12 -> 0
A35: Adjustment form previous month | G35: ='Infos Mensuelles'!AQ12 -> 0
A36: Deductions
A37: Advance salary | J37: ='Infos Mensuelles'!AT12 -> 0
A38: Your Fines paid by the company | J38: ='Infos Mensuelles'!AU12 -> 0
A39: Absence | J39: ='Infos Mensuelles'!Z12 -> 0
A40: Unpaid leaves | J40: ='Infos Mensuelles'!W12 -> 0
A41: Sick leave unpaid | J41: ='Infos Mensuelles'!Y12 -> 0
A42: Adjustment form previous month | J42: ='Infos Mensuelles'!AV12 -> 0
A43: Emergency leave Unpaid | J43: ='Infos Mensuelles'!X12 -> 0
A45: TOTAL EARNINGS & DEDUCTIONS | G45: =SUM(G27:I36) -> 4688 | J45: =SUM(J42:L43) -> 0
A48: TOTAL AMOUNT : | G48: =G45-J45 -> 4688
A52: Payment informations:
A53: Date of payment: | D53: ='Infos Mensuelles'!E1 -> 46081
A54: Methode of payment: | D54: WPS
A55: If you need any informations please contact us at hr-dubai@chabe.com

Sheet 7
A1: CHABE LUXURY TRANSPORT LLC
A2: 11B Street Warehouse 3b/27
A3: AL KHABAISI
A4: Dubai, UAE
A5: ='Infos Mensuelles'!A1 -> Salary slip February 2026
A8: Employee last name: | D8: ='Infos Mensuelles'!B13 -> SHAH MISAL SHAH BUKHARI | H8: Employee ID: | J8: ='Infos Mensuelles'!F13 -> 20001018653644
H9: Arrival date: | J9: ='Infos Mensuelles'!D13 -> 44726
A11: Employee first name | D11: ='Infos Mensuelles'!C13 -> Asal | H11: Employee Position: | J11: ='Infos Mensuelles'!G13 -> Light Vehicule Driver
A15: Employee Attendance
A16: Working days : | D16: ='Infos Mensuelles'!L13 -> 24 | E16: Emergency not payable: | H16: ='Infos Mensuelles'!T13 -> 0 | I16: OT Hours Basic : | L16: ='Infos Mensuelles'!AF13 -> 30
A17: Working Public Holidays : | D17: ='Infos Mensuelles'!N13 -> 0 | E17: Sick Leave not Payable: | H17: ='Infos Mensuelles'!U13 -> 0 | I17: OT Hours Public holidays : | L17: ='Infos Mensuelles'!AI13 -> 0
A18: Off days : | D18: ='Infos Mensuelles'!M13 -> 4 | E18: Absence day not payable: | H18: ='Infos Mensuelles'!V13 -> 0 | I18: OT Days : | L18: ='Infos Mensuelles'!AM13 -> 0
A19: Sick Leave Payable : | D19: ='Infos Mensuelles'!P13 -> 0 | E19: Unpaid Leaves: | H19: ='Infos Mensuelles'!S13 -> 0 | I19: Leave Payable : | L19: ='Infos Mensuelles'!O13 -> 0
A20: Total of payable days : | D20: ='Infos Mensuelles'!R13 -> 30
A23: Earnings & Deductions
A24: Salary Head | G24: Amount Earnings (AED) | J24: Amount Deductions (AED)
A26: Earnings
A27: Basic Salary | G27: ='Infos Mensuelles'!H13 -> 2580
A28: Housing Allowances | G28: ='Infos Mensuelles'!I13 -> 860
A29: Transport Allowances | G29: ='Infos Mensuelles'!J13 -> 860
A30: OT Hours Basic | G30: ='Infos Mensuelles'!AH13 -> 360
A31: OT Hours Public holidays | G31: ='Infos Mensuelles'!AK13 -> 0
A32: OT Days | G32: ='Infos Mensuelles'!AO13 -> 0
A33: Air Plane Ticket Refundable | G33: ='Infos Mensuelles'!AR13 -> 0
A34: Other Allowance | G34: ='Infos Mensuelles'!AP13 -> 0
A35: Adjustment form previous month | G35: ='Infos Mensuelles'!AQ13 -> 0
A36: Deductions
A37: Advance salary | J37: ='Infos Mensuelles'!AT13 -> 0
A38: Your Fines paid by the company | J38: ='Infos Mensuelles'!AU13 -> 0
A39: Absence | J39: ='Infos Mensuelles'!Z13 -> 0
A40: Unpaid leaves | J40: ='Infos Mensuelles'!W13 -> 0
A41: Sick leave unpaid | J41: ='Infos Mensuelles'!Y13 -> 0
A42: Adjustment form previous month | J42: ='Infos Mensuelles'!AV13 -> 0
A43: Emergency leave Unpaid | J43: ='Infos Mensuelles'!X13 -> 0
A45: TOTAL EARNINGS & DEDUCTIONS | G45: =SUM(G27:I36) -> 4660 | J45: =SUM(J42:L43) -> 0
A48: TOTAL AMOUNT : | G48: =G45-J45 -> 4660
A52: Payment informations:
A53: Date of payment: | D53: ='Infos Mensuelles'!E1 -> 46081
A54: Methode of payment: | D54: WPS
A55: If you need any informations please contact us at hr-dubai@chabe.com

Sheet 8
A1: CHABE LUXURY TRANSPORT LLC
A2: 11B Street Warehouse 3b/27
A3: AL KHABAISI
A4: Dubai, UAE
A5: ='Infos Mensuelles'!A1 -> Salary slip February 2026
A8: Employee last name: | D8: ='Infos Mensuelles'!B14 -> FAZAL HUSSAIN | H8: Employee ID: | J8: ='Infos Mensuelles'!F14 -> 20015018877124
H9: Arrival date: | J9: ='Infos Mensuelles'!D14 -> 42642
A11: Employee first name | D11: ='Infos Mensuelles'!C14 -> Atta Rasool | H11: Employee Position: | J11: ='Infos Mensuelles'!G14 -> Light Vehicule Driver
A15: Employee Attendance
A16: Working days : | D16: ='Infos Mensuelles'!L14 -> 25 | E16: Emergency not payable: | H16: ='Infos Mensuelles'!T14 -> 0 | I16: OT Hours Basic : | L16: ='Infos Mensuelles'!AF14 -> 36
A17: Working Public Holidays : | D17: ='Infos Mensuelles'!N14 -> 0 | E17: Sick Leave not Payable: | H17: ='Infos Mensuelles'!U14 -> 0 | I17: OT Hours Public holidays : | L17: ='Infos Mensuelles'!AI14 -> 0
A18: Off days : | D18: ='Infos Mensuelles'!M14 -> 3 | E18: Absence day not payable: | H18: ='Infos Mensuelles'!V14 -> 0 | I18: OT Days : | L18: ='Infos Mensuelles'!AM14 -> 1
A19: Sick Leave Payable : | D19: ='Infos Mensuelles'!P14 -> 0 | E19: Unpaid Leaves: | H19: ='Infos Mensuelles'!S14 -> 0 | I19: Leave Payable : | L19: ='Infos Mensuelles'!O14 -> 0
A20: Total of payable days : | D20: ='Infos Mensuelles'!R14 -> 30
A23: Earnings & Deductions
A24: Salary Head | G24: Amount Earnings (AED) | J24: Amount Deductions (AED)
A26: Earnings
A27: Basic Salary | G27: ='Infos Mensuelles'!H14 -> 2700
A28: Housing Allowances | G28: ='Infos Mensuelles'!I14 -> 900
A29: Transport Allowances | G29: ='Infos Mensuelles'!J14 -> 900
A30: OT Hours Basic | G30: ='Infos Mensuelles'!AH14 -> 432
A31: OT Hours Public holidays | G31: ='Infos Mensuelles'!AK14 -> 0
A32: OT Days | G32: ='Infos Mensuelles'!AO14 -> 148
A33: Air Plane Ticket Refundable | G33: ='Infos Mensuelles'!AR14 -> 0
A34: Other Allowance | G34: ='Infos Mensuelles'!AP14 -> 0
A35: Adjustment form previous month | G35: ='Infos Mensuelles'!AQ14 -> 0
A36: Deductions
A37: Advance salary | J37: ='Infos Mensuelles'!AT14 -> 0
A38: Your Fines paid by the company | J38: ='Infos Mensuelles'!AU14 -> 0
A39: Absence | J39: ='Infos Mensuelles'!Z14 -> 0
A40: Unpaid leaves | J40: ='Infos Mensuelles'!W14 -> 0
A41: Sick leave unpaid | J41: ='Infos Mensuelles'!Y14 -> 0
A42: Adjustment form previous month | J42: ='Infos Mensuelles'!AV14 -> 0
A43: Emergency leave Unpaid | J43: ='Infos Mensuelles'!X14 -> 0
A45: TOTAL EARNINGS & DEDUCTIONS | G45: =SUM(G27:I36) -> 5080 | J45: =SUM(J42:L43) -> 0
A48: TOTAL AMOUNT : | G48: =G45-J45 -> 5080
A52: Payment informations:
A53: Date of payment: | D53: ='Infos Mensuelles'!E1 -> 46081
A54: Methode of payment: | D54: WPS
A55: If you need any informations please contact us at hr-dubai@chabe.com

Sheet 9
A1: CHABE LUXURY TRANSPORT LLC
A2: 11B Street Warehouse 3b/27
A3: AL KHABAISI
A4: Dubai, UAE
A5: ='Infos Mensuelles'!A1 -> Salary slip February 2026
A8: Employee last name: | D8: ='Infos Mensuelles'!B15 -> ULLAH MUHAMMAD RIAZ | H8: Employee ID: | J8: ='Infos Mensuelles'!F15 -> 20010118687794
H9: Arrival date: | J9: ='Infos Mensuelles'!D15 -> 43507
A11: Employee first name | D11: ='Infos Mensuelles'!C15 -> Attiq | H11: Employee Position: | J11: ='Infos Mensuelles'!G15 -> Light Vehicule Driver
A15: Employee Attendance
A16: Working days : | D16: ='Infos Mensuelles'!L15 -> 24 | E16: Emergency not payable: | H16: ='Infos Mensuelles'!T15 -> 0 | I16: OT Hours Basic : | L16: ='Infos Mensuelles'!AF15 -> 34
A17: Working Public Holidays : | D17: ='Infos Mensuelles'!N15 -> 0 | E17: Sick Leave not Payable: | H17: ='Infos Mensuelles'!U15 -> 0 | I17: OT Hours Public holidays : | L17: ='Infos Mensuelles'!AI15 -> 0
A18: Off days : | D18: ='Infos Mensuelles'!M15 -> 4 | E18: Absence day not payable: | H18: ='Infos Mensuelles'!V15 -> 0 | I18: OT Days : | L18: ='Infos Mensuelles'!AM15 -> 1
A19: Sick Leave Payable : | D19: ='Infos Mensuelles'!P15 -> 0 | E19: Unpaid Leaves: | H19: ='Infos Mensuelles'!S15 -> 0 | I19: Leave Payable : | L19: ='Infos Mensuelles'!O15 -> 0
A20: Total of payable days : | D20: ='Infos Mensuelles'!R15 -> 30
A23: Earnings & Deductions
A24: Salary Head | G24: Amount Earnings (AED) | J24: Amount Deductions (AED)
A26: Earnings
A27: Basic Salary | G27: ='Infos Mensuelles'!H15 -> 2700
A28: Housing Allowances | G28: ='Infos Mensuelles'!I15 -> 900
A29: Transport Allowances | G29: ='Infos Mensuelles'!J15 -> 900
A30: OT Hours Basic | G30: ='Infos Mensuelles'!AH15 -> 408
A31: OT Hours Public holidays | G31: ='Infos Mensuelles'!AK15 -> 0
A32: OT Days | G32: ='Infos Mensuelles'!AO15 -> 148
A33: Air Plane Ticket Refundable | G33: ='Infos Mensuelles'!AR15 -> 0
A34: Other Allowance | G34: ='Infos Mensuelles'!AP15 -> 0
A35: Adjustment form previous month | G35: ='Infos Mensuelles'!AQ15 -> 0
A36: Deductions
A37: Advance salary | J37: ='Infos Mensuelles'!AT15 -> 0
A38: Your Fines paid by the company | J38: ='Infos Mensuelles'!AU15 -> 0
A39: Absence | J39: ='Infos Mensuelles'!Z15 -> 0
A40: Unpaid leaves | J40: ='Infos Mensuelles'!W15 -> 0
A41: Sick leave unpaid | J41: ='Infos Mensuelles'!Y15 -> 0
